Workbook

Sheet 使用说明
B2: 11 人问卷 · 结果录入工作簿
B6: 先分发 | C6: Q01–Q11 分别给 11 位不同参与者；每人只拿对应的 Word 或 PDF。不要把本 Excel、全部问卷或解盲文件给受试者。
B7: 再登记 | C7: 在“参与者登记”的蓝色单元格填写回收、三个同意/资格确认、既往接触、可选背景。没有真实答卷时保持空白。编号不可重复。
B8: 录入评分 | C8: 在“评分录入”按编号与场次填写 6 个数字。1=A明显；2=A略好；3=相当；4=B略好；5=B明显；6=无法判断。每人 6 场，共 36 项。
B9: 可选信息 | C9: 两份都不足、评论、经验、用时与评论引用同意可留空。未明确同意评论引用时，不引用。请不要在此表写姓名、邮箱或招募联系人。
B10: 哪些回答纳入 | C10: 仅“已回收=是”、年龄/英文/同意均=是、既往接触=没有、36 项评分全部有效的参与者进入汇总。未回收、待补录或被排除的回答均不计入。
B11: 如何计算 | C11: A/B 按每份问卷独立解盲。主要终点把明显/略好合并为偏好；胜=1、相当=0.5、负=0。无法判断单独计数，不当作相当、零分或败场。原始 1–6 评分完整保留。
B12: 怎么看汇总 | C12: 架构按 10 个提示等权；模型按该两模型共同具备成品的提示等权。只有全部计划提示都有可判票时显示完整宏平均；缺失覆盖会显示“未完整覆盖”。不要按混合提示总票数排模型名次。
B13: 样本边界 | C13: 11 人共 44 场模型、22 场架构评价。41 个精确模型/提示配对中 38 个只有 1 票、3 个有 2 票；9 个架构请求各 2 票、1 个有 4 票。模型结果为探索性描述，不是稳定排名。
B14: 六个维度 | C14: “总体世界设计”为主要终点；其余五维为诊断项目。“逐题汇总”保留六维各自的票数和缺失，不将六个维度加总成总分或当作六个独立受试者。
B15: 材料边界 | C15: 英文原始证据，架构比较为实际且不等计算预算的配置。模型仅评价已有成功成品；无成品失败不能自动算成人工偏好败场。此表不含置信区间、p 值、显著性星号或 Elo。
B16: Excel 操作 | C16: 仅编辑蓝色格。灰色为冻结编号/分配，绿色为自动结果；工作表保护防止误改，不是保密措施。使用 Excel/LibreOffice 的自动计算；若结果未更新，请启用自动计算并重算。
B17: 保存与回传 | C17: 请将填完的工作簿另存到本地独立文件夹。完整答卷和含评论的工作簿仅供研究者处理，不要上传公开 Git；本发布包只包含空白模板，没有真实受试者结果。
B19: 版本：agora-paper-11p-20260921-v1 | 预定样本：11 人 | 分配种子：20260921

Sheet 参与者登记
A1: 参与者登记 · 11 份，11 位不同参与者
A2: 先填蓝色格，再录入评分；请照原答卷填写，不能代填同意。可选项目空白不会影响纳入。
A6: 编号 | B6: 已回收 | C6: 年满18岁 | D6: 能独立读英文 | E6: 同意参与 | F6: 既往开发/结果接触 | G6: 游戏经验（可选） | H6: 同意评论引用（可选） | I6: 用时/分钟（可选） | J6: 有效评分项 / 36 | K6: 主要分析状态 | L6: 录入备注（不写身份）
A7: Q01 | J7: =SUM('评分录入'!L7:L12) -> 0 | K7: =IF(B7<>"是","待回收",IF(OR(C7="否",D7="否",E7="否"),"排除：资格/同意",IF(OR(C7<>"是",D7<>"是",E7<>"是",F7=""),"待核对：背景",IF(F7<>"没有","排除：既往接触",IF(J7<>36,"待补录评分","纳入"))))) -> 待回收
A8: Q02 | J8: =SUM('评分录入'!L13:L18) -> 0 | K8: =IF(B8<>"是","待回收",IF(OR(C8="否",D8="否",E8="否"),"排除：资格/同意",IF(OR(C8<>"是",D8<>"是",E8<>"是",F8=""),"待核对：背景",IF(F8<>"没有","排除：既往接触",IF(J8<>36,"待补录评分","纳入"))))) -> 待回收
A9: Q03 | J9: =SUM('评分录入'!L19:L24) -> 0 | K9: =IF(B9<>"是","待回收",IF(OR(C9="否",D9="否",E9="否"),"排除：资格/同意",IF(OR(C9<>"是",D9<>"是",E9<>"是",F9=""),"待核对：背景",IF(F9<>"没有","排除：既往接触",IF(J9<>36,"待补录评分","纳入"))))) -> 待回收
A10: Q04 | J10: =SUM('评分录入'!L25:L30) -> 0 | K10: =IF(B10<>"是","待回收",IF(OR(C10="否",D10="否",E10="否"),"排除：资格/同意",IF(OR(C10<>"是",D10<>"是",E10<>"是",F10=""),"待核对：背景",IF(F10<>"没有","排除：既往接触",IF(J10<>36,"待补录评分","纳入"))))) -> 待回收
A11: Q05 | J11: =SUM('评分录入'!L31:L36) -> 0 | K11: =IF(B11<>"是","待回收",IF(OR(C11="否",D11="否",E11="否"),"排除：资格/同意",IF(OR(C11<>"是",D11<>"是",E11<>"是",F11=""),"待核对：背景",IF(F11<>"没有","排除：既往接触",IF(J11<>36,"待补录评分","纳入"))))) -> 待回收
A12: Q06 | J12: =SUM('评分录入'!L37:L42) -> 0 | K12: =IF(B12<>"是","待回收",IF(OR(C12="否",D12="否",E12="否"),"排除：资格/同意",IF(OR(C12<>"是",D12<>"是",E12<>"是",F12=""),"待核对：背景",IF(F12<>"没有","排除：既往接触",IF(J12<>36,"待补录评分","纳入"))))) -> 待回收
A13: Q07 | J13: =SUM('评分录入'!L43:L48) -> 0 | K13: =IF(B13<>"是","待回收",IF(OR(C13="否",D13="否",E13="否"),"排除：资格/同意",IF(OR(C13<>"是",D13<>"是",E13<>"是",F13=""),"待核对：背景",IF(F13<>"没有","排除：既往接触",IF(J13<>36,"待补录评分","纳入"))))) -> 待回收
A14: Q08 | J14: =SUM('评分录入'!L49:L54) -> 0 | K14: =IF(B14<>"是","待回收",IF(OR(C14="否",D14="否",E14="否"),"排除：资格/同意",IF(OR(C14<>"是",D14<>"是",E14<>"是",F14=""),"待核对：背景",IF(F14<>"没有","排除：既往接触",IF(J14<>36,"待补录评分","纳入"))))) -> 待回收
A15: Q09 | J15: =SUM('评分录入'!L55:L60) -> 0 | K15: =IF(B15<>"是","待回收",IF(OR(C15="否",D15="否",E15="否"),"排除：资格/同意",IF(OR(C15<>"是",D15<>"是",E15<>"是",F15=""),"待核对：背景",IF(F15<>"没有","排除：既往接触",IF(J15<>36,"待补录评分","纳入"))))) -> 待回收
A16: Q10 | J16: =SUM('评分录入'!L61:L66) -> 0 | K16: =IF(B16<>"是","待回收",IF(OR(C16="否",D16="否",E16="否"),"排除：资格/同意",IF(OR(C16<>"是",D16<>"是",E16<>"是",F16=""),"待核对：背景",IF(F16<>"没有","排除：既往接触",IF(J16<>36,"待补录评分","纳入"))))) -> 待回收
A17: Q11 | J17: =SUM('评分录入'!L67:L72) -> 0 | K17: =IF(B17<>"是","待回收",IF(OR(C17="否",D17="否",E17="否"),"排除：资格/同意",IF(OR(C17<>"是",D17<>"是",E17<>"是",F17=""),"待核对：背景",IF(F17<>"没有","排除：既往接触",IF(J17<>36,"待补录评分","纳入"))))) -> 待回收

Sheet 评分录入
A1: 原始评分录入 · 66 场
A2: 只填蓝色格。1=A明显；2=A略好；3=相当；4=B略好；5=B明显；6=无法判断。灰色的编号/场次与对应 PDF、Word 一致；模型和方法映射在右侧隐藏列。
A6: 编号 | B6: 场次 | C6: PDF材料 / 评分页 | D6: 总体 | E6: 设定 | F6: 规则 | G6: 人物 | H6: 地点 | I6: 行动 | J6: 两份都不足（可选） | K6: 具体细节评论（可选） | L6: 有效项/6 | M6: 主要分析状态 | N6: 类型 | O6: 提示ID | P6: A来源 | Q6: B来源 | R6: 条件1 | S6: 条件2 | T6: 总体条件1得分 | U6: 无法判断 | V6: 相当 | W6: 条件1胜 | X6: 条件2胜 | Y6: 可判票 | Z6: 设定实现条件1得分 | AA6: 规则与活动条件1得分 | AB6: 人物与社会联系条件1得分 | AC6: 地点与物件条件1得分 | AD6: 可设想的行动条件1得分
A7: Q01 | B7: 1 | C7: A 2 / B 3 / 评分 4 | L7: =SUM(IFERROR(IF(AND(VALUE(D7)>=1,VALUE(D7)<=6,MOD(VALUE(D7),1)=0),1,0),0),IFERROR(IF(AND(VALUE(E7)>=1,VALUE(E7)<=6,MOD(VALUE(E7),1)=0),1,0),0),IFERROR(IF(AND(VALUE(F7)>=1,VALUE(F7)<=6,MOD(VALUE(F7),1)=0),1,0),0),IFERROR(IF(AND(VALUE(G7)>=1,VALUE(G7)<=6,MOD(VALUE(G7),1)=0),1,0),0),IFERROR(IF(AND(VALUE(H7)>=1,VALUE(H7)<=6,MOD(VALUE(H7),1)=0),1,0),0),IFERROR(IF(AND(VALUE(I7)>=1,VALUE(I7)<=6,MOD(VALUE(I7),1)=0),1,0),0)) -> 0 | M7: ='参与者登记'!K7 -> 待回收 | N7: 模型 | O7: lwb_hidden_v2_03 | P7: Gemini 2.5 Flash | Q7: Gemini 3.7 Flash | R7: Gemini 2.5 Flash | S7: Gemini 3.7 Flash | T7: =IF(M7<>"纳入","",IF(VALUE(D7)=6,"",IF(VALUE(D7)=3,0.5,IF(OR(AND(VALUE(D7)<3,P7=R7),AND(VALUE(D7)>3,Q7=R7)),1,0)))) | U7: =IF(AND(M7="纳入",IFERROR(VALUE(D7),0)=6),1,0) -> 0 | V7: =IF(AND(M7="纳入",IFERROR(VALUE(D7),0)=3),1,0) -> 0 | W7: =IF(AND(M7="纳入",ISNUMBER(T7),T7=1),1,0) -> 0 | X7: =IF(AND(M7="纳入",ISNUMBER(T7),T7=0),1,0) -> 0 | Y7: =IF(AND(M7="纳入",ISNUMBER(T7)),1,0) -> 0 | Z7: =IF(M7<>"纳入","",IF(VALUE(E7)=6,"",IF(VALUE(E7)=3,0.5,IF(OR(AND(VALUE(E7)<3,P7=R7),AND(VALUE(E7)>3,Q7=R7)),1,0)))) | AA7: =IF(M7<>"纳入","",IF(VALUE(F7)=6,"",IF(VALUE(F7)=3,0.5,IF(OR(AND(VALUE(F7)<3,P7=R7),AND(VALUE(F7)>3,Q7=R7)),1,0)))) | AB7: =IF(M7<>"纳入","",IF(VALUE(G7)=6,"",IF(VALUE(G7)=3,0.5,IF(OR(AND(VALUE(G7)<3,P7=R7),AND(VALUE(G7)>3,Q7=R7)),1,0)))) | AC7: =IF(M7<>"纳入","",IF(VALUE(H7)=6,"",IF(VALUE(H7)=3,0.5,IF(OR(AND(VALUE(H7)<3,P7=R7),AND(VALUE(H7)>3,Q7=R7)),1,0)))) | AD7: =IF(M7<>"纳入","",IF(VALUE(I7)=6,"",IF(VALUE(I7)=3,0.5,IF(OR(AND(VALUE(I7)<3,P7=R7),AND(VALUE(I7)>3,Q7=R7)),1,0))))
A8: Q01 | B8: 2 | C8: A 5 / B 6 / 评分 7 | L8: =SUM(IFERROR(IF(AND(VALUE(D8)>=1,VALUE(D8)<=6,MOD(VALUE(D8),1)=0),1,0),0),IFERROR(IF(AND(VALUE(E8)>=1,VALUE(E8)<=6,MOD(VALUE(E8),1)=0),1,0),0),IFERROR(IF(AND(VALUE(F8)>=1,VALUE(F8)<=6,MOD(VALUE(F8),1)=0),1,0),0),IFERROR(IF(AND(VALUE(G8)>=1,VALUE(G8)<=6,MOD(VALUE(G8),1)=0),1,0),0),IFERROR(IF(AND(VALUE(H8)>=1,VALUE(H8)<=6,MOD(VALUE(H8),1)=0),1,0),0),IFERROR(IF(AND(VALUE(I8)>=1,VALUE(I8)<=6,MOD(VALUE(I8),1)=0),1,0),0)) -> 0 | M8: ='参与者登记'!K7 -> 待回收 | N8: 模型 | O8: lwb_hidden_v2_01 | P8: Gemini 3.1 Pro Preview | Q8: Gemini 3.1 Flash Lite | R8: Gemini 3.1 Flash Lite | S8: Gemini 3.1 Pro Preview | T8: =IF(M8<>"纳入","",IF(VALUE(D8)=6,"",IF(VALUE(D8)=3,0.5,IF(OR(AND(VALUE(D8)<3,P8=R8),AND(VALUE(D8)>3,Q8=R8)),1,0)))) | U8: =IF(AND(M8="纳入",IFERROR(VALUE(D8),0)=6),1,0) -> 0 | V8: =IF(AND(M8="纳入",IFERROR(VALUE(D8),0)=3),1,0) -> 0 | W8: =IF(AND(M8="纳入",ISNUMBER(T8),T8=1),1,0) -> 0 | X8: =IF(AND(M8="纳入",ISNUMBER(T8),T8=0),1,0) -> 0 | Y8: =IF(AND(M8="纳入",ISNUMBER(T8)),1,0) -> 0 | Z8: =IF(M8<>"纳入","",IF(VALUE(E8)=6,"",IF(VALUE(E8)=3,0.5,IF(OR(AND(VALUE(E8)<3,P8=R8),AND(VALUE(E8)>3,Q8=R8)),1,0)))) | AA8: =IF(M8<>"纳入","",IF(VALUE(F8)=6,"",IF(VALUE(F8)=3,0.5,IF(OR(AND(VALUE(F8)<3,P8=R8),AND(VALUE(F8)>3,Q8=R8)),1,0)))) | AB8: =IF(M8<>"纳入","",IF(VALUE(G8)=6,"",IF(VALUE(G8)=3,0.5,IF(OR(AND(VALUE(G8)<3,P8=R8),AND(VALUE(G8)>3,Q8=R8)),1,0)))) | AC8: =IF(M8<>"纳入","",IF(VALUE(H8)=6,"",IF(VALUE(H8)=3,0.5,IF(OR(AND(VALUE(H8)<3,P8=R8),AND(VALUE(H8)>3,Q8=R8)),1,0)))) | AD8: =IF(M8<>"纳入","",IF(VALUE(I8)=6,"",IF(VALUE(I8)=3,0.5,IF(OR(AND(VALUE(I8)<3,P8=R8),AND(VALUE(I8)>3,Q8=R8)),1,0))))
A9: Q01 | B9: 3 | C9: A 8 / B 9 / 评分 10 | L9: =SUM(IFERROR(IF(AND(VALUE(D9)>=1,VALUE(D9)<=6,MOD(VALUE(D9),1)=0),1,0),0),IFERROR(IF(AND(VALUE(E9)>=1,VALUE(E9)<=6,MOD(VALUE(E9),1)=0),1,0),0),IFERROR(IF(AND(VALUE(F9)>=1,VALUE(F9)<=6,MOD(VALUE(F9),1)=0),1,0),0),IFERROR(IF(AND(VALUE(G9)>=1,VALUE(G9)<=6,MOD(VALUE(G9),1)=0),1,0),0),IFERROR(IF(AND(VALUE(H9)>=1,VALUE(H9)<=6,MOD(VALUE(H9),1)=0),1,0),0),IFERROR(IF(AND(VALUE(I9)>=1,VALUE(I9)<=6,MOD(VALUE(I9),1)=0),1,0),0)) -> 0 | M9: ='参与者登记'!K7 -> 待回收 | N9: 架构 | O9: cartographer_lung_exchange | P9: 完整 Agora | Q9: 单次生成基线 | R9: 完整 Agora | S9: 单次生成基线 | T9: =IF(M9<>"纳入","",IF(VALUE(D9)=6,"",IF(VALUE(D9)=3,0.5,IF(OR(AND(VALUE(D9)<3,P9=R9),AND(VALUE(D9)>3,Q9=R9)),1,0)))) | U9: =IF(AND(M9="纳入",IFERROR(VALUE(D9),0)=6),1,0) -> 0 | V9: =IF(AND(M9="纳入",IFERROR(VALUE(D9),0)=3),1,0) -> 0 | W9: =IF(AND(M9="纳入",ISNUMBER(T9),T9=1),1,0) -> 0 | X9: =IF(AND(M9="纳入",ISNUMBER(T9),T9=0),1,0) -> 0 | Y9: =IF(AND(M9="纳入",ISNUMBER(T9)),1,0) -> 0 | Z9: =IF(M9<>"纳入","",IF(VALUE(E9)=6,"",IF(VALUE(E9)=3,0.5,IF(OR(AND(VALUE(E9)<3,P9=R9),AND(VALUE(E9)>3,Q9=R9)),1,0)))) | AA9: =IF(M9<>"纳入","",IF(VALUE(F9)=6,"",IF(VALUE(F9)=3,0.5,IF(OR(AND(VALUE(F9)<3,P9=R9),AND(VALUE(F9)>3,Q9=R9)),1,0)))) | AB9: =IF(M9<>"纳入","",IF(VALUE(G9)=6,"",IF(VALUE(G9)=3,0.5,IF(OR(AND(VALUE(G9)<3,P9=R9),AND(VALUE(G9)>3,Q9=R9)),1,0)))) | AC9: =IF(M9<>"纳入","",IF(VALUE(H9)=6,"",IF(VALUE(H9)=3,0.5,IF(OR(AND(VALUE(H9)<3,P9=R9),AND(VALUE(H9)>3,Q9=R9)),1,0)))) | AD9: =IF(M9<>"纳入","",IF(VALUE(I9)=6,"",IF(VALUE(I9)=3,0.5,IF(OR(AND(VALUE(I9)<3,P9=R9),AND(VALUE(I9)>3,Q9=R9)),1,0))))
A10: Q01 | B10: 4 | C10: A 11 / B 12 / 评分 13 | L10: =SUM(IFERROR(IF(AND(VALUE(D10)>=1,VALUE(D10)<=6,MOD(VALUE(D10),1)=0),1,0),0),IFERROR(IF(AND(VALUE(E10)>=1,VALUE(E10)<=6,MOD(VALUE(E10),1)=0),1,0),0),IFERROR(IF(AND(VALUE(F10)>=1,VALUE(F10)<=6,MOD(VALUE(F10),1)=0),1,0),0),IFERROR(IF(AND(VALUE(G10)>=1,VALUE(G10)<=6,MOD(VALUE(G10),1)=0),1,0),0),IFERROR(IF(AND(VALUE(H10)>=1,VALUE(H10)<=6,MOD(VALUE(H10),1)=0),1,0),0),IFERROR(IF(AND(VALUE(I10)>=1,VALUE(I10)<=6,MOD(VALUE(I10),1)=0),1,0),0)) -> 0 | M10: ='参与者登记'!K7 -> 待回收 | N10: 模型 | O10: lwb_hidden_v2_02 | P10: Gemini 3.1 Flash Lite | Q10: GPT-5.6 Sol | R10: Gemini 3.1 Flash Lite | S10: GPT-5.6 Sol | T10: =IF(M10<>"纳入","",IF(VALUE(D10)=6,"",IF(VALUE(D10)=3,0.5,IF(OR(AND(VALUE(D10)<3,P10=R10),AND(VALUE(D10)>3,Q10=R10)),1,0)))) | U10: =IF(AND(M10="纳入",IFERROR(VALUE(D10),0)=6),1,0) -> 0 | V10: =IF(AND(M10="纳入",IFERROR(VALUE(D10),0)=3),1,0) -> 0 | W10: =IF(AND(M10="纳入",ISNUMBER(T10),T10=1),1,0) -> 0 | X10: =IF(AND(M10="纳入",ISNUMBER(T10),T10=0),1,0) -> 0 | Y10: =IF(AND(M10="纳入",ISNUMBER(T10)),1,0) -> 0 | Z10: =IF(M10<>"纳入","",IF(VALUE(E10)=6,"",IF(VALUE(E10)=3,0.5,IF(OR(AND(VALUE(E10)<3,P10=R10),AND(VALUE(E10)>3,Q10=R10)),1,0)))) | AA10: =IF(M10<>"纳入","",IF(VALUE(F10)=6,"",IF(VALUE(F10)=3,0.5,IF(OR(AND(VALUE(F10)<3,P10=R10),AND(VALUE(F10)>3,Q10=R10)),1,0)))) | AB10: =IF(M10<>"纳入","",IF(VALUE(G10)=6,"",IF(VALUE(G10)=3,0.5,IF(OR(AND(VALUE(G10)<3,P10=R10),AND(VALUE(G10)>3,Q10=R10)),1,0)))) | AC10: =IF(M10<>"纳入","",IF(VALUE(H10)=6,"",IF(VALUE(H10)=3,0.5,IF(OR(AND(VALUE(H10)<3,P10=R10),AND(VALUE(H10)>3,Q10=R10)),1,0)))) | AD10: =IF(M10<>"纳入","",IF(VALUE(I10)=6,"",IF(VALUE(I10)=3,0.5,IF(OR(AND(VALUE(I10)<3,P10=R10),AND(VALUE(I10)>3,Q10=R10)),1,0))))
A11: Q01 | B11: 5 | C11: A 14 / B 15 / 评分 16 | L11: =SUM(IFERROR(IF(AND(VALUE(D11)>=1,VALUE(D11)<=6,MOD(VALUE(D11),1)=0),1,0),0),IFERROR(IF(AND(VALUE(E11)>=1,VALUE(E11)<=6,MOD(VALUE(E11),1)=0),1,0),0),IFERROR(IF(AND(VALUE(F11)>=1,VALUE(F11)<=6,MOD(VALUE(F11),1)=0),1,0),0),IFERROR(IF(AND(VALUE(G11)>=1,VALUE(G11)<=6,MOD(VALUE(G11),1)=0),1,0),0),IFERROR(IF(AND(VALUE(H11)>=1,VALUE(H11)<=6,MOD(VALUE(H11),1)=0),1,0),0),IFERROR(IF(AND(VALUE(I11)>=1,VALUE(I11)<=6,MOD(VALUE(I11),1)=0),1,0),0)) -> 0 | M11: ='参与者登记'!K7 -> 待回收 | N11: 模型 | O11: lwb_hidden_v2_01 | P11: GPT-5.6 Terra | Q11: Gemini 3.1 Flash Lite | R11: Gemini 3.1 Flash Lite | S11: GPT-5.6 Terra | T11: =IF(M11<>"纳入","",IF(VALUE(D11)=6,"",IF(VALUE(D11)=3,0.5,IF(OR(AND(VALUE(D11)<3,P11=R11),AND(VALUE(D11)>3,Q11=R11)),1,0)))) | U11: =IF(AND(M11="纳入",IFERROR(VALUE(D11),0)=6),1,0) -> 0 | V11: =IF(AND(M11="纳入",IFERROR(VALUE(D11),0)=3),1,0) -> 0 | W11: =IF(AND(M11="纳入",ISNUMBER(T11),T11=1),1,0) -> 0 | X11: =IF(AND(M11="纳入",ISNUMBER(T11),T11=0),1,0) -> 0 | Y11: =IF(AND(M11="纳入",ISNUMBER(T11)),1,0) -> 0 | Z11: =IF(M11<>"纳入","",IF(VALUE(E11)=6,"",IF(VALUE(E11)=3,0.5,IF(OR(AND(VALUE(E11)<3,P11=R11),AND(VALUE(E11)>3,Q11=R11)),1,0)))) | AA11: =IF(M11<>"纳入","",IF(VALUE(F11)=6,"",IF(VALUE(F11)=3,0.5,IF(OR(AND(VALUE(F11)<3,P11=R11),AND(VALUE(F11)>3,Q11=R11)),1,0)))) | AB11: =IF(M11<>"纳入","",IF(VALUE(G11)=6,"",IF(VALUE(G11)=3,0.5,IF(OR(AND(VALUE(G11)<3,P11=R11),AND(VALUE(G11)>3,Q11=R11)),1,0)))) | AC11: =IF(M11<>"纳入","",IF(VALUE(H11)=6,"",IF(VALUE(H11)=3,0.5,IF(OR(AND(VALUE(H11)<3,P11=R11),AND(VALUE(H11)>3,Q11=R11)),1,0)))) | AD11: =IF(M11<>"纳入","",IF(VALUE(I11)=6,"",IF(VALUE(I11)=3,0.5,IF(OR(AND(VALUE(I11)<3,P11=R11),AND(VALUE(I11)>3,Q11=R11)),1,0))))
A12: Q01 | B12: 6 | C12: A 17 / B 18 / 评分 19 | L12: =SUM(IFERROR(IF(AND(VALUE(D12)>=1,VALUE(D12)<=6,MOD(VALUE(D12),1)=0),1,0),0),IFERROR(IF(AND(VALUE(E12)>=1,VALUE(E12)<=6,MOD(VALUE(E12),1)=0),1,0),0),IFERROR(IF(AND(VALUE(F12)>=1,VALUE(F12)<=6,MOD(VALUE(F12),1)=0),1,0),0),IFERROR(IF(AND(VALUE(G12)>=1,VALUE(G12)<=6,MOD(VALUE(G12),1)=0),1,0),0),IFERROR(IF(AND(VALUE(H12)>=1,VALUE(H12)<=6,MOD(VALUE(H12),1)=0),1,0),0),IFERROR(IF(AND(VALUE(I12)>=1,VALUE(I12)<=6,MOD(VALUE(I12),1)=0),1,0),0)) -> 0 | M12: ='参与者登记'!K7 -> 待回收 | N12: 架构 | O12: clockwork_rain_conservatory | P12: 单次生成基线 | Q12: 完整 Agora | R12: 完整 Agora | S12: 单次生成基线 | T12: =IF(M12<>"纳入","",IF(VALUE(D12)=6,"",IF(VALUE(D12)=3,0.5,IF(OR(AND(VALUE(D12)<3,P12=R12),AND(VALUE(D12)>3,Q12=R12)),1,0)))) | U12: =IF(AND(M12="纳入",IFERROR(VALUE(D12),0)=6),1,0) -> 0 | V12: =IF(AND(M12="纳入",IFERROR(VALUE(D12),0)=3),1,0) -> 0 | W12: =IF(AND(M12="纳入",ISNUMBER(T12),T12=1),1,0) -> 0 | X12: =IF(AND(M12="纳入",ISNUMBER(T12),T12=0),1,0) -> 0 | Y12: =IF(AND(M12="纳入",ISNUMBER(T12)),1,0) -> 0 | Z12: =IF(M12<>"纳入","",IF(VALUE(E12)=6,"",IF(VALUE(E12)=3,0.5,IF(OR(AND(VALUE(E12)<3,P12=R12),AND(VALUE(E12)>3,Q12=R12)),1,0)))) | AA12: =IF(M12<>"纳入","",IF(VALUE(F12)=6,"",IF(VALUE(F12)=3,0.5,IF(OR(AND(VALUE(F12)<3,P12=R12),AND(VALUE(F12)>3,Q12=R12)),1,0)))) | AB12: =IF(M12<>"纳入","",IF(VALUE(G12)=6,"",IF(VALUE(G12)=3,0.5,IF(OR(AND(VALUE(G12)<3,P12=R12),AND(VALUE(G12)>3,Q12=R12)),1,0)))) | AC12: =IF(M12<>"纳入","",IF(VALUE(H12)=6,"",IF(VALUE(H12)=3,0.5,IF(OR(AND(VALUE(H12)<3,P12=R12),AND(VALUE(H12)>3,Q12=R12)),1,0)))) | AD12: =IF(M12<>"纳入","",IF(VALUE(I12)=6,"",IF(VALUE(I12)=3,0.5,IF(OR(AND(VALUE(I12)<3,P12=R12),AND(VALUE(I12)>3,Q12=R12)),1,0))))
A13: Q02 | B13: 1 | C13: A 2 / B 3 / 评分 4 | L13: =SUM(IFERROR(IF(AND(VALUE(D13)>=1,VALUE(D13)<=6,MOD(VALUE(D13),1)=0),1,0),0),IFERROR(IF(AND(VALUE(E13)>=1,VALUE(E13)<=6,MOD(VALUE(E13),1)=0),1,0),0),IFERROR(IF(AND(VALUE(F13)>=1,VALUE(F13)<=6,MOD(VALUE(F13),1)=0),1,0),0),IFERROR(IF(AND(VALUE(G13)>=1,VALUE(G13)<=6,MOD(VALUE(G13),1)=0),1,0),0),IFERROR(IF(AND(VALUE(H13)>=1,VALUE(H13)<=6,MOD(VALUE(H13),1)=0),1,0),0),IFERROR(IF(AND(VALUE(I13)>=1,VALUE(I13)<=6,MOD(VALUE(I13),1)=0),1,0),0)) -> 0 | M13: ='参与者登记'!K8 -> 待回收 | N13: 模型 | O13: lwb_hidden_v2_02 | P13: Gemini 3.1 Pro Preview | Q13: Gemini 2.5 Flash | R13: Gemini 2.5 Flash | S13: Gemini 3.1 Pro Preview | T13: =IF(M13<>"纳入","",IF(VALUE(D13)=6,"",IF(VALUE(D13)=3,0.5,IF(OR(AND(VALUE(D13)<3,P13=R13),AND(VALUE(D13)>3,Q13=R13)),1,0)))) | U13: =IF(AND(M13="纳入",IFERROR(VALUE(D13),0)=6),1,0) -> 0 | V13: =IF(AND(M13="纳入",IFERROR(VALUE(D13),0)=3),1,0) -> 0 | W13: =IF(AND(M13="纳入",ISNUMBER(T13),T13=1),1,0) -> 0 | X13: =IF(AND(M13="纳入",ISNUMBER(T13),T13=0),1,0) -> 0 | Y13: =IF(AND(M13="纳入",ISNUMBER(T13)),1,0) -> 0 | Z13: =IF(M13<>"纳入","",IF(VALUE(E13)=6,"",IF(VALUE(E13)=3,0.5,IF(OR(AND(VALUE(E13)<3,P13=R13),AND(VALUE(E13)>3,Q13=R13)),1,0)))) | AA13: =IF(M13<>"纳入","",IF(VALUE(F13)=6,"",IF(VALUE(F13)=3,0.5,IF(OR(AND(VALUE(F13)<3,P13=R13),AND(VALUE(F13)>3,Q13=R13)),1,0)))) | AB13: =IF(M13<>"纳入","",IF(VALUE(G13)=6,"",IF(VALUE(G13)=3,0.5,IF(OR(AND(VALUE(G13)<3,P13=R13),AND(VALUE(G13)>3,Q13=R13)),1,0)))) | AC13: =IF(M13<>"纳入","",IF(VALUE(H13)=6,"",IF(VALUE(H13)=3,0.5,IF(OR(AND(VALUE(H13)<3,P13=R13),AND(VALUE(H13)>3,Q13=R13)),1,0)))) | AD13: =IF(M13<>"纳入","",IF(VALUE(I13)=6,"",IF(VALUE(I13)=3,0.5,IF(OR(AND(VALUE(I13)<3,P13=R13),AND(VALUE(I13)>3,Q13=R13)),1,0))))
A14: Q02 | B14: 2 | C14: A 5 / B 6 / 评分 7 | L14: =SUM(IFERROR(IF(AND(VALUE(D14)>=1,VALUE(D14)<=6,MOD(VALUE(D14),1)=0),1,0),0),IFERROR(IF(AND(VALUE(E14)>=1,VALUE(E14)<=6,MOD(VALUE(E14),1)=0),1,0),0),IFERROR(IF(AND(VALUE(F14)>=1,VALUE(F14)<=6,MOD(VALUE(F14),1)=0),1,0),0),IFERROR(IF(AND(VALUE(G14)>=1,VALUE(G14)<=6,MOD(VALUE(G14),1)=0),1,0),0),IFERROR(IF(AND(VALUE(H14)>=1,VALUE(H14)<=6,MOD(VALUE(H14),1)=0),1,0),0),IFERROR(IF(AND(VALUE(I14)>=1,VALUE(I14)<=6,MOD(VALUE(I14),1)=0),1,0),0)) -> 0 | M14: ='参与者登记'!K8 -> 待回收 | N14: 架构 | O14: mycelium_patent_bazaar | P14: 完整 Agora | Q14: 单次生成基线 | R14: 完整 Agora | S14: 单次生成基线 | T14: =IF(M14<>"纳入","",IF(VALUE(D14)=6,"",IF(VALUE(D14)=3,0.5,IF(OR(AND(VALUE(D14)<3,P14=R14),AND(VALUE(D14)>3,Q14=R14)),1,0)))) | U14: =IF(AND(M14="纳入",IFERROR(VALUE(D14),0)=6),1,0) -> 0 | V14: =IF(AND(M14="纳入",IFERROR(VALUE(D14),0)=3),1,0) -> 0 | W14: =IF(AND(M14="纳入",ISNUMBER(T14),T14=1),1,0) -> 0 | X14: =IF(AND(M14="纳入",ISNUMBER(T14),T14=0),1,0) -> 0 | Y14: =IF(AND(M14="纳入",ISNUMBER(T14)),1,0) -> 0 | Z14: =IF(M14<>"纳入","",IF(VALUE(E14)=6,"",IF(VALUE(E14)=3,0.5,IF(OR(AND(VALUE(E14)<3,P14=R14),AND(VALUE(E14)>3,Q14=R14)),1,0)))) | AA14: =IF(M14<>"纳入","",IF(VALUE(F14)=6,"",IF(VALUE(F14)=3,0.5,IF(OR(AND(VALUE(F14)<3,P14=R14),AND(VALUE(F14)>3,Q14=R14)),1,0)))) | AB14: =IF(M14<>"纳入","",IF(VALUE(G14)=6,"",IF(VALUE(G14)=3,0.5,IF(OR(AND(VALUE(G14)<3,P14=R14),AND(VALUE(G14)>3,Q14=R14)),1,0)))) | AC14: =IF(M14<>"纳入","",IF(VALUE(H14)=6,"",IF(VALUE(H14)=3,0.5,IF(OR(AND(VALUE(H14)<3,P14=R14),AND(VALUE(H14)>3,Q14=R14)),1,0)))) | AD14: =IF(M14<>"纳入","",IF(VALUE(I14)=6,"",IF(VALUE(I14)=3,0.5,IF(OR(AND(VALUE(I14)<3,P14=R14),AND(VALUE(I14)>3,Q14=R14)),1,0))))
A15: Q02 | B15: 3 | C15: A 8 / B 9 / 评分 10 | L15: =SUM(IFERROR(IF(AND(VALUE(D15)>=1,VALUE(D15)<=6,MOD(VALUE(D15),1)=0),1,0),0),IFERROR(IF(AND(VALUE(E15)>=1,VALUE(E15)<=6,MOD(VALUE(E15),1)=0),1,0),0),IFERROR(IF(AND(VALUE(F15)>=1,VALUE(F15)<=6,MOD(VALUE(F15),1)=0),1,0),0),IFERROR(IF(AND(VALUE(G15)>=1,VALUE(G15)<=6,MOD(VALUE(G15),1)=0),1,0),0),IFERROR(IF(AND(VALUE(H15)>=1,VALUE(H15)<=6,MOD(VALUE(H15),1)=0),1,0),0),IFERROR(IF(AND(VALUE(I15)>=1,VALUE(I15)<=6,MOD(VALUE(I15),1)=0),1,0),0)) -> 0 | M15: ='参与者登记'!K8 -> 待回收 | N15: 模型 | O15: lwb_hidden_v2_01 | P15: Gemini 3.5 Flash Lite | Q15: Gemini 2.5 Flash | R15: Gemini 2.5 Flash | S15: Gemini 3.5 Flash Lite | T15: =IF(M15<>"纳入","",IF(VALUE(D15)=6,"",IF(VALUE(D15)=3,0.5,IF(OR(AND(VALUE(D15)<3,P15=R15),AND(VALUE(D15)>3,Q15=R15)),1,0)))) | U15: =IF(AND(M15="纳入",IFERROR(VALUE(D15),0)=6),1,0) -> 0 | V15: =IF(AND(M15="纳入",IFERROR(VALUE(D15),0)=3),1,0) -> 0 | W15: =IF(AND(M15="纳入",ISNUMBER(T15),T15=1),1,0) -> 0 | X15: =IF(AND(M15="纳入",ISNUMBER(T15),T15=0),1,0) -> 0 | Y15: =IF(AND(M15="纳入",ISNUMBER(T15)),1,0) -> 0 | Z15: =IF(M15<>"纳入","",IF(VALUE(E15)=6,"",IF(VALUE(E15)=3,0.5,IF(OR(AND(VALUE(E15)<3,P15=R15),AND(VALUE(E15)>3,Q15=R15)),1,0)))) | AA15: =IF(M15<>"纳入","",IF(VALUE(F15)=6,"",IF(VALUE(F15)=3,0.5,IF(OR(AND(VALUE(F15)<3,P15=R15),AND(VALUE(F15)>3,Q15=R15)),1,0)))) | AB15: =IF(M15<>"纳入","",IF(VALUE(G15)=6,"",IF(VALUE(G15)=3,0.5,IF(OR(AND(VALUE(G15)<3,P15=R15),AND(VALUE(G15)>3,Q15=R15)),1,0)))) | AC15: =IF(M15<>"纳入","",IF(VALUE(H15)=6,"",IF(VALUE(H15)=3,0.5,IF(OR(AND(VALUE(H15)<3,P15=R15),AND(VALUE(H15)>3,Q15=R15)),1,0)))) | AD15: =IF(M15<>"纳入","",IF(VALUE(I15)=6,"",IF(VALUE(I15)=3,0.5,IF(OR(AND(VALUE(I15)<3,P15=R15),AND(VALUE(I15)>3,Q15=R15)),1,0))))
A16: Q02 | B16: 4 | C16: A 11 / B 12 / 评分 13 | L16: =SUM(IFERROR(IF(AND(VALUE(D16)>=1,VALUE(D16)<=6,MOD(VALUE(D16),1)=0),1,0),0),IFERROR(IF(AND(VALUE(E16)>=1,VALUE(E16)<=6,MOD(VALUE(E16),1)=0),1,0),0),IFERROR(IF(AND(VALUE(F16)>=1,VALUE(F16)<=6,MOD(VALUE(F16),1)=0),1,0),0),IFERROR(IF(AND(VALUE(G16)>=1,VALUE(G16)<=6,MOD(VALUE(G16),1)=0),1,0),0),IFERROR(IF(AND(VALUE(H16)>=1,VALUE(H16)<=6,MOD(VALUE(H16),1)=0),1,0),0),IFERROR(IF(AND(VALUE(I16)>=1,VALUE(I16)<=6,MOD(VALUE(I16),1)=0),1,0),0)) -> 0 | M16: ='参与者登记'!K8 -> 待回收 | N16: 模型 | O16: lwb_hidden_v2_01 | P16: GPT-5.6 Sol | Q16: Gemini 3.7 Flash | R16: Gemini 3.7 Flash | S16: GPT-5.6 Sol | T16: =IF(M16<>"纳入","",IF(VALUE(D16)=6,"",IF(VALUE(D16)=3,0.5,IF(OR(AND(VALUE(D16)<3,P16=R16),AND(VALUE(D16)>3,Q16=R16)),1,0)))) | U16: =IF(AND(M16="纳入",IFERROR(VALUE(D16),0)=6),1,0) -> 0 | V16: =IF(AND(M16="纳入",IFERROR(VALUE(D16),0)=3),1,0) -> 0 | W16: =IF(AND(M16="纳入",ISNUMBER(T16),T16=1),1,0) -> 0 | X16: =IF(AND(M16="纳入",ISNUMBER(T16),T16=0),1,0) -> 0 | Y16: =IF(AND(M16="纳入",ISNUMBER(T16)),1,0) -> 0 | Z16: =IF(M16<>"纳入","",IF(VALUE(E16)=6,"",IF(VALUE(E16)=3,0.5,IF(OR(AND(VALUE(E16)<3,P16=R16),AND(VALUE(E16)>3,Q16=R16)),1,0)))) | AA16: =IF(M16<>"纳入","",IF(VALUE(F16)=6,"",IF(VALUE(F16)=3,0.5,IF(OR(AND(VALUE(F16)<3,P16=R16),AND(VALUE(F16)>3,Q16=R16)),1,0)))) | AB16: =IF(M16<>"纳入","",IF(VALUE(G16)=6,"",IF(VALUE(G16)=3,0.5,IF(OR(AND(VALUE(G16)<3,P16=R16),AND(VALUE(G16)>3,Q16=R16)),1,0)))) | AC16: =IF(M16<>"纳入","",IF(VALUE(H16)=6,"",IF(VALUE(H16)=3,0.5,IF(OR(AND(VALUE(H16)<3,P16=R16),AND(VALUE(H16)>3,Q16=R16)),1,0)))) | AD16: =IF(M16<>"纳入","",IF(VALUE(I16)=6,"",IF(VALUE(I16)=3,0.5,IF(OR(AND(VALUE(I16)<3,P16=R16),AND(VALUE(I16)>3,Q16=R16)),1,0))))
A17: Q02 | B17: 5 | C17: A 14 / B 15 / 评分 16 | L17: =SUM(IFERROR(IF(AND(VALUE(D17)>=1,VALUE(D17)<=6,MOD(VALUE(D17),1)=0),1,0),0),IFERROR(IF(AND(VALUE(E17)>=1,VALUE(E17)<=6,MOD(VALUE(E17),1)=0),1,0),0),IFERROR(IF(AND(VALUE(F17)>=1,VALUE(F17)<=6,MOD(VALUE(F17),1)=0),1,0),0),IFERROR(IF(AND(VALUE(G17)>=1,VALUE(G17)<=6,MOD(VALUE(G17),1)=0),1,0),0),IFERROR(IF(AND(VALUE(H17)>=1,VALUE(H17)<=6,MOD(VALUE(H17),1)=0),1,0),0),IFERROR(IF(AND(VALUE(I17)>=1,VALUE(I17)<=6,MOD(VALUE(I17),1)=0),1,0),0)) -> 0 | M17: ='参与者登记'!K8 -> 待回收 | N17: 架构 | O17: aurora_court_of_migrating_cities | P17: 单次生成基线 | Q17: 完整 Agora | R17: 完整 Agora | S17: 单次生成基线 | T17: =IF(M17<>"纳入","",IF(VALUE(D17)=6,"",IF(VALUE(D17)=3,0.5,IF(OR(AND(VALUE(D17)<3,P17=R17),AND(VALUE(D17)>3,Q17=R17)),1,0)))) | U17: =IF(AND(M17="纳入",IFERROR(VALUE(D17),0)=6),1,0) -> 0 | V17: =IF(AND(M17="纳入",IFERROR(VALUE(D17),0)=3),1,0) -> 0 | W17: =IF(AND(M17="纳入",ISNUMBER(T17),T17=1),1,0) -> 0 | X17: =IF(AND(M17="纳入",ISNUMBER(T17),T17=0),1,0) -> 0 | Y17: =IF(AND(M17="纳入",ISNUMBER(T17)),1,0) -> 0 | Z17: =IF(M17<>"纳入","",IF(VALUE(E17)=6,"",IF(VALUE(E17)=3,0.5,IF(OR(AND(VALUE(E17)<3,P17=R17),AND(VALUE(E17)>3,Q17=R17)),1,0)))) | AA17: =IF(M17<>"纳入","",IF(VALUE(F17)=6,"",IF(VALUE(F17)=3,0.5,IF(OR(AND(VALUE(F17)<3,P17=R17),AND(VALUE(F17)>3,Q17=R17)),1,0)))) | AB17: =IF(M17<>"纳入","",IF(VALUE(G17)=6,"",IF(VALUE(G17)=3,0.5,IF(OR(AND(VALUE(G17)<3,P17=R17),AND(VALUE(G17)>3,Q17=R17)),1,0)))) | AC17: =IF(M17<>"纳入","",IF(VALUE(H17)=6,"",IF(VALUE(H17)=3,0.5,IF(OR(AND(VALUE(H17)<3,P17=R17),AND(VALUE(H17)>3,Q17=R17)),1,0)))) | AD17: =IF(M17<>"纳入","",IF(VALUE(I17)=6,"",IF(VALUE(I17)=3,0.5,IF(OR(AND(VALUE(I17)<3,P17=R17),AND(VALUE(I17)>3,Q17=R17)),1,0))))
A18: Q02 | B18: 6 | C18: A 17 / B 18 / 评分 19 | L18: =SUM(IFERROR(IF(AND(VALUE(D18)>=1,VALUE(D18)<=6,MOD(VALUE(D18),1)=0),1,0),0),IFERROR(IF(AND(VALUE(E18)>=1,VALUE(E18)<=6,MOD(VALUE(E18),1)=0),1,0),0),IFERROR(IF(AND(VALUE(F18)>=1,VALUE(F18)<=6,MOD(VALUE(F18),1)=0),1,0),0),IFERROR(IF(AND(VALUE(G18)>=1,VALUE(G18)<=6,MOD(VALUE(G18),1)=0),1,0),0),IFERROR(IF(AND(VALUE(H18)>=1,VALUE(H18)<=6,MOD(VALUE(H18),1)=0),1,0),0),IFERROR(IF(AND(VALUE(I18)>=1,VALUE(I18)<=6,MOD(VALUE(I18),1)=0),1,0),0)) -> 0 | M18: ='参与者登记'!K8 -> 待回收 | N18: 模型 | O18: lwb_hidden_v2_03 | P18: Gemini 3.7 Flash | Q18: GPT-5.6 Sol | R18: Gemini 3.7 Flash | S18: GPT-5.6 Sol | T18: =IF(M18<>"纳入","",IF(VALUE(D18)=6,"",IF(VALUE(D18)=3,0.5,IF(OR(AND(VALUE(D18)<3,P18=R18),AND(VALUE(D18)>3,Q18=R18)),1,0)))) | U18: =IF(AND(M18="纳入",IFERROR(VALUE(D18),0)=6),1,0) -> 0 | V18: =IF(AND(M18="纳入",IFERROR(VALUE(D18),0)=3),1,0) -> 0 | W18: =IF(AND(M18="纳入",ISNUMBER(T18),T18=1),1,0) -> 0 | X18: =IF(AND(M18="纳入",ISNUMBER(T18),T18=0),1,0) -> 0 | Y18: =IF(AND(M18="纳入",ISNUMBER(T18)),1,0) -> 0 | Z18: =IF(M18<>"纳入","",IF(VALUE(E18)=6,"",IF(VALUE(E18)=3,0.5,IF(OR(AND(VALUE(E18)<3,P18=R18),AND(VALUE(E18)>3,Q18=R18)),1,0)))) | AA18: =IF(M18<>"纳入","",IF(VALUE(F18)=6,"",IF(VALUE(F18)=3,0.5,IF(OR(AND(VALUE(F18)<3,P18=R18),AND(VALUE(F18)>3,Q18=R18)),1,0)))) | AB18: =IF(M18<>"纳入","",IF(VALUE(G18)=6,"",IF(VALUE(G18)=3,0.5,IF(OR(AND(VALUE(G18)<3,P18=R18),AND(VALUE(G18)>3,Q18=R18)),1,0)))) | AC18: =IF(M18<>"纳入","",IF(VALUE(H18)=6,"",IF(VALUE(H18)=3,0.5,IF(OR(AND(VALUE(H18)<3,P18=R18),AND(VALUE(H18)>3,Q18=R18)),1,0)))) | AD18: =IF(M18<>"纳入","",IF(VALUE(I18)=6,"",IF(VALUE(I18)=3,0.5,IF(OR(AND(VALUE(I18)<3,P18=R18),AND(VALUE(I18)>3,Q18=R18)),1,0))))
A19: Q03 | B19: 1 | C19: A 2 / B 3 / 评分 4 | L19: =SUM(IFERROR(IF(AND(VALUE(D19)>=1,VALUE(D19)<=6,MOD(VALUE(D19),1)=0),1,0),0),IFERROR(IF(AND(VALUE(E19)>=1,VALUE(E19)<=6,MOD(VALUE(E19),1)=0),1,0),0),IFERROR(IF(AND(VALUE(F19)>=1,VALUE(F19)<=6,MOD(VALUE(F19),1)=0),1,0),0),IFERROR(IF(AND(VALUE(G19)>=1,VALUE(G19)<=6,MOD(VALUE(G19),1)=0),1,0),0),IFERROR(IF(AND(VALUE(H19)>=1,VALUE(H19)<=6,MOD(VALUE(H19),1)=0),1,0),0),IFERROR(IF(AND(VALUE(I19)>=1,VALUE(I19)<=6,MOD(VALUE(I19),1)=0),1,0),0)) -> 0 | M19: ='参与者登记'!K9 -> 待回收 | N19: 架构 | O19: night_market_of_unfinished_weather | P19: 完整 Agora | Q19: 单次生成基线 | R19: 完整 Agora | S19: 单次生成基线 | T19: =IF(M19<>"纳入","",IF(VALUE(D19)=6,"",IF(VALUE(D19)=3,0.5,IF(OR(AND(VALUE(D19)<3,P19=R19),AND(VALUE(D19)>3,Q19=R19)),1,0)))) | U19: =IF(AND(M19="纳入",IFERROR(VALUE(D19),0)=6),1,0) -> 0 | V19: =IF(AND(M19="纳入",IFERROR(VALUE(D19),0)=3),1,0) -> 0 | W19: =IF(AND(M19="纳入",ISNUMBER(T19),T19=1),1,0) -> 0 | X19: =IF(AND(M19="纳入",ISNUMBER(T19),T19=0),1,0) -> 0 | Y19: =IF(AND(M19="纳入",ISNUMBER(T19)),1,0) -> 0 | Z19: =IF(M19<>"纳入","",IF(VALUE(E19)=6,"",IF(VALUE(E19)=3,0.5,IF(OR(AND(VALUE(E19)<3,P19=R19),AND(VALUE(E19)>3,Q19=R19)),1,0)))) | AA19: =IF(M19<>"纳入","",IF(VALUE(F19)=6,"",IF(VALUE(F19)=3,0.5,IF(OR(AND(VALUE(F19)<3,P19=R19),AND(VALUE(F19)>3,Q19=R19)),1,0)))) | AB19: =IF(M19<>"纳入","",IF(VALUE(G19)=6,"",IF(VALUE(G19)=3,0.5,IF(OR(AND(VALUE(G19)<3,P19=R19),AND(VALUE(G19)>3,Q19=R19)),1,0)))) | AC19: =IF(M19<>"纳入","",IF(VALUE(H19)=6,"",IF(VALUE(H19)=3,0.5,IF(OR(AND(VALUE(H19)<3,P19=R19),AND(VALUE(H19)>3,Q19=R19)),1,0)))) | AD19: =IF(M19<>"纳入","",IF(VALUE(I19)=6,"",IF(VALUE(I19)=3,0.5,IF(OR(AND(VALUE(I19)<3,P19=R19),AND(VALUE(I19)>3,Q19=R19)),1,0))))
A20: Q03 | B20: 2 | C20: A 5 / B 6 / 评分 7 | L20: =SUM(IFERROR(IF(AND(VALUE(D20)>=1,VALUE(D20)<=6,MOD(VALUE(D20),1)=0),1,0),0),IFERROR(IF(AND(VALUE(E20)>=1,VALUE(E20)<=6,MOD(VALUE(E20),1)=0),1,0),0),IFERROR(IF(AND(VALUE(F20)>=1,VALUE(F20)<=6,MOD(VALUE(F20),1)=0),1,0),0),IFERROR(IF(AND(VALUE(G20)>=1,VALUE(G20)<=6,MOD(VALUE(G20),1)=0),1,0),0),IFERROR(IF(AND(VALUE(H20)>=1,VALUE(H20)<=6,MOD(VALUE(H20),1)=0),1,0),0),IFERROR(IF(AND(VALUE(I20)>=1,VALUE(I20)<=6,MOD(VALUE(I20),1)=0),1,0),0)) -> 0 | M20: ='参与者登记'!K9 -> 待回收 | N20: 模型 | O20: lwb_hidden_v2_01 | P20: Gemini 2.5 Flash | Q20: GPT-5.6 Sol | R20: Gemini 2.5 Flash | S20: GPT-5.6 Sol | T20: =IF(M20<>"纳入","",IF(VALUE(D20)=6,"",IF(VALUE(D20)=3,0.5,IF(OR(AND(VALUE(D20)<3,P20=R20),AND(VALUE(D20)>3,Q20=R20)),1,0)))) | U20: =IF(AND(M20="纳入",IFERROR(VALUE(D20),0)=6),1,0) -> 0 | V20: =IF(AND(M20="纳入",IFERROR(VALUE(D20),0)=3),1,0) -> 0 | W20: =IF(AND(M20="纳入",ISNUMBER(T20),T20=1),1,0) -> 0 | X20: =IF(AND(M20="纳入",ISNUMBER(T20),T20=0),1,0) -> 0 | Y20: =IF(AND(M20="纳入",ISNUMBER(T20)),1,0) -> 0 | Z20: =IF(M20<>"纳入","",IF(VALUE(E20)=6,"",IF(VALUE(E20)=3,0.5,IF(OR(AND(VALUE(E20)<3,P20=R20),AND(VALUE(E20)>3,Q20=R20)),1,0)))) | AA20: =IF(M20<>"纳入","",IF(VALUE(F20)=6,"",IF(VALUE(F20)=3,0.5,IF(OR(AND(VALUE(F20)<3,P20=R20),AND(VALUE(F20)>3,Q20=R20)),1,0)))) | AB20: =IF(M20<>"纳入","",IF(VALUE(G20)=6,"",IF(VALUE(G20)=3,0.5,IF(OR(AND(VALUE(G20)<3,P20=R20),AND(VALUE(G20)>3,Q20=R20)),1,0)))) | AC20: =IF(M20<>"纳入","",IF(VALUE(H20)=6,"",IF(VALUE(H20)=3,0.5,IF(OR(AND(VALUE(H20)<3,P20=R20),AND(VALUE(H20)>3,Q20=R20)),1,0)))) | AD20: =IF(M20<>"纳入","",IF(VALUE(I20)=6,"",IF(VALUE(I20)=3,0.5,IF(OR(AND(VALUE(I20)<3,P20=R20),AND(VALUE(I20)>3,Q20=R20)),1,0))))
A21: Q03 | B21: 3 | C21: A 8 / B 9 / 评分 10 | L21: =SUM(IFERROR(IF(AND(VALUE(D21)>=1,VALUE(D21)<=6,MOD(VALUE(D21),1)=0),1,0),0),IFERROR(IF(AND(VALUE(E21)>=1,VALUE(E21)<=6,MOD(VALUE(E21),1)=0),1,0),0),IFERROR(IF(AND(VALUE(F21)>=1,VALUE(F21)<=6,MOD(VALUE(F21),1)=0),1,0),0),IFERROR(IF(AND(VALUE(G21)>=1,VALUE(G21)<=6,MOD(VALUE(G21),1)=0),1,0),0),IFERROR(IF(AND(VALUE(H21)>=1,VALUE(H21)<=6,MOD(VALUE(H21),1)=0),1,0),0),IFERROR(IF(AND(VALUE(I21)>=1,VALUE(I21)<=6,MOD(VALUE(I21),1)=0),1,0),0)) -> 0 | M21: ='参与者登记'!K9 -> 待回收 | N21: 模型 | O21: lwb_hidden_v2_03 | P21: Gemini 3.1 Flash Lite | Q21: GPT-5.6 Sol | R21: Gemini 3.1 Flash Lite | S21: GPT-5.6 Sol | T21: =IF(M21<>"纳入","",IF(VALUE(D21)=6,"",IF(VALUE(D21)=3,0.5,IF(OR(AND(VALUE(D21)<3,P21=R21),AND(VALUE(D21)>3,Q21=R21)),1,0)))) | U21: =IF(AND(M21="纳入",IFERROR(VALUE(D21),0)=6),1,0) -> 0 | V21: =IF(AND(M21="纳入",IFERROR(VALUE(D21),0)=3),1,0) -> 0 | W21: =IF(AND(M21="纳入",ISNUMBER(T21),T21=1),1,0) -> 0 | X21: =IF(AND(M21="纳入",ISNUMBER(T21),T21=0),1,0) -> 0 | Y21: =IF(AND(M21="纳入",ISNUMBER(T21)),1,0) -> 0 | Z21: =IF(M21<>"纳入","",IF(VALUE(E21)=6,"",IF(VALUE(E21)=3,0.5,IF(OR(AND(VALUE(E21)<3,P21=R21),AND(VALUE(E21)>3,Q21=R21)),1,0)))) | AA21: =IF(M21<>"纳入","",IF(VALUE(F21)=6,"",IF(VALUE(F21)=3,0.5,IF(OR(AND(VALUE(F21)<3,P21=R21),AND(VALUE(F21)>3,Q21=R21)),1,0)))) | AB21: =IF(M21<>"纳入","",IF(VALUE(G21)=6,"",IF(VALUE(G21)=3,0.5,IF(OR(AND(VALUE(G21)<3,P21=R21),AND(VALUE(G21)>3,Q21=R21)),1,0)))) | AC21: =IF(M21<>"纳入","",IF(VALUE(H21)=6,"",IF(VALUE(H21)=3,0.5,IF(OR(AND(VALUE(H21)<3,P21=R21),AND(VALUE(H21)>3,Q21=R21)),1,0)))) | AD21: =IF(M21<>"纳入","",IF(VALUE(I21)=6,"",IF(VALUE(I21)=3,0.5,IF(OR(AND(VALUE(I21)<3,P21=R21),AND(VALUE(I21)>3,Q21=R21)),1,0))))
A22: Q03 | B22: 4 | C22: A 11 / B 12 / 评分 13 | L22: =SUM(IFERROR(IF(AND(VALUE(D22)>=1,VALUE(D22)<=6,MOD(VALUE(D22),1)=0),1,0),0),IFERROR(IF(AND(VALUE(E22)>=1,VALUE(E22)<=6,MOD(VALUE(E22),1)=0),1,0),0),IFERROR(IF(AND(VALUE(F22)>=1,VALUE(F22)<=6,MOD(VALUE(F22),1)=0),1,0),0),IFERROR(IF(AND(VALUE(G22)>=1,VALUE(G22)<=6,MOD(VALUE(G22),1)=0),1,0),0),IFERROR(IF(AND(VALUE(H22)>=1,VALUE(H22)<=6,MOD(VALUE(H22),1)=0),1,0),0),IFERROR(IF(AND(VALUE(I22)>=1,VALUE(I22)<=6,MOD(VALUE(I22),1)=0),1,0),0)) -> 0 | M22: ='参与者登记'!K9 -> 待回收 | N22: 架构 | O22: archive_of_borrowed_gravity | P22: 单次生成基线 | Q22: 完整 Agora | R22: 完整 Agora | S22: 单次生成基线 | T22: =IF(M22<>"纳入","",IF(VALUE(D22)=6,"",IF(VALUE(D22)=3,0.5,IF(OR(AND(VALUE(D22)<3,P22=R22),AND(VALUE(D22)>3,Q22=R22)),1,0)))) | U22: =IF(AND(M22="纳入",IFERROR(VALUE(D22),0)=6),1,0) -> 0 | V22: =IF(AND(M22="纳入",IFERROR(VALUE(D22),0)=3),1,0) -> 0 | W22: =IF(AND(M22="纳入",ISNUMBER(T22),T22=1),1,0) -> 0 | X22: =IF(AND(M22="纳入",ISNUMBER(T22),T22=0),1,0) -> 0 | Y22: =IF(AND(M22="纳入",ISNUMBER(T22)),1,0) -> 0 | Z22: =IF(M22<>"纳入","",IF(VALUE(E22)=6,"",IF(VALUE(E22)=3,0.5,IF(OR(AND(VALUE(E22)<3,P22=R22),AND(VALUE(E22)>3,Q22=R22)),1,0)))) | AA22: =IF(M22<>"纳入","",IF(VALUE(F22)=6,"",IF(VALUE(F22)=3,0.5,IF(OR(AND(VALUE(F22)<3,P22=R22),AND(VALUE(F22)>3,Q22=R22)),1,0)))) | AB22: =IF(M22<>"纳入","",IF(VALUE(G22)=6,"",IF(VALUE(G22)=3,0.5,IF(OR(AND(VALUE(G22)<3,P22=R22),AND(VALUE(G22)>3,Q22=R22)),1,0)))) | AC22: =IF(M22<>"纳入","",IF(VALUE(H22)=6,"",IF(VALUE(H22)=3,0.5,IF(OR(AND(VALUE(H22)<3,P22=R22),AND(VALUE(H22)>3,Q22=R22)),1,0)))) | AD22: =IF(M22<>"纳入","",IF(VALUE(I22)=6,"",IF(VALUE(I22)=3,0.5,IF(OR(AND(VALUE(I22)<3,P22=R22),AND(VALUE(I22)>3,Q22=R22)),1,0))))
A23: Q03 | B23: 5 | C23: A 14 / B 15 / 评分 16 | L23: =SUM(IFERROR(IF(AND(VALUE(D23)>=1,VALUE(D23)<=6,MOD(VALUE(D23),1)=0),1,0),0),IFERROR(IF(AND(VALUE(E23)>=1,VALUE(E23)<=6,MOD(VALUE(E23),1)=0),1,0),0),IFERROR(IF(AND(VALUE(F23)>=1,VALUE(F23)<=6,MOD(VALUE(F23),1)=0),1,0),0),IFERROR(IF(AND(VALUE(G23)>=1,VALUE(G23)<=6,MOD(VALUE(G23),1)=0),1,0),0),IFERROR(IF(AND(VALUE(H23)>=1,VALUE(H23)<=6,MOD(VALUE(H23),1)=0),1,0),0),IFERROR(IF(AND(VALUE(I23)>=1,VALUE(I23)<=6,MOD(VALUE(I23),1)=0),1,0),0)) -> 0 | M23: ='参与者登记'!K9 -> 待回收 | N23: 模型 | O23: lwb_hidden_v2_01 | P23: Gemini 3.5 Flash Lite | Q23: Gemini 3.1 Pro Preview | R23: Gemini 3.1 Pro Preview | S23: Gemini 3.5 Flash Lite | T23: =IF(M23<>"纳入","",IF(VALUE(D23)=6,"",IF(VALUE(D23)=3,0.5,IF(OR(AND(VALUE(D23)<3,P23=R23),AND(VALUE(D23)>3,Q23=R23)),1,0)))) | U23: =IF(AND(M23="纳入",IFERROR(VALUE(D23),0)=6),1,0) -> 0 | V23: =IF(AND(M23="纳入",IFERROR(VALUE(D23),0)=3),1,0) -> 0 | W23: =IF(AND(M23="纳入",ISNUMBER(T23),T23=1),1,0) -> 0 | X23: =IF(AND(M23="纳入",ISNUMBER(T23),T23=0),1,0) -> 0 | Y23: =IF(AND(M23="纳入",ISNUMBER(T23)),1,0) -> 0 | Z23: =IF(M23<>"纳入","",IF(VALUE(E23)=6,"",IF(VALUE(E23)=3,0.5,IF(OR(AND(VALUE(E23)<3,P23=R23),AND(VALUE(E23)>3,Q23=R23)),1,0)))) | AA23: =IF(M23<>"纳入","",IF(VALUE(F23)=6,"",IF(VALUE(F23)=3,0.5,IF(OR(AND(VALUE(F23)<3,P23=R23),AND(VALUE(F23)>3,Q23=R23)),1,0)))) | AB23: =IF(M23<>"纳入","",IF(VALUE(G23)=6,"",IF(VALUE(G23)=3,0.5,IF(OR(AND(VALUE(G23)<3,P23=R23),AND(VALUE(G23)>3,Q23=R23)),1,0)))) | AC23: =IF(M23<>"纳入","",IF(VALUE(H23)=6,"",IF(VALUE(H23)=3,0.5,IF(OR(AND(VALUE(H23)<3,P23=R23),AND(VALUE(H23)>3,Q23=R23)),1,0)))) | AD23: =IF(M23<>"纳入","",IF(VALUE(I23)=6,"",IF(VALUE(I23)=3,0.5,IF(OR(AND(VALUE(I23)<3,P23=R23),AND(VALUE(I23)>3,Q23=R23)),1,0))))
A24: Q03 | B24: 6 | C24: A 17 / B 18 / 评分 19 | L24: =SUM(IFERROR(IF(AND(VALUE(D24)>=1,VALUE(D24)<=6,MOD(VALUE(D24),1)=0),1,0),0),IFERROR(IF(AND(VALUE(E24)>=1,VALUE(E24)<=6,MOD(VALUE(E24),1)=0),1,0),0),IFERROR(IF(AND(VALUE(F24)>=1,VALUE(F24)<=6,MOD(VALUE(F24),1)=0),1,0),0),IFERROR(IF(AND(VALUE(G24)>=1,VALUE(G24)<=6,MOD(VALUE(G24),1)=0),1,0),0),IFERROR(IF(AND(VALUE(H24)>=1,VALUE(H24)<=6,MOD(VALUE(H24),1)=0),1,0),0),IFERROR(IF(AND(VALUE(I24)>=1,VALUE(I24)<=6,MOD(VALUE(I24),1)=0),1,0),0)) -> 0 | M24: ='参与者登记'!K9 -> 待回收 | N24: 模型 | O24: lwb_hidden_v2_02 | P24: Gemini 3.7 Flash | Q24: GPT-5.6 Sol | R24: Gemini 3.7 Flash | S24: GPT-5.6 Sol | T24: =IF(M24<>"纳入","",IF(VALUE(D24)=6,"",IF(VALUE(D24)=3,0.5,IF(OR(AND(VALUE(D24)<3,P24=R24),AND(VALUE(D24)>3,Q24=R24)),1,0)))) | U24: =IF(AND(M24="纳入",IFERROR(VALUE(D24),0)=6),1,0) -> 0 | V24: =IF(AND(M24="纳入",IFERROR(VALUE(D24),0)=3),1,0) -> 0 | W24: =IF(AND(M24="纳入",ISNUMBER(T24),T24=1),1,0) -> 0 | X24: =IF(AND(M24="纳入",ISNUMBER(T24),T24=0),1,0) -> 0 | Y24: =IF(AND(M24="纳入",ISNUMBER(T24)),1,0) -> 0 | Z24: =IF(M24<>"纳入","",IF(VALUE(E24)=6,"",IF(VALUE(E24)=3,0.5,IF(OR(AND(VALUE(E24)<3,P24=R24),AND(VALUE(E24)>3,Q24=R24)),1,0)))) | AA24: =IF(M24<>"纳入","",IF(VALUE(F24)=6,"",IF(VALUE(F24)=3,0.5,IF(OR(AND(VALUE(F24)<3,P24=R24),AND(VALUE(F24)>3,Q24=R24)),1,0)))) | AB24: =IF(M24<>"纳入","",IF(VALUE(G24)=6,"",IF(VALUE(G24)=3,0.5,IF(OR(AND(VALUE(G24)<3,P24=R24),AND(VALUE(G24)>3,Q24=R24)),1,0)))) | AC24: =IF(M24<>"纳入","",IF(VALUE(H24)=6,"",IF(VALUE(H24)=3,0.5,IF(OR(AND(VALUE(H24)<3,P24=R24),AND(VALUE(H24)>3,Q24=R24)),1,0)))) | AD24: =IF(M24<>"纳入","",IF(VALUE(I24)=6,"",IF(VALUE(I24)=3,0.5,IF(OR(AND(VALUE(I24)<3,P24=R24),AND(VALUE(I24)>3,Q24=R24)),1,0))))
A25: Q04 | B25: 1 | C25: A 2 / B 3 / 评分 4 | L25: =SUM(IFERROR(IF(AND(VALUE(D25)>=1,VALUE(D25)<=6,MOD(VALUE(D25),1)=0),1,0),0),IFERROR(IF(AND(VALUE(E25)>=1,VALUE(E25)<=6,MOD(VALUE(E25),1)=0),1,0),0),IFERROR(IF(AND(VALUE(F25)>=1,VALUE(F25)<=6,MOD(VALUE(F25),1)=0),1,0),0),IFERROR(IF(AND(VALUE(G25)>=1,VALUE(G25)<=6,MOD(VALUE(G25),1)=0),1,0),0),IFERROR(IF(AND(VALUE(H25)>=1,VALUE(H25)<=6,MOD(VALUE(H25),1)=0),1,0),0),IFERROR(IF(AND(VALUE(I25)>=1,VALUE(I25)<=6,MOD(VALUE(I25),1)=0),1,0),0)) -> 0 | M25: ='参与者登记'!K10 -> 待回收 | N25: 模型 | O25: lwb_hidden_v2_02 | P25: Gemini 3.7 Flash | Q25: Gemini 3.1 Pro Preview | R25: Gemini 3.1 Pro Preview | S25: Gemini 3.7 Flash | T25: =IF(M25<>"纳入","",IF(VALUE(D25)=6,"",IF(VALUE(D25)=3,0.5,IF(OR(AND(VALUE(D25)<3,P25=R25),AND(VALUE(D25)>3,Q25=R25)),1,0)))) | U25: =IF(AND(M25="纳入",IFERROR(VALUE(D25),0)=6),1,0) -> 0 | V25: =IF(AND(M25="纳入",IFERROR(VALUE(D25),0)=3),1,0) -> 0 | W25: =IF(AND(M25="纳入",ISNUMBER(T25),T25=1),1,0) -> 0 | X25: =IF(AND(M25="纳入",ISNUMBER(T25),T25=0),1,0) -> 0 | Y25: =IF(AND(M25="纳入",ISNUMBER(T25)),1,0) -> 0 | Z25: =IF(M25<>"纳入","",IF(VALUE(E25)=6,"",IF(VALUE(E25)=3,0.5,IF(OR(AND(VALUE(E25)<3,P25=R25),AND(VALUE(E25)>3,Q25=R25)),1,0)))) | AA25: =IF(M25<>"纳入","",IF(VALUE(F25)=6,"",IF(VALUE(F25)=3,0.5,IF(OR(AND(VALUE(F25)<3,P25=R25),AND(VALUE(F25)>3,Q25=R25)),1,0)))) | AB25: =IF(M25<>"纳入","",IF(VALUE(G25)=6,"",IF(VALUE(G25)=3,0.5,IF(OR(AND(VALUE(G25)<3,P25=R25),AND(VALUE(G25)>3,Q25=R25)),1,0)))) | AC25: =IF(M25<>"纳入","",IF(VALUE(H25)=6,"",IF(VALUE(H25)=3,0.5,IF(OR(AND(VALUE(H25)<3,P25=R25),AND(VALUE(H25)>3,Q25=R25)),1,0)))) | AD25: =IF(M25<>"纳入","",IF(VALUE(I25)=6,"",IF(VALUE(I25)=3,0.5,IF(OR(AND(VALUE(I25)<3,P25=R25),AND(VALUE(I25)>3,Q25=R25)),1,0))))
A26: Q04 | B26: 2 | C26: A 5 / B 6 / 评分 7 | L26: =SUM(IFERROR(IF(AND(VALUE(D26)>=1,VALUE(D26)<=6,MOD(VALUE(D26),1)=0),1,0),0),IFERROR(IF(AND(VALUE(E26)>=1,VALUE(E26)<=6,MOD(VALUE(E26),1)=0),1,0),0),IFERROR(IF(AND(VALUE(F26)>=1,VALUE(F26)<=6,MOD(VALUE(F26),1)=0),1,0),0),IFERROR(IF(AND(VALUE(G26)>=1,VALUE(G26)<=6,MOD(VALUE(G26),1)=0),1,0),0),IFERROR(IF(AND(VALUE(H26)>=1,VALUE(H26)<=6,MOD(VALUE(H26),1)=0),1,0),0),IFERROR(IF(AND(VALUE(I26)>=1,VALUE(I26)<=6,MOD(VALUE(I26),1)=0),1,0),0)) -> 0 | M26: ='参与者登记'!K10 -> 待回收 | N26: 模型 | O26: lwb_hidden_v2_03 | P26: Gemini 3.1 Flash Lite | Q26: Gemini 3.1 Pro Preview | R26: Gemini 3.1 Flash Lite | S26: Gemini 3.1 Pro Preview | T26: =IF(M26<>"纳入","",IF(VALUE(D26)=6,"",IF(VALUE(D26)=3,0.5,IF(OR(AND(VALUE(D26)<3,P26=R26),AND(VALUE(D26)>3,Q26=R26)),1,0)))) | U26: =IF(AND(M26="纳入",IFERROR(VALUE(D26),0)=6),1,0) -> 0 | V26: =IF(AND(M26="纳入",IFERROR(VALUE(D26),0)=3),1,0) -> 0 | W26: =IF(AND(M26="纳入",ISNUMBER(T26),T26=1),1,0) -> 0 | X26: =IF(AND(M26="纳入",ISNUMBER(T26),T26=0),1,0) -> 0 | Y26: =IF(AND(M26="纳入",ISNUMBER(T26)),1,0) -> 0 | Z26: =IF(M26<>"纳入","",IF(VALUE(E26)=6,"",IF(VALUE(E26)=3,0.5,IF(OR(AND(VALUE(E26)<3,P26=R26),AND(VALUE(E26)>3,Q26=R26)),1,0)))) | AA26: =IF(M26<>"纳入","",IF(VALUE(F26)=6,"",IF(VALUE(F26)=3,0.5,IF(OR(AND(VALUE(F26)<3,P26=R26),AND(VALUE(F26)>3,Q26=R26)),1,0)))) | AB26: =IF(M26<>"纳入","",IF(VALUE(G26)=6,"",IF(VALUE(G26)=3,0.5,IF(OR(AND(VALUE(G26)<3,P26=R26),AND(VALUE(G26)>3,Q26=R26)),1,0)))) | AC26: =IF(M26<>"纳入","",IF(VALUE(H26)=6,"",IF(VALUE(H26)=3,0.5,IF(OR(AND(VALUE(H26)<3,P26=R26),AND(VALUE(H26)>3,Q26=R26)),1,0)))) | AD26: =IF(M26<>"纳入","",IF(VALUE(I26)=6,"",IF(VALUE(I26)=3,0.5,IF(OR(AND(VALUE(I26)<3,P26=R26),AND(VALUE(I26)>3,Q26=R26)),1,0))))
A27: Q04 | B27: 3 | C27: A 8 / B 9 / 评分 10 | L27: =SUM(IFERROR(IF(AND(VALUE(D27)>=1,VALUE(D27)<=6,MOD(VALUE(D27),1)=0),1,0),0),IFERROR(IF(AND(VALUE(E27)>=1,VALUE(E27)<=6,MOD(VALUE(E27),1)=0),1,0),0),IFERROR(IF(AND(VALUE(F27)>=1,VALUE(F27)<=6,MOD(VALUE(F27),1)=0),1,0),0),IFERROR(IF(AND(VALUE(G27)>=1,VALUE(G27)<=6,MOD(VALUE(G27),1)=0),1,0),0),IFERROR(IF(AND(VALUE(H27)>=1,VALUE(H27)<=6,MOD(VALUE(H27),1)=0),1,0),0),IFERROR(IF(AND(VALUE(I27)>=1,VALUE(I27)<=6,MOD(VALUE(I27),1)=0),1,0),0)) -> 0 | M27: ='参与者登记'!K10 -> 待回收 | N27: 架构 | O27: archive_of_borrowed_gravity | P27: 完整 Agora | Q27: 单次生成基线 | R27: 完整 Agora | S27: 单次生成基线 | T27: =IF(M27<>"纳入","",IF(VALUE(D27)=6,"",IF(VALUE(D27)=3,0.5,IF(OR(AND(VALUE(D27)<3,P27=R27),AND(VALUE(D27)>3,Q27=R27)),1,0)))) | U27: =IF(AND(M27="纳入",IFERROR(VALUE(D27),0)=6),1,0) -> 0 | V27: =IF(AND(M27="纳入",IFERROR(VALUE(D27),0)=3),1,0) -> 0 | W27: =IF(AND(M27="纳入",ISNUMBER(T27),T27=1),1,0) -> 0 | X27: =IF(AND(M27="纳入",ISNUMBER(T27),T27=0),1,0) -> 0 | Y27: =IF(AND(M27="纳入",ISNUMBER(T27)),1,0) -> 0 | Z27: =IF(M27<>"纳入","",IF(VALUE(E27)=6,"",IF(VALUE(E27)=3,0.5,IF(OR(AND(VALUE(E27)<3,P27=R27),AND(VALUE(E27)>3,Q27=R27)),1,0)))) | AA27: =IF(M27<>"纳入","",IF(VALUE(F27)=6,"",IF(VALUE(F27)=3,0.5,IF(OR(AND(VALUE(F27)<3,P27=R27),AND(VALUE(F27)>3,Q27=R27)),1,0)))) | AB27: =IF(M27<>"纳入","",IF(VALUE(G27)=6,"",IF(VALUE(G27)=3,0.5,IF(OR(AND(VALUE(G27)<3,P27=R27),AND(VALUE(G27)>3,Q27=R27)),1,0)))) | AC27: =IF(M27<>"纳入","",IF(VALUE(H27)=6,"",IF(VALUE(H27)=3,0.5,IF(OR(AND(VALUE(H27)<3,P27=R27),AND(VALUE(H27)>3,Q27=R27)),1,0)))) | AD27: =IF(M27<>"纳入","",IF(VALUE(I27)=6,"",IF(VALUE(I27)=3,0.5,IF(OR(AND(VALUE(I27)<3,P27=R27),AND(VALUE(I27)>3,Q27=R27)),1,0))))
A28: Q04 | B28: 4 | C28: A 11 / B 12 / 评分 13 | L28: =SUM(IFERROR(IF(AND(VALUE(D28)>=1,VALUE(D28)<=6,MOD(VALUE(D28),1)=0),1,0),0),IFERROR(IF(AND(VALUE(E28)>=1,VALUE(E28)<=6,MOD(VALUE(E28),1)=0),1,0),0),IFERROR(IF(AND(VALUE(F28)>=1,VALUE(F28)<=6,MOD(VALUE(F28),1)=0),1,0),0),IFERROR(IF(AND(VALUE(G28)>=1,VALUE(G28)<=6,MOD(VALUE(G28),1)=0),1,0),0),IFERROR(IF(AND(VALUE(H28)>=1,VALUE(H28)<=6,MOD(VALUE(H28),1)=0),1,0),0),IFERROR(IF(AND(VALUE(I28)>=1,VALUE(I28)<=6,MOD(VALUE(I28),1)=0),1,0),0)) -> 0 | M28: ='参与者登记'!K10 -> 待回收 | N28: 模型 | O28: lwb_hidden_v2_01 | P28: Gemini 3.7 Flash | Q28: Gemini 3.1 Flash Lite | R28: Gemini 3.1 Flash Lite | S28: Gemini 3.7 Flash | T28: =IF(M28<>"纳入","",IF(VALUE(D28)=6,"",IF(VALUE(D28)=3,0.5,IF(OR(AND(VALUE(D28)<3,P28=R28),AND(VALUE(D28)>3,Q28=R28)),1,0)))) | U28: =IF(AND(M28="纳入",IFERROR(VALUE(D28),0)=6),1,0) -> 0 | V28: =IF(AND(M28="纳入",IFERROR(VALUE(D28),0)=3),1,0) -> 0 | W28: =IF(AND(M28="纳入",ISNUMBER(T28),T28=1),1,0) -> 0 | X28: =IF(AND(M28="纳入",ISNUMBER(T28),T28=0),1,0) -> 0 | Y28: =IF(AND(M28="纳入",ISNUMBER(T28)),1,0) -> 0 | Z28: =IF(M28<>"纳入","",IF(VALUE(E28)=6,"",IF(VALUE(E28)=3,0.5,IF(OR(AND(VALUE(E28)<3,P28=R28),AND(VALUE(E28)>3,Q28=R28)),1,0)))) | AA28: =IF(M28<>"纳入","",IF(VALUE(F28)=6,"",IF(VALUE(F28)=3,0.5,IF(OR(AND(VALUE(F28)<3,P28=R28),AND(VALUE(F28)>3,Q28=R28)),1,0)))) | AB28: =IF(M28<>"纳入","",IF(VALUE(G28)=6,"",IF(VALUE(G28)=3,0.5,IF(OR(AND(VALUE(G28)<3,P28=R28),AND(VALUE(G28)>3,Q28=R28)),1,0)))) | AC28: =IF(M28<>"纳入","",IF(VALUE(H28)=6,"",IF(VALUE(H28)=3,0.5,IF(OR(AND(VALUE(H28)<3,P28=R28),AND(VALUE(H28)>3,Q28=R28)),1,0)))) | AD28: =IF(M28<>"纳入","",IF(VALUE(I28)=6,"",IF(VALUE(I28)=3,0.5,IF(OR(AND(VALUE(I28)<3,P28=R28),AND(VALUE(I28)>3,Q28=R28)),1,0))))
A29: Q04 | B29: 5 | C29: A 14 / B 15 / 评分 16 | L29: =SUM(IFERROR(IF(AND(VALUE(D29)>=1,VALUE(D29)<=6,MOD(VALUE(D29),1)=0),1,0),0),IFERROR(IF(AND(VALUE(E29)>=1,VALUE(E29)<=6,MOD(VALUE(E29),1)=0),1,0),0),IFERROR(IF(AND(VALUE(F29)>=1,VALUE(F29)<=6,MOD(VALUE(F29),1)=0),1,0),0),IFERROR(IF(AND(VALUE(G29)>=1,VALUE(G29)<=6,MOD(VALUE(G29),1)=0),1,0),0),IFERROR(IF(AND(VALUE(H29)>=1,VALUE(H29)<=6,MOD(VALUE(H29),1)=0),1,0),0),IFERROR(IF(AND(VALUE(I29)>=1,VALUE(I29)<=6,MOD(VALUE(I29),1)=0),1,0),0)) -> 0 | M29: ='参与者登记'!K10 -> 待回收 | N29: 模型 | O29: lwb_hidden_v2_01 | P29: Gemini 3.1 Flash Lite | Q29: GPT-5.6 Sol | R29: Gemini 3.1 Flash Lite | S29: GPT-5.6 Sol | T29: =IF(M29<>"纳入","",IF(VALUE(D29)=6,"",IF(VALUE(D29)=3,0.5,IF(OR(AND(VALUE(D29)<3,P29=R29),AND(VALUE(D29)>3,Q29=R29)),1,0)))) | U29: =IF(AND(M29="纳入",IFERROR(VALUE(D29),0)=6),1,0) -> 0 | V29: =IF(AND(M29="纳入",IFERROR(VALUE(D29),0)=3),1,0) -> 0 | W29: =IF(AND(M29="纳入",ISNUMBER(T29),T29=1),1,0) -> 0 | X29: =IF(AND(M29="纳入",ISNUMBER(T29),T29=0),1,0) -> 0 | Y29: =IF(AND(M29="纳入",ISNUMBER(T29)),1,0) -> 0 | Z29: =IF(M29<>"纳入","",IF(VALUE(E29)=6,"",IF(VALUE(E29)=3,0.5,IF(OR(AND(VALUE(E29)<3,P29=R29),AND(VALUE(E29)>3,Q29=R29)),1,0)))) | AA29: =IF(M29<>"纳入","",IF(VALUE(F29)=6,"",IF(VALUE(F29)=3,0.5,IF(OR(AND(VALUE(F29)<3,P29=R29),AND(VALUE(F29)>3,Q29=R29)),1,0)))) | AB29: =IF(M29<>"纳入","",IF(VALUE(G29)=6,"",IF(VALUE(G29)=3,0.5,IF(OR(AND(VALUE(G29)<3,P29=R29),AND(VALUE(G29)>3,Q29=R29)),1,0)))) | AC29: =IF(M29<>"纳入","",IF(VALUE(H29)=6,"",IF(VALUE(H29)=3,0.5,IF(OR(AND(VALUE(H29)<3,P29=R29),AND(VALUE(H29)>3,Q29=R29)),1,0)))) | AD29: =IF(M29<>"纳入","",IF(VALUE(I29)=6,"",IF(VALUE(I29)=3,0.5,IF(OR(AND(VALUE(I29)<3,P29=R29),AND(VALUE(I29)>3,Q29=R29)),1,0))))
A30: Q04 | B30: 6 | C30: A 17 / B 18 / 评分 19 | L30: =SUM(IFERROR(IF(AND(VALUE(D30)>=1,VALUE(D30)<=6,MOD(VALUE(D30),1)=0),1,0),0),IFERROR(IF(AND(VALUE(E30)>=1,VALUE(E30)<=6,MOD(VALUE(E30),1)=0),1,0),0),IFERROR(IF(AND(VALUE(F30)>=1,VALUE(F30)<=6,MOD(VALUE(F30),1)=0),1,0),0),IFERROR(IF(AND(VALUE(G30)>=1,VALUE(G30)<=6,MOD(VALUE(G30),1)=0),1,0),0),IFERROR(IF(AND(VALUE(H30)>=1,VALUE(H30)<=6,MOD(VALUE(H30),1)=0),1,0),0),IFERROR(IF(AND(VALUE(I30)>=1,VALUE(I30)<=6,MOD(VALUE(I30),1)=0),1,0),0)) -> 0 | M30: ='参与者登记'!K10 -> 待回收 | N30: 架构 | O30: tidal_embassy_of_lost_languages | P30: 单次生成基线 | Q30: 完整 Agora | R30: 完整 Agora | S30: 单次生成基线 | T30: =IF(M30<>"纳入","",IF(VALUE(D30)=6,"",IF(VALUE(D30)=3,0.5,IF(OR(AND(VALUE(D30)<3,P30=R30),AND(VALUE(D30)>3,Q30=R30)),1,0)))) | U30: =IF(AND(M30="纳入",IFERROR(VALUE(D30),0)=6),1,0) -> 0 | V30: =IF(AND(M30="纳入",IFERROR(VALUE(D30),0)=3),1,0) -> 0 | W30: =IF(AND(M30="纳入",ISNUMBER(T30),T30=1),1,0) -> 0 | X30: =IF(AND(M30="纳入",ISNUMBER(T30),T30=0),1,0) -> 0 | Y30: =IF(AND(M30="纳入",ISNUMBER(T30)),1,0) -> 0 | Z30: =IF(M30<>"纳入","",IF(VALUE(E30)=6,"",IF(VALUE(E30)=3,0.5,IF(OR(AND(VALUE(E30)<3,P30=R30),AND(VALUE(E30)>3,Q30=R30)),1,0)))) | AA30: =IF(M30<>"纳入","",IF(VALUE(F30)=6,"",IF(VALUE(F30)=3,0.5,IF(OR(AND(VALUE(F30)<3,P30=R30),AND(VALUE(F30)>3,Q30=R30)),1,0)))) | AB30: =IF(M30<>"纳入","",IF(VALUE(G30)=6,"",IF(VALUE(G30)=3,0.5,IF(OR(AND(VALUE(G30)<3,P30=R30),AND(VALUE(G30)>3,Q30=R30)),1,0)))) | AC30: =IF(M30<>"纳入","",IF(VALUE(H30)=6,"",IF(VALUE(H30)=3,0.5,IF(OR(AND(VALUE(H30)<3,P30=R30),AND(VALUE(H30)>3,Q30=R30)),1,0)))) | AD30: =IF(M30<>"纳入","",IF(VALUE(I30)=6,"",IF(VALUE(I30)=3,0.5,IF(OR(AND(VALUE(I30)<3,P30=R30),AND(VALUE(I30)>3,Q30=R30)),1,0))))
A31: Q05 | B31: 1 | C31: A 2 / B 3 / 评分 4 | L31: =SUM(IFERROR(IF(AND(VALUE(D31)>=1,VALUE(D31)<=6,MOD(VALUE(D31),1)=0),1,0),0),IFERROR(IF(AND(VALUE(E31)>=1,VALUE(E31)<=6,MOD(VALUE(E31),1)=0),1,0),0),IFERROR(IF(AND(VALUE(F31)>=1,VALUE(F31)<=6,MOD(VALUE(F31),1)=0),1,0),0),IFERROR(IF(AND(VALUE(G31)>=1,VALUE(G31)<=6,MOD(VALUE(G31),1)=0),1,0),0),IFERROR(IF(AND(VALUE(H31)>=1,VALUE(H31)<=6,MOD(VALUE(H31),1)=0),1,0),0),IFERROR(IF(AND(VALUE(I31)>=1,VALUE(I31)<=6,MOD(VALUE(I31),1)=0),1,0),0)) -> 0 | M31: ='参与者登记'!K11 -> 待回收 | N31: 模型 | O31: lwb_hidden_v2_01 | P31: GPT-5.6 Sol | Q31: Gemini 3.5 Flash Lite | R31: Gemini 3.5 Flash Lite | S31: GPT-5.6 Sol | T31: =IF(M31<>"纳入","",IF(VALUE(D31)=6,"",IF(VALUE(D31)=3,0.5,IF(OR(AND(VALUE(D31)<3,P31=R31),AND(VALUE(D31)>3,Q31=R31)),1,0)))) | U31: =IF(AND(M31="纳入",IFERROR(VALUE(D31),0)=6),1,0) -> 0 | V31: =IF(AND(M31="纳入",IFERROR(VALUE(D31),0)=3),1,0) -> 0 | W31: =IF(AND(M31="纳入",ISNUMBER(T31),T31=1),1,0) -> 0 | X31: =IF(AND(M31="纳入",ISNUMBER(T31),T31=0),1,0) -> 0 | Y31: =IF(AND(M31="纳入",ISNUMBER(T31)),1,0) -> 0 | Z31: =IF(M31<>"纳入","",IF(VALUE(E31)=6,"",IF(VALUE(E31)=3,0.5,IF(OR(AND(VALUE(E31)<3,P31=R31),AND(VALUE(E31)>3,Q31=R31)),1,0)))) | AA31: =IF(M31<>"纳入","",IF(VALUE(F31)=6,"",IF(VALUE(F31)=3,0.5,IF(OR(AND(VALUE(F31)<3,P31=R31),AND(VALUE(F31)>3,Q31=R31)),1,0)))) | AB31: =IF(M31<>"纳入","",IF(VALUE(G31)=6,"",IF(VALUE(G31)=3,0.5,IF(OR(AND(VALUE(G31)<3,P31=R31),AND(VALUE(G31)>3,Q31=R31)),1,0)))) | AC31: =IF(M31<>"纳入","",IF(VALUE(H31)=6,"",IF(VALUE(H31)=3,0.5,IF(OR(AND(VALUE(H31)<3,P31=R31),AND(VALUE(H31)>3,Q31=R31)),1,0)))) | AD31: =IF(M31<>"纳入","",IF(VALUE(I31)=6,"",IF(VALUE(I31)=3,0.5,IF(OR(AND(VALUE(I31)<3,P31=R31),AND(VALUE(I31)>3,Q31=R31)),1,0))))
A32: Q05 | B32: 2 | C32: A 5 / B 6 / 评分 7 | L32: =SUM(IFERROR(IF(AND(VALUE(D32)>=1,VALUE(D32)<=6,MOD(VALUE(D32),1)=0),1,0),0),IFERROR(IF(AND(VALUE(E32)>=1,VALUE(E32)<=6,MOD(VALUE(E32),1)=0),1,0),0),IFERROR(IF(AND(VALUE(F32)>=1,VALUE(F32)<=6,MOD(VALUE(F32),1)=0),1,0),0),IFERROR(IF(AND(VALUE(G32)>=1,VALUE(G32)<=6,MOD(VALUE(G32),1)=0),1,0),0),IFERROR(IF(AND(VALUE(H32)>=1,VALUE(H32)<=6,MOD(VALUE(H32),1)=0),1,0),0),IFERROR(IF(AND(VALUE(I32)>=1,VALUE(I32)<=6,MOD(VALUE(I32),1)=0),1,0),0)) -> 0 | M32: ='参与者登记'!K11 -> 待回收 | N32: 架构 | O32: museum_of_future_debts | P32: 单次生成基线 | Q32: 完整 Agora | R32: 完整 Agora | S32: 单次生成基线 | T32: =IF(M32<>"纳入","",IF(VALUE(D32)=6,"",IF(VALUE(D32)=3,0.5,IF(OR(AND(VALUE(D32)<3,P32=R32),AND(VALUE(D32)>3,Q32=R32)),1,0)))) | U32: =IF(AND(M32="纳入",IFERROR(VALUE(D32),0)=6),1,0) -> 0 | V32: =IF(AND(M32="纳入",IFERROR(VALUE(D32),0)=3),1,0) -> 0 | W32: =IF(AND(M32="纳入",ISNUMBER(T32),T32=1),1,0) -> 0 | X32: =IF(AND(M32="纳入",ISNUMBER(T32),T32=0),1,0) -> 0 | Y32: =IF(AND(M32="纳入",ISNUMBER(T32)),1,0) -> 0 | Z32: =IF(M32<>"纳入","",IF(VALUE(E32)=6,"",IF(VALUE(E32)=3,0.5,IF(OR(AND(VALUE(E32)<3,P32=R32),AND(VALUE(E32)>3,Q32=R32)),1,0)))) | AA32: =IF(M32<>"纳入","",IF(VALUE(F32)=6,"",IF(VALUE(F32)=3,0.5,IF(OR(AND(VALUE(F32)<3,P32=R32),AND(VALUE(F32)>3,Q32=R32)),1,0)))) | AB32: =IF(M32<>"纳入","",IF(VALUE(G32)=6,"",IF(VALUE(G32)=3,0.5,IF(OR(AND(VALUE(G32)<3,P32=R32),AND(VALUE(G32)>3,Q32=R32)),1,0)))) | AC32: =IF(M32<>"纳入","",IF(VALUE(H32)=6,"",IF(VALUE(H32)=3,0.5,IF(OR(AND(VALUE(H32)<3,P32=R32),AND(VALUE(H32)>3,Q32=R32)),1,0)))) | AD32: =IF(M32<>"纳入","",IF(VALUE(I32)=6,"",IF(VALUE(I32)=3,0.5,IF(OR(AND(VALUE(I32)<3,P32=R32),AND(VALUE(I32)>3,Q32=R32)),1,0))))
A33: Q05 | B33: 3 | C33: A 8 / B 9 / 评分 10 | L33: =SUM(IFERROR(IF(AND(VALUE(D33)>=1,VALUE(D33)<=6,MOD(VALUE(D33),1)=0),1,0),0),IFERROR(IF(AND(VALUE(E33)>=1,VALUE(E33)<=6,MOD(VALUE(E33),1)=0),1,0),0),IFERROR(IF(AND(VALUE(F33)>=1,VALUE(F33)<=6,MOD(VALUE(F33),1)=0),1,0),0),IFERROR(IF(AND(VALUE(G33)>=1,VALUE(G33)<=6,MOD(VALUE(G33),1)=0),1,0),0),IFERROR(IF(AND(VALUE(H33)>=1,VALUE(H33)<=6,MOD(VALUE(H33),1)=0),1,0),0),IFERROR(IF(AND(VALUE(I33)>=1,VALUE(I33)<=6,MOD(VALUE(I33),1)=0),1,0),0)) -> 0 | M33: ='参与者登记'!K11 -> 待回收 | N33: 模型 | O33: lwb_hidden_v2_01 | P33: GPT-5.6 Terra | Q33: Gemini 3.1 Pro Preview | R33: Gemini 3.1 Pro Preview | S33: GPT-5.6 Terra | T33: =IF(M33<>"纳入","",IF(VALUE(D33)=6,"",IF(VALUE(D33)=3,0.5,IF(OR(AND(VALUE(D33)<3,P33=R33),AND(VALUE(D33)>3,Q33=R33)),1,0)))) | U33: =IF(AND(M33="纳入",IFERROR(VALUE(D33),0)=6),1,0) -> 0 | V33: =IF(AND(M33="纳入",IFERROR(VALUE(D33),0)=3),1,0) -> 0 | W33: =IF(AND(M33="纳入",ISNUMBER(T33),T33=1),1,0) -> 0 | X33: =IF(AND(M33="纳入",ISNUMBER(T33),T33=0),1,0) -> 0 | Y33: =IF(AND(M33="纳入",ISNUMBER(T33)),1,0) -> 0 | Z33: =IF(M33<>"纳入","",IF(VALUE(E33)=6,"",IF(VALUE(E33)=3,0.5,IF(OR(AND(VALUE(E33)<3,P33=R33),AND(VALUE(E33)>3,Q33=R33)),1,0)))) | AA33: =IF(M33<>"纳入","",IF(VALUE(F33)=6,"",IF(VALUE(F33)=3,0.5,IF(OR(AND(VALUE(F33)<3,P33=R33),AND(VALUE(F33)>3,Q33=R33)),1,0)))) | AB33: =IF(M33<>"纳入","",IF(VALUE(G33)=6,"",IF(VALUE(G33)=3,0.5,IF(OR(AND(VALUE(G33)<3,P33=R33),AND(VALUE(G33)>3,Q33=R33)),1,0)))) | AC33: =IF(M33<>"纳入","",IF(VALUE(H33)=6,"",IF(VALUE(H33)=3,0.5,IF(OR(AND(VALUE(H33)<3,P33=R33),AND(VALUE(H33)>3,Q33=R33)),1,0)))) | AD33: =IF(M33<>"纳入","",IF(VALUE(I33)=6,"",IF(VALUE(I33)=3,0.5,IF(OR(AND(VALUE(I33)<3,P33=R33),AND(VALUE(I33)>3,Q33=R33)),1,0))))
A34: Q05 | B34: 4 | C34: A 11 / B 12 / 评分 13 | L34: =SUM(IFERROR(IF(AND(VALUE(D34)>=1,VALUE(D34)<=6,MOD(VALUE(D34),1)=0),1,0),0),IFERROR(IF(AND(VALUE(E34)>=1,VALUE(E34)<=6,MOD(VALUE(E34),1)=0),1,0),0),IFERROR(IF(AND(VALUE(F34)>=1,VALUE(F34)<=6,MOD(VALUE(F34),1)=0),1,0),0),IFERROR(IF(AND(VALUE(G34)>=1,VALUE(G34)<=6,MOD(VALUE(G34),1)=0),1,0),0),IFERROR(IF(AND(VALUE(H34)>=1,VALUE(H34)<=6,MOD(VALUE(H34),1)=0),1,0),0),IFERROR(IF(AND(VALUE(I34)>=1,VALUE(I34)<=6,MOD(VALUE(I34),1)=0),1,0),0)) -> 0 | M34: ='参与者登记'!K11 -> 待回收 | N34: 模型 | O34: lwb_hidden_v2_02 | P34: Gemini 3.1 Pro Preview | Q34: Gemini 3.1 Flash Lite | R34: Gemini 3.1 Flash Lite | S34: Gemini 3.1 Pro Preview | T34: =IF(M34<>"纳入","",IF(VALUE(D34)=6,"",IF(VALUE(D34)=3,0.5,IF(OR(AND(VALUE(D34)<3,P34=R34),AND(VALUE(D34)>3,Q34=R34)),1,0)))) | U34: =IF(AND(M34="纳入",IFERROR(VALUE(D34),0)=6),1,0) -> 0 | V34: =IF(AND(M34="纳入",IFERROR(VALUE(D34),0)=3),1,0) -> 0 | W34: =IF(AND(M34="纳入",ISNUMBER(T34),T34=1),1,0) -> 0 | X34: =IF(AND(M34="纳入",ISNUMBER(T34),T34=0),1,0) -> 0 | Y34: =IF(AND(M34="纳入",ISNUMBER(T34)),1,0) -> 0 | Z34: =IF(M34<>"纳入","",IF(VALUE(E34)=6,"",IF(VALUE(E34)=3,0.5,IF(OR(AND(VALUE(E34)<3,P34=R34),AND(VALUE(E34)>3,Q34=R34)),1,0)))) | AA34: =IF(M34<>"纳入","",IF(VALUE(F34)=6,"",IF(VALUE(F34)=3,0.5,IF(OR(AND(VALUE(F34)<3,P34=R34),AND(VALUE(F34)>3,Q34=R34)),1,0)))) | AB34: =IF(M34<>"纳入","",IF(VALUE(G34)=6,"",IF(VALUE(G34)=3,0.5,IF(OR(AND(VALUE(G34)<3,P34=R34),AND(VALUE(G34)>3,Q34=R34)),1,0)))) | AC34: =IF(M34<>"纳入","",IF(VALUE(H34)=6,"",IF(VALUE(H34)=3,0.5,IF(OR(AND(VALUE(H34)<3,P34=R34),AND(VALUE(H34)>3,Q34=R34)),1,0)))) | AD34: =IF(M34<>"纳入","",IF(VALUE(I34)=6,"",IF(VALUE(I34)=3,0.5,IF(OR(AND(VALUE(I34)<3,P34=R34),AND(VALUE(I34)>3,Q34=R34)),1,0))))
A35: Q05 | B35: 5 | C35: A 14 / B 15 / 评分 16 | L35: =SUM(IFERROR(IF(AND(VALUE(D35)>=1,VALUE(D35)<=6,MOD(VALUE(D35),1)=0),1,0),0),IFERROR(IF(AND(VALUE(E35)>=1,VALUE(E35)<=6,MOD(VALUE(E35),1)=0),1,0),0),IFERROR(IF(AND(VALUE(F35)>=1,VALUE(F35)<=6,MOD(VALUE(F35),1)=0),1,0),0),IFERROR(IF(AND(VALUE(G35)>=1,VALUE(G35)<=6,MOD(VALUE(G35),1)=0),1,0),0),IFERROR(IF(AND(VALUE(H35)>=1,VALUE(H35)<=6,MOD(VALUE(H35),1)=0),1,0),0),IFERROR(IF(AND(VALUE(I35)>=1,VALUE(I35)<=6,MOD(VALUE(I35),1)=0),1,0),0)) -> 0 | M35: ='参与者登记'!K11 -> 待回收 | N35: 架构 | O35: archive_of_borrowed_gravity | P35: 完整 Agora | Q35: 单次生成基线 | R35: 完整 Agora | S35: 单次生成基线 | T35: =IF(M35<>"纳入","",IF(VALUE(D35)=6,"",IF(VALUE(D35)=3,0.5,IF(OR(AND(VALUE(D35)<3,P35=R35),AND(VALUE(D35)>3,Q35=R35)),1,0)))) | U35: =IF(AND(M35="纳入",IFERROR(VALUE(D35),0)=6),1,0) -> 0 | V35: =IF(AND(M35="纳入",IFERROR(VALUE(D35),0)=3),1,0) -> 0 | W35: =IF(AND(M35="纳入",ISNUMBER(T35),T35=1),1,0) -> 0 | X35: =IF(AND(M35="纳入",ISNUMBER(T35),T35=0),1,0) -> 0 | Y35: =IF(AND(M35="纳入",ISNUMBER(T35)),1,0) -> 0 | Z35: =IF(M35<>"纳入","",IF(VALUE(E35)=6,"",IF(VALUE(E35)=3,0.5,IF(OR(AND(VALUE(E35)<3,P35=R35),AND(VALUE(E35)>3,Q35=R35)),1,0)))) | AA35: =IF(M35<>"纳入","",IF(VALUE(F35)=6,"",IF(VALUE(F35)=3,0.5,IF(OR(AND(VALUE(F35)<3,P35=R35),AND(VALUE(F35)>3,Q35=R35)),1,0)))) | AB35: =IF(M35<>"纳入","",IF(VALUE(G35)=6,"",IF(VALUE(G35)=3,0.5,IF(OR(AND(VALUE(G35)<3,P35=R35),AND(VALUE(G35)>3,Q35=R35)),1,0)))) | AC35: =IF(M35<>"纳入","",IF(VALUE(H35)=6,"",IF(VALUE(H35)=3,0.5,IF(OR(AND(VALUE(H35)<3,P35=R35),AND(VALUE(H35)>3,Q35=R35)),1,0)))) | AD35: =IF(M35<>"纳入","",IF(VALUE(I35)=6,"",IF(VALUE(I35)=3,0.5,IF(OR(AND(VALUE(I35)<3,P35=R35),AND(VALUE(I35)>3,Q35=R35)),1,0))))
A36: Q05 | B36: 6 | C36: A 17 / B 18 / 评分 19 | L36: =SUM(IFERROR(IF(AND(VALUE(D36)>=1,VALUE(D36)<=6,MOD(VALUE(D36),1)=0),1,0),0),IFERROR(IF(AND(VALUE(E36)>=1,VALUE(E36)<=6,MOD(VALUE(E36),1)=0),1,0),0),IFERROR(IF(AND(VALUE(F36)>=1,VALUE(F36)<=6,MOD(VALUE(F36),1)=0),1,0),0),IFERROR(IF(AND(VALUE(G36)>=1,VALUE(G36)<=6,MOD(VALUE(G36),1)=0),1,0),0),IFERROR(IF(AND(VALUE(H36)>=1,VALUE(H36)<=6,MOD(VALUE(H36),1)=0),1,0),0),IFERROR(IF(AND(VALUE(I36)>=1,VALUE(I36)<=6,MOD(VALUE(I36),1)=0),1,0),0)) -> 0 | M36: ='参与者登记'!K11 -> 待回收 | N36: 模型 | O36: lwb_hidden_v2_03 | P36: GPT-5.6 Sol | Q36: Gemini 3.7 Flash | R36: Gemini 3.7 Flash | S36: GPT-5.6 Sol | T36: =IF(M36<>"纳入","",IF(VALUE(D36)=6,"",IF(VALUE(D36)=3,0.5,IF(OR(AND(VALUE(D36)<3,P36=R36),AND(VALUE(D36)>3,Q36=R36)),1,0)))) | U36: =IF(AND(M36="纳入",IFERROR(VALUE(D36),0)=6),1,0) -> 0 | V36: =IF(AND(M36="纳入",IFERROR(VALUE(D36),0)=3),1,0) -> 0 | W36: =IF(AND(M36="纳入",ISNUMBER(T36),T36=1),1,0) -> 0 | X36: =IF(AND(M36="纳入",ISNUMBER(T36),T36=0),1,0) -> 0 | Y36: =IF(AND(M36="纳入",ISNUMBER(T36)),1,0) -> 0 | Z36: =IF(M36<>"纳入","",IF(VALUE(E36)=6,"",IF(VALUE(E36)=3,0.5,IF(OR(AND(VALUE(E36)<3,P36=R36),AND(VALUE(E36)>3,Q36=R36)),1,0)))) | AA36: =IF(M36<>"纳入","",IF(VALUE(F36)=6,"",IF(VALUE(F36)=3,0.5,IF(OR(AND(VALUE(F36)<3,P36=R36),AND(VALUE(F36)>3,Q36=R36)),1,0)))) | AB36: =IF(M36<>"纳入","",IF(VALUE(G36)=6,"",IF(VALUE(G36)=3,0.5,IF(OR(AND(VALUE(G36)<3,P36=R36),AND(VALUE(G36)>3,Q36=R36)),1,0)))) | AC36: =IF(M36<>"纳入","",IF(VALUE(H36)=6,"",IF(VALUE(H36)=3,0.5,IF(OR(AND(VALUE(H36)<3,P36=R36),AND(VALUE(H36)>3,Q36=R36)),1,0)))) | AD36: =IF(M36<>"纳入","",IF(VALUE(I36)=6,"",IF(VALUE(I36)=3,0.5,IF(OR(AND(VALUE(I36)<3,P36=R36),AND(VALUE(I36)>3,Q36=R36)),1,0))))
A37: Q06 | B37: 1 | C37: A 2 / B 3 / 评分 4 | L37: =SUM(IFERROR(IF(AND(VALUE(D37)>=1,VALUE(D37)<=6,MOD(VALUE(D37),1)=0),1,0),0),IFERROR(IF(AND(VALUE(E37)>=1,VALUE(E37)<=6,MOD(VALUE(E37),1)=0),1,0),0),IFERROR(IF(AND(VALUE(F37)>=1,VALUE(F37)<=6,MOD(VALUE(F37),1)=0),1,0),0),IFERROR(IF(AND(VALUE(G37)>=1,VALUE(G37)<=6,MOD(VALUE(G37),1)=0),1,0),0),IFERROR(IF(AND(VALUE(H37)>=1,VALUE(H37)<=6,MOD(VALUE(H37),1)=0),1,0),0),IFERROR(IF(AND(VALUE(I37)>=1,VALUE(I37)<=6,MOD(VALUE(I37),1)=0),1,0),0)) -> 0 | M37: ='参与者登记'!K12 -> 待回收 | N37: 架构 | O37: archive_of_borrowed_gravity | P37: 单次生成基线 | Q37: 完整 Agora | R37: 完整 Agora | S37: 单次生成基线 | T37: =IF(M37<>"纳入","",IF(VALUE(D37)=6,"",IF(VALUE(D37)=3,0.5,IF(OR(AND(VALUE(D37)<3,P37=R37),AND(VALUE(D37)>3,Q37=R37)),1,0)))) | U37: =IF(AND(M37="纳入",IFERROR(VALUE(D37),0)=6),1,0) -> 0 | V37: =IF(AND(M37="纳入",IFERROR(VALUE(D37),0)=3),1,0) -> 0 | W37: =IF(AND(M37="纳入",ISNUMBER(T37),T37=1),1,0) -> 0 | X37: =IF(AND(M37="纳入",ISNUMBER(T37),T37=0),1,0) -> 0 | Y37: =IF(AND(M37="纳入",ISNUMBER(T37)),1,0) -> 0 | Z37: =IF(M37<>"纳入","",IF(VALUE(E37)=6,"",IF(VALUE(E37)=3,0.5,IF(OR(AND(VALUE(E37)<3,P37=R37),AND(VALUE(E37)>3,Q37=R37)),1,0)))) | AA37: =IF(M37<>"纳入","",IF(VALUE(F37)=6,"",IF(VALUE(F37)=3,0.5,IF(OR(AND(VALUE(F37)<3,P37=R37),AND(VALUE(F37)>3,Q37=R37)),1,0)))) | AB37: =IF(M37<>"纳入","",IF(VALUE(G37)=6,"",IF(VALUE(G37)=3,0.5,IF(OR(AND(VALUE(G37)<3,P37=R37),AND(VALUE(G37)>3,Q37=R37)),1,0)))) | AC37: =IF(M37<>"纳入","",IF(VALUE(H37)=6,"",IF(VALUE(H37)=3,0.5,IF(OR(AND(VALUE(H37)<3,P37=R37),AND(VALUE(H37)>3,Q37=R37)),1,0)))) | AD37: =IF(M37<>"纳入","",IF(VALUE(I37)=6,"",IF(VALUE(I37)=3,0.5,IF(OR(AND(VALUE(I37)<3,P37=R37),AND(VALUE(I37)>3,Q37=R37)),1,0))))
A38: Q06 | B38: 2 | C38: A 5 / B 6 / 评分 7 | L38: =SUM(IFERROR(IF(AND(VALUE(D38)>=1,VALUE(D38)<=6,MOD(VALUE(D38),1)=0),1,0),0),IFERROR(IF(AND(VALUE(E38)>=1,VALUE(E38)<=6,MOD(VALUE(E38),1)=0),1,0),0),IFERROR(IF(AND(VALUE(F38)>=1,VALUE(F38)<=6,MOD(VALUE(F38),1)=0),1,0),0),IFERROR(IF(AND(VALUE(G38)>=1,VALUE(G38)<=6,MOD(VALUE(G38),1)=0),1,0),0),IFERROR(IF(AND(VALUE(H38)>=1,VALUE(H38)<=6,MOD(VALUE(H38),1)=0),1,0),0),IFERROR(IF(AND(VALUE(I38)>=1,VALUE(I38)<=6,MOD(VALUE(I38),1)=0),1,0),0)) -> 0 | M38: ='参与者登记'!K12 -> 待回收 | N38: 模型 | O38: lwb_hidden_v2_01 | P38: Gemini 3.1 Flash Lite | Q38: Gemini 3.5 Flash Lite | R38: Gemini 3.1 Flash Lite | S38: Gemini 3.5 Flash Lite | T38: =IF(M38<>"纳入","",IF(VALUE(D38)=6,"",IF(VALUE(D38)=3,0.5,IF(OR(AND(VALUE(D38)<3,P38=R38),AND(VALUE(D38)>3,Q38=R38)),1,0)))) | U38: =IF(AND(M38="纳入",IFERROR(VALUE(D38),0)=6),1,0) -> 0 | V38: =IF(AND(M38="纳入",IFERROR(VALUE(D38),0)=3),1,0) -> 0 | W38: =IF(AND(M38="纳入",ISNUMBER(T38),T38=1),1,0) -> 0 | X38: =IF(AND(M38="纳入",ISNUMBER(T38),T38=0),1,0) -> 0 | Y38: =IF(AND(M38="纳入",ISNUMBER(T38)),1,0) -> 0 | Z38: =IF(M38<>"纳入","",IF(VALUE(E38)=6,"",IF(VALUE(E38)=3,0.5,IF(OR(AND(VALUE(E38)<3,P38=R38),AND(VALUE(E38)>3,Q38=R38)),1,0)))) | AA38: =IF(M38<>"纳入","",IF(VALUE(F38)=6,"",IF(VALUE(F38)=3,0.5,IF(OR(AND(VALUE(F38)<3,P38=R38),AND(VALUE(F38)>3,Q38=R38)),1,0)))) | AB38: =IF(M38<>"纳入","",IF(VALUE(G38)=6,"",IF(VALUE(G38)=3,0.5,IF(OR(AND(VALUE(G38)<3,P38=R38),AND(VALUE(G38)>3,Q38=R38)),1,0)))) | AC38: =IF(M38<>"纳入","",IF(VALUE(H38)=6,"",IF(VALUE(H38)=3,0.5,IF(OR(AND(VALUE(H38)<3,P38=R38),AND(VALUE(H38)>3,Q38=R38)),1,0)))) | AD38: =IF(M38<>"纳入","",IF(VALUE(I38)=6,"",IF(VALUE(I38)=3,0.5,IF(OR(AND(VALUE(I38)<3,P38=R38),AND(VALUE(I38)>3,Q38=R38)),1,0))))
