Workbook

Sheet Start here
B2: Visual survey | Completed results
B6: 1. Send one packet | C6: Give V01-V11 to 11 different adults. Send each person only their own fillable PDF or Word file. Do not distribute this workbook: it contains identities.
B7: 2. Register returns | C7: Fill the blue cells on Participants from the actual cover-page answers. No names or contact details are needed.
B8: 3. Enter 18 choices | C8: On Responses, enter A, B, Same, or Not sure for each of the three questions in each round. Round and PDF page are already fixed.
B9: What Q1-Q3 mean | C9: Images: Q1 explore preference, Q2 map readability, Q3 character-world fit. Structure: Q1 explore preference, Q2 world clarity, Q3 place-scene fit. Results stay separate.
B10: Automatic inclusion | C10: Returned + adult + English + consent must be Yes, prior exposure must be No, and all 18 choices must be valid. The status shows missing or excluded packets.
B11: Automatic decoding | C11: The workbook knows what A/B means on each page. Preference for Source 1 = 1; Same = 0.5; Source 2 = 0. Not sure is missing preference, counted separately.
B12: What is covered | C12: Images: 7 models on one shared scene, 21 pairs, 44 ratings; each pair has 2 or 4 raters. Structure: 10 matched requests, 22 ratings, each pair has 2 or 4 raters.
B13: What the pictures show | C13: Archived maps and the first two requested character samples. Structure diagrams show authored places, assigned residents and props; they are not walking maps. No baseline artwork has been invented.
B14: Interpretation | C14: Eleven people provide exploratory judgments on these fixed artifacts. Do not call this a stable model ranking. Structure comparisons use the recorded unequal generation budgets.
B15: Reading the summaries | C15: Image results show each exact model pair and each question. Structure results also show an equal-request mean only when all 10 requests have judgeable votes. No p-values or Elo are produced.
B16: Keep versions separate | C16: This is the English visual V01-V11 version. Do not mix it with the rejected text-only Q01-Q11 survey or the earlier HTML S/P codes.
B17: Saving | C17: Only blue cells are editable; protection prevents mistakes, not disclosure. Save your completed workbook outside the public release folder. This copy contains actual returned choices; the original blank template is retained separately.
B19: 11 returns; 10 included. V04 cover blank: pending confirmation, not imputed.

Sheet Participants
A1: Participants | V01-V11
A2: Copy the cover-page choices into blue cells. A missing response is not a No. Every code is used by one person only.
A6: Code | B6: Returned | C6: Adult | D6: English | E6: Consent | F6: Prior exposure | G6: Valid choices / 18 | H6: Analysis status
A7: V01 | B7: Yes | C7: Yes | D7: Yes | E7: Yes | F7: No | G7: =SUM(Responses!H7:H12) -> 18 | H7: =IF(B7<>"Yes","Not returned",IF(OR(C7="No",D7="No",E7="No"),"Exclude: eligibility/consent",IF(OR(C7<>"Yes",D7<>"Yes",E7<>"Yes",F7=""),"Check cover answers",IF(F7<>"No","Exclude: prior exposure",IF(G7<>18,"Incomplete choices","Include"))))) -> Include
A8: V02 | B8: Yes | C8: Yes | D8: Yes | E8: Yes | F8: No | G8: =SUM(Responses!H13:H18) -> 18 | H8: =IF(B8<>"Yes","Not returned",IF(OR(C8="No",D8="No",E8="No"),"Exclude: eligibility/consent",IF(OR(C8<>"Yes",D8<>"Yes",E8<>"Yes",F8=""),"Check cover answers",IF(F8<>"No","Exclude: prior exposure",IF(G8<>18,"Incomplete choices","Include"))))) -> Include
A9: V03 | B9: Yes | C9: Yes | D9: Yes | E9: Yes | F9: No | G9: =SUM(Responses!H19:H24) -> 18 | H9: =IF(B9<>"Yes","Not returned",IF(OR(C9="No",D9="No",E9="No"),"Exclude: eligibility/consent",IF(OR(C9<>"Yes",D9<>"Yes",E9<>"Yes",F9=""),"Check cover answers",IF(F9<>"No","Exclude: prior exposure",IF(G9<>18,"Incomplete choices","Include"))))) -> Include
A10: V04 | B10: Yes | G10: =SUM(Responses!H25:H30) -> 18 | H10: =IF(B10<>"Yes","Not returned",IF(OR(C10="No",D10="No",E10="No"),"Exclude: eligibility/consent",IF(OR(C10<>"Yes",D10<>"Yes",E10<>"Yes",F10=""),"Check cover answers",IF(F10<>"No","Exclude: prior exposure",IF(G10<>18,"Incomplete choices","Include"))))) -> Check cover answers
A11: V05 | B11: Yes | C11: Yes | D11: Yes | E11: Yes | F11: No | G11: =SUM(Responses!H31:H36) -> 18 | H11: =IF(B11<>"Yes","Not returned",IF(OR(C11="No",D11="No",E11="No"),"Exclude: eligibility/consent",IF(OR(C11<>"Yes",D11<>"Yes",E11<>"Yes",F11=""),"Check cover answers",IF(F11<>"No","Exclude: prior exposure",IF(G11<>18,"Incomplete choices","Include"))))) -> Include
A12: V06 | B12: Yes | C12: Yes | D12: Yes | E12: Yes | F12: No | G12: =SUM(Responses!H37:H42) -> 18 | H12: =IF(B12<>"Yes","Not returned",IF(OR(C12="No",D12="No",E12="No"),"Exclude: eligibility/consent",IF(OR(C12<>"Yes",D12<>"Yes",E12<>"Yes",F12=""),"Check cover answers",IF(F12<>"No","Exclude: prior exposure",IF(G12<>18,"Incomplete choices","Include"))))) -> Include
A13: V07 | B13: Yes | C13: Yes | D13: Yes | E13: Yes | F13: No | G13: =SUM(Responses!H43:H48) -> 18 | H13: =IF(B13<>"Yes","Not returned",IF(OR(C13="No",D13="No",E13="No"),"Exclude: eligibility/consent",IF(OR(C13<>"Yes",D13<>"Yes",E13<>"Yes",F13=""),"Check cover answers",IF(F13<>"No","Exclude: prior exposure",IF(G13<>18,"Incomplete choices","Include"))))) -> Include
A14: V08 | B14: Yes | C14: Yes | D14: Yes | E14: Yes | F14: No | G14: =SUM(Responses!H49:H54) -> 18 | H14: =IF(B14<>"Yes","Not returned",IF(OR(C14="No",D14="No",E14="No"),"Exclude: eligibility/consent",IF(OR(C14<>"Yes",D14<>"Yes",E14<>"Yes",F14=""),"Check cover answers",IF(F14<>"No","Exclude: prior exposure",IF(G14<>18,"Incomplete choices","Include"))))) -> Include
A15: V09 | B15: Yes | C15: Yes | D15: Yes | E15: Yes | F15: No | G15: =SUM(Responses!H55:H60) -> 18 | H15: =IF(B15<>"Yes","Not returned",IF(OR(C15="No",D15="No",E15="No"),"Exclude: eligibility/consent",IF(OR(C15<>"Yes",D15<>"Yes",E15<>"Yes",F15=""),"Check cover answers",IF(F15<>"No","Exclude: prior exposure",IF(G15<>18,"Incomplete choices","Include"))))) -> Include
A16: V10 | B16: Yes | C16: Yes | D16: Yes | E16: Yes | F16: No | G16: =SUM(Responses!H61:H66) -> 18 | H16: =IF(B16<>"Yes","Not returned",IF(OR(C16="No",D16="No",E16="No"),"Exclude: eligibility/consent",IF(OR(C16<>"Yes",D16<>"Yes",E16<>"Yes",F16=""),"Check cover answers",IF(F16<>"No","Exclude: prior exposure",IF(G16<>18,"Incomplete choices","Include"))))) -> Include
A17: V11 | B17: Yes | C17: Yes | D17: Yes | E17: Yes | F17: No | G17: =SUM(Responses!H67:H72) -> 18 | H17: =IF(B17<>"Yes","Not returned",IF(OR(C17="No",D17="No",E17="No"),"Exclude: eligibility/consent",IF(OR(C17<>"Yes",D17<>"Yes",E17<>"Yes",F17=""),"Check cover answers",IF(F17<>"No","Exclude: prior exposure",IF(G17<>18,"Incomplete choices","Include"))))) -> Include

Sheet Responses
A1: Responses | Copy choices, no numerical codes
A2: Q1: explore preference. Images Q2/Q3: map readability / character-world fit. Structure Q2/Q3: world clarity / place-scene fit. Use A, B, Same, or Not sure. Empty cells are unentered.
A6: Code | B6: Round | C6: PDF page | D6: Page type | E6: Q1: Explore | F6: Q2: Clarity | G6: Q3: Fit | H6: Valid / 3 | I6: Analysis status | J6: Kind | K6: Pair | L6: A identity | M6: B identity | N6: Source 1 | O6: Source 2 | P6: Q1 score | Q6: Q2 score | R6: Q3 score
A7: V01 | B7: 1 | C7: 2 | D7: Images | E7: A | F7: A | G7: Not sure | H7: =SUM(COUNTIF(E7:G7,"A"),COUNTIF(E7:G7,"B"),COUNTIF(E7:G7,"Same"),COUNTIF(E7:G7,"Not sure")) -> 3 | I7: =Participants!H7 -> Include | J7: images | K7: pqpfxmjtr95 | L7: Gemini 2.5 Flash | M7: Gemini 3.1 Flash Lite | N7: Gemini 2.5 Flash | O7: Gemini 3.1 Flash Lite | P7: =IF(I7<>"Include","",IF(E7="Not sure","",IF(E7="Same",0.5,IF(OR(AND(E7="A",L7=N7),AND(E7="B",M7=N7)),1,0)))) -> 1 | Q7: =IF(I7<>"Include","",IF(F7="Not sure","",IF(F7="Same",0.5,IF(OR(AND(F7="A",L7=N7),AND(F7="B",M7=N7)),1,0)))) -> 1 | R7: =IF(I7<>"Include","",IF(G7="Not sure","",IF(G7="Same",0.5,IF(OR(AND(G7="A",L7=N7),AND(G7="B",M7=N7)),1,0))))
A8: V01 | B8: 2 | C8: 3 | D8: Images | E8: B | F8: B | G8: A | H8: =SUM(COUNTIF(E8:G8,"A"),COUNTIF(E8:G8,"B"),COUNTIF(E8:G8,"Same"),COUNTIF(E8:G8,"Not sure")) -> 3 | I8: =Participants!H7 -> Include | J8: images | K8: pve74cbss7m | L8: GPT-5.6 Sol | M8: GPT-5.6 Terra | N8: GPT-5.6 Sol | O8: GPT-5.6 Terra | P8: =IF(I8<>"Include","",IF(E8="Not sure","",IF(E8="Same",0.5,IF(OR(AND(E8="A",L8=N8),AND(E8="B",M8=N8)),1,0)))) -> 0 | Q8: =IF(I8<>"Include","",IF(F8="Not sure","",IF(F8="Same",0.5,IF(OR(AND(F8="A",L8=N8),AND(F8="B",M8=N8)),1,0)))) -> 0 | R8: =IF(I8<>"Include","",IF(G8="Not sure","",IF(G8="Same",0.5,IF(OR(AND(G8="A",L8=N8),AND(G8="B",M8=N8)),1,0)))) -> 1
A9: V01 | B9: 3 | C9: 4 | D9: Structure | E9: B | F9: A | G9: Not sure | H9: =SUM(COUNTIF(E9:G9,"A"),COUNTIF(E9:G9,"B"),COUNTIF(E9:G9,"Same"),COUNTIF(E9:G9,"Not sure")) -> 3 | I9: =Participants!H7 -> Include | J9: structure | K9: pba8emhpy3a | L9: Single-pass baseline | M9: Full Agora | N9: Full Agora | O9: Single-pass baseline | P9: =IF(I9<>"Include","",IF(E9="Not sure","",IF(E9="Same",0.5,IF(OR(AND(E9="A",L9=N9),AND(E9="B",M9=N9)),1,0)))) -> 1 | Q9: =IF(I9<>"Include","",IF(F9="Not sure","",IF(F9="Same",0.5,IF(OR(AND(F9="A",L9=N9),AND(F9="B",M9=N9)),1,0)))) -> 0 | R9: =IF(I9<>"Include","",IF(G9="Not sure","",IF(G9="Same",0.5,IF(OR(AND(G9="A",L9=N9),AND(G9="B",M9=N9)),1,0))))
A10: V01 | B10: 4 | C10: 5 | D10: Images | E10: B | F10: A | G10: B | H10: =SUM(COUNTIF(E10:G10,"A"),COUNTIF(E10:G10,"B"),COUNTIF(E10:G10,"Same"),COUNTIF(E10:G10,"Not sure")) -> 3 | I10: =Participants!H7 -> Include | J10: images | K10: pkmwb7u7g3n | L10: Gemini 2.5 Flash | M10: GPT-5.6 Sol | N10: Gemini 2.5 Flash | O10: GPT-5.6 Sol | P10: =IF(I10<>"Include","",IF(E10="Not sure","",IF(E10="Same",0.5,IF(OR(AND(E10="A",L10=N10),AND(E10="B",M10=N10)),1,0)))) -> 0 | Q10: =IF(I10<>"Include","",IF(F10="Not sure","",IF(F10="Same",0.5,IF(OR(AND(F10="A",L10=N10),AND(F10="B",M10=N10)),1,0)))) -> 1 | R10: =IF(I10<>"Include","",IF(G10="Not sure","",IF(G10="Same",0.5,IF(OR(AND(G10="A",L10=N10),AND(G10="B",M10=N10)),1,0)))) -> 0
A11: V01 | B11: 5 | C11: 6 | D11: Images | E11: A | F11: A | G11: Not sure | H11: =SUM(COUNTIF(E11:G11,"A"),COUNTIF(E11:G11,"B"),COUNTIF(E11:G11,"Same"),COUNTIF(E11:G11,"Not sure")) -> 3 | I11: =Participants!H7 -> Include | J11: images | K11: pqz6par2vck | L11: GPT-5.6 Terra | M11: Gemini 3.1 Pro Preview | N11: Gemini 3.1 Pro Preview | O11: GPT-5.6 Terra | P11: =IF(I11<>"Include","",IF(E11="Not sure","",IF(E11="Same",0.5,IF(OR(AND(E11="A",L11=N11),AND(E11="B",M11=N11)),1,0)))) -> 0 | Q11: =IF(I11<>"Include","",IF(F11="Not sure","",IF(F11="Same",0.5,IF(OR(AND(F11="A",L11=N11),AND(F11="B",M11=N11)),1,0)))) -> 0 | R11: =IF(I11<>"Include","",IF(G11="Not sure","",IF(G11="Same",0.5,IF(OR(AND(G11="A",L11=N11),AND(G11="B",M11=N11)),1,0))))
A12: V01 | B12: 6 | C12: 7 | D12: Structure | E12: A | F12: A | G12: A | H12: =SUM(COUNTIF(E12:G12,"A"),COUNTIF(E12:G12,"B"),COUNTIF(E12:G12,"Same"),COUNTIF(E12:G12,"Not sure")) -> 3 | I12: =Participants!H7 -> Include | J12: structure | K12: pgtsk9rzfxz | L12: Full Agora | M12: Single-pass baseline | N12: Full Agora | O12: Single-pass baseline | P12: =IF(I12<>"Include","",IF(E12="Not sure","",IF(E12="Same",0.5,IF(OR(AND(E12="A",L12=N12),AND(E12="B",M12=N12)),1,0)))) -> 1 | Q12: =IF(I12<>"Include","",IF(F12="Not sure","",IF(F12="Same",0.5,IF(OR(AND(F12="A",L12=N12),AND(F12="B",M12=N12)),1,0)))) -> 1 | R12: =IF(I12<>"Include","",IF(G12="Not sure","",IF(G12="Same",0.5,IF(OR(AND(G12="A",L12=N12),AND(G12="B",M12=N12)),1,0)))) -> 1
A13: V02 | B13: 1 | C13: 2 | D13: Images | E13: B | F13: A | G13: B | H13: =SUM(COUNTIF(E13:G13,"A"),COUNTIF(E13:G13,"B"),COUNTIF(E13:G13,"Same"),COUNTIF(E13:G13,"Not sure")) -> 3 | I13: =Participants!H8 -> Include | J13: images | K13: pb77h495mwy | L13: GPT-5.6 Sol | M13: Gemini 3.5 Flash Lite | N13: Gemini 3.5 Flash Lite | O13: GPT-5.6 Sol | P13: =IF(I13<>"Include","",IF(E13="Not sure","",IF(E13="Same",0.5,IF(OR(AND(E13="A",L13=N13),AND(E13="B",M13=N13)),1,0)))) -> 1 | Q13: =IF(I13<>"Include","",IF(F13="Not sure","",IF(F13="Same",0.5,IF(OR(AND(F13="A",L13=N13),AND(F13="B",M13=N13)),1,0)))) -> 0 | R13: =IF(I13<>"Include","",IF(G13="Not sure","",IF(G13="Same",0.5,IF(OR(AND(G13="A",L13=N13),AND(G13="B",M13=N13)),1,0)))) -> 1
A14: V02 | B14: 2 | C14: 3 | D14: Structure | E14: B | F14: A | G14: A | H14: =SUM(COUNTIF(E14:G14,"A"),COUNTIF(E14:G14,"B"),COUNTIF(E14:G14,"Same"),COUNTIF(E14:G14,"Not sure")) -> 3 | I14: =Participants!H8 -> Include | J14: structure | K14: pm36f3jqvfc | L14: Single-pass baseline | M14: Full Agora | N14: Full Agora | O14: Single-pass baseline | P14: =IF(I14<>"Include","",IF(E14="Not sure","",IF(E14="Same",0.5,IF(OR(AND(E14="A",L14=N14),AND(E14="B",M14=N14)),1,0)))) -> 1 | Q14: =IF(I14<>"Include","",IF(F14="Not sure","",IF(F14="Same",0.5,IF(OR(AND(F14="A",L14=N14),AND(F14="B",M14=N14)),1,0)))) -> 0 | R14: =IF(I14<>"Include","",IF(G14="Not sure","",IF(G14="Same",0.5,IF(OR(AND(G14="A",L14=N14),AND(G14="B",M14=N14)),1,0)))) -> 0
A15: V02 | B15: 3 | C15: 4 | D15: Images | E15: B | F15: A | G15: B | H15: =SUM(COUNTIF(E15:G15,"A"),COUNTIF(E15:G15,"B"),COUNTIF(E15:G15,"Same"),COUNTIF(E15:G15,"Not sure")) -> 3 | I15: =Participants!H8 -> Include | J15: images | K15: pkmwb7u7g3n | L15: GPT-5.6 Sol | M15: Gemini 2.5 Flash | N15: Gemini 2.5 Flash | O15: GPT-5.6 Sol | P15: =IF(I15<>"Include","",IF(E15="Not sure","",IF(E15="Same",0.5,IF(OR(AND(E15="A",L15=N15),AND(E15="B",M15=N15)),1,0)))) -> 1 | Q15: =IF(I15<>"Include","",IF(F15="Not sure","",IF(F15="Same",0.5,IF(OR(AND(F15="A",L15=N15),AND(F15="B",M15=N15)),1,0)))) -> 0 | R15: =IF(I15<>"Include","",IF(G15="Not sure","",IF(G15="Same",0.5,IF(OR(AND(G15="A",L15=N15),AND(G15="B",M15=N15)),1,0)))) -> 1
A16: V02 | B16: 4 | C16: 5 | D16: Images | E16: B | F16: B | G16: B | H16: =SUM(COUNTIF(E16:G16,"A"),COUNTIF(E16:G16,"B"),COUNTIF(E16:G16,"Same"),COUNTIF(E16:G16,"Not sure")) -> 3 | I16: =Participants!H8 -> Include | J16: images | K16: pve74cbss7m | L16: GPT-5.6 Terra | M16: GPT-5.6 Sol | N16: GPT-5.6 Sol | O16: GPT-5.6 Terra | P16: =IF(I16<>"Include","",IF(E16="Not sure","",IF(E16="Same",0.5,IF(OR(AND(E16="A",L16=N16),AND(E16="B",M16=N16)),1,0)))) -> 1 | Q16: =IF(I16<>"Include","",IF(F16="Not sure","",IF(F16="Same",0.5,IF(OR(AND(F16="A",L16=N16),AND(F16="B",M16=N16)),1,0)))) -> 1 | R16: =IF(I16<>"Include","",IF(G16="Not sure","",IF(G16="Same",0.5,IF(OR(AND(G16="A",L16=N16),AND(G16="B",M16=N16)),1,0)))) -> 1
A17: V02 | B17: 5 | C17: 6 | D17: Structure | E17: B | F17: B | G17: B | H17: =SUM(COUNTIF(E17:G17,"A"),COUNTIF(E17:G17,"B"),COUNTIF(E17:G17,"Same"),COUNTIF(E17:G17,"Not sure")) -> 3 | I17: =Participants!H8 -> Include | J17: structure | K17: pshtgk9bhb8 | L17: Full Agora | M17: Single-pass baseline | N17: Full Agora | O17: Single-pass baseline | P17: =IF(I17<>"Include","",IF(E17="Not sure","",IF(E17="Same",0.5,IF(OR(AND(E17="A",L17=N17),AND(E17="B",M17=N17)),1,0)))) -> 0 | Q17: =IF(I17<>"Include","",IF(F17="Not sure","",IF(F17="Same",0.5,IF(OR(AND(F17="A",L17=N17),AND(F17="B",M17=N17)),1,0)))) -> 0 | R17: =IF(I17<>"Include","",IF(G17="Not sure","",IF(G17="Same",0.5,IF(OR(AND(G17="A",L17=N17),AND(G17="B",M17=N17)),1,0)))) -> 0
A18: V02 | B18: 6 | C18: 7 | D18: Images | E18: B | F18: B | G18: B | H18: =SUM(COUNTIF(E18:G18,"A"),COUNTIF(E18:G18,"B"),COUNTIF(E18:G18,"Same"),COUNTIF(E18:G18,"Not sure")) -> 3 | I18: =Participants!H8 -> Include | J18: images | K18: pe5t7ur8bj8 | L18: Gemini 3.5 Flash Lite | M18: Gemini 3.7 Flash | N18: Gemini 3.5 Flash Lite | O18: Gemini 3.7 Flash | P18: =IF(I18<>"Include","",IF(E18="Not sure","",IF(E18="Same",0.5,IF(OR(AND(E18="A",L18=N18),AND(E18="B",M18=N18)),1,0)))) -> 0 | Q18: =IF(I18<>"Include","",IF(F18="Not sure","",IF(F18="Same",0.5,IF(OR(AND(F18="A",L18=N18),AND(F18="B",M18=N18)),1,0)))) -> 0 | R18: =IF(I18<>"Include","",IF(G18="Not sure","",IF(G18="Same",0.5,IF(OR(AND(G18="A",L18=N18),AND(G18="B",M18=N18)),1,0)))) -> 0
A19: V03 | B19: 1 | C19: 2 | D19: Structure | E19: A | F19: B | G19: A | H19: =SUM(COUNTIF(E19:G19,"A"),COUNTIF(E19:G19,"B"),COUNTIF(E19:G19,"Same"),COUNTIF(E19:G19,"Not sure")) -> 3 | I19: =Participants!H9 -> Include | J19: structure | K19: pjr89bu8zuw | L19: Full Agora | M19: Single-pass baseline | N19: Full Agora | O19: Single-pass baseline | P19: =IF(I19<>"Include","",IF(E19="Not sure","",IF(E19="Same",0.5,IF(OR(AND(E19="A",L19=N19),AND(E19="B",M19=N19)),1,0)))) -> 1 | Q19: =IF(I19<>"Include","",IF(F19="Not sure","",IF(F19="Same",0.5,IF(OR(AND(F19="A",L19=N19),AND(F19="B",M19=N19)),1,0)))) -> 0 | R19: =IF(I19<>"Include","",IF(G19="Not sure","",IF(G19="Same",0.5,IF(OR(AND(G19="A",L19=N19),AND(G19="B",M19=N19)),1,0)))) -> 1
A20: V03 | B20: 2 | C20: 3 | D20: Images | E20: A | F20: B | G20: A | H20: =SUM(COUNTIF(E20:G20,"A"),COUNTIF(E20:G20,"B"),COUNTIF(E20:G20,"Same"),COUNTIF(E20:G20,"Not sure")) -> 3 | I20: =Participants!H9 -> Include | J20: images | K20: pb77h495mwy | L20: Gemini 3.5 Flash Lite | M20: GPT-5.6 Sol | N20: Gemini 3.5 Flash Lite | O20: GPT-5.6 Sol | P20: =IF(I20<>"Include","",IF(E20="Not sure","",IF(E20="Same",0.5,IF(OR(AND(E20="A",L20=N20),AND(E20="B",M20=N20)),1,0)))) -> 1 | Q20: =IF(I20<>"Include","",IF(F20="Not sure","",IF(F20="Same",0.5,IF(OR(AND(F20="A",L20=N20),AND(F20="B",M20=N20)),1,0)))) -> 0 | R20: =IF(I20<>"Include","",IF(G20="Not sure","",IF(G20="Same",0.5,IF(OR(AND(G20="A",L20=N20),AND(G20="B",M20=N20)),1,0)))) -> 1
A21: V03 | B21: 3 | C21: 4 | D21: Images | E21: A | F21: B | G21: A | H21: =SUM(COUNTIF(E21:G21,"A"),COUNTIF(E21:G21,"B"),COUNTIF(E21:G21,"Same"),COUNTIF(E21:G21,"Not sure")) -> 3 | I21: =Participants!H9 -> Include | J21: images | K21: p4n4wt973gs | L21: Gemini 2.5 Flash | M21: Gemini 3.1 Pro Preview | N21: Gemini 2.5 Flash | O21: Gemini 3.1 Pro Preview | P21: =IF(I21<>"Include","",IF(E21="Not sure","",IF(E21="Same",0.5,IF(OR(AND(E21="A",L21=N21),AND(E21="B",M21=N21)),1,0)))) -> 1 | Q21: =IF(I21<>"Include","",IF(F21="Not sure","",IF(F21="Same",0.5,IF(OR(AND(F21="A",L21=N21),AND(F21="B",M21=N21)),1,0)))) -> 0 | R21: =IF(I21<>"Include","",IF(G21="Not sure","",IF(G21="Same",0.5,IF(OR(AND(G21="A",L21=N21),AND(G21="B",M21=N21)),1,0)))) -> 1
A22: V03 | B22: 4 | C22: 5 | D22: Structure | E22: A | F22: B | G22: A | H22: =SUM(COUNTIF(E22:G22,"A"),COUNTIF(E22:G22,"B"),COUNTIF(E22:G22,"Same"),COUNTIF(E22:G22,"Not sure")) -> 3 | I22: =Participants!H9 -> Include | J22: structure | K22: p99djg9fns3 | L22: Single-pass baseline | M22: Full Agora | N22: Full Agora | O22: Single-pass baseline | P22: =IF(I22<>"Include","",IF(E22="Not sure","",IF(E22="Same",0.5,IF(OR(AND(E22="A",L22=N22),AND(E22="B",M22=N22)),1,0)))) -> 0 | Q22: =IF(I22<>"Include","",IF(F22="Not sure","",IF(F22="Same",0.5,IF(OR(AND(F22="A",L22=N22),AND(F22="B",M22=N22)),1,0)))) -> 1 | R22: =IF(I22<>"Include","",IF(G22="Not sure","",IF(G22="Same",0.5,IF(OR(AND(G22="A",L22=N22),AND(G22="B",M22=N22)),1,0)))) -> 0
A23: V03 | B23: 5 | C23: 6 | D23: Images | E23: A | F23: B | G23: A | H23: =SUM(COUNTIF(E23:G23,"A"),COUNTIF(E23:G23,"B"),COUNTIF(E23:G23,"Same"),COUNTIF(E23:G23,"Not sure")) -> 3 | I23: =Participants!H9 -> Include | J23: images | K23: pr9q8buqrwe | L23: Gemini 3.1 Flash Lite | M23: GPT-5.6 Sol | N23: Gemini 3.1 Flash Lite | O23: GPT-5.6 Sol | P23: =IF(I23<>"Include","",IF(E23="Not sure","",IF(E23="Same",0.5,IF(OR(AND(E23="A",L23=N23),AND(E23="B",M23=N23)),1,0)))) -> 1 | Q23: =IF(I23<>"Include","",IF(F23="Not sure","",IF(F23="Same",0.5,IF(OR(AND(F23="A",L23=N23),AND(F23="B",M23=N23)),1,0)))) -> 0 | R23: =IF(I23<>"Include","",IF(G23="Not sure","",IF(G23="Same",0.5,IF(OR(AND(G23="A",L23=N23),AND(G23="B",M23=N23)),1,0)))) -> 1
A24: V03 | B24: 6 | C24: 7 | D24: Images | E24: B | F24: A | G24: B | H24: =SUM(COUNTIF(E24:G24,"A"),COUNTIF(E24:G24,"B"),COUNTIF(E24:G24,"Same"),COUNTIF(E24:G24,"Not sure")) -> 3 | I24: =Participants!H9 -> Include | J24: images | K24: pe5t7ur8bj8 | L24: Gemini 3.7 Flash | M24: Gemini 3.5 Flash Lite | N24: Gemini 3.5 Flash Lite | O24: Gemini 3.7 Flash | P24: =IF(I24<>"Include","",IF(E24="Not sure","",IF(E24="Same",0.5,IF(OR(AND(E24="A",L24=N24),AND(E24="B",M24=N24)),1,0)))) -> 1 | Q24: =IF(I24<>"Include","",IF(F24="Not sure","",IF(F24="Same",0.5,IF(OR(AND(F24="A",L24=N24),AND(F24="B",M24=N24)),1,0)))) -> 0 | R24: =IF(I24<>"Include","",IF(G24="Not sure","",IF(G24="Same",0.5,IF(OR(AND(G24="A",L24=N24),AND(G24="B",M24=N24)),1,0)))) -> 1
A25: V04 | B25: 1 | C25: 2 | D25: Images | E25: A | F25: A | G25: A | H25: =SUM(COUNTIF(E25:G25,"A"),COUNTIF(E25:G25,"B"),COUNTIF(E25:G25,"Same"),COUNTIF(E25:G25,"Not sure")) -> 3 | I25: =Participants!H10 -> Check cover answers | J25: images | K25: pyega4erk2n | L25: GPT-5.6 Terra | M25: Gemini 3.1 Flash Lite | N25: Gemini 3.1 Flash Lite | O25: GPT-5.6 Terra | P25: =IF(I25<>"Include","",IF(E25="Not sure","",IF(E25="Same",0.5,IF(OR(AND(E25="A",L25=N25),AND(E25="B",M25=N25)),1,0)))) | Q25: =IF(I25<>"Include","",IF(F25="Not sure","",IF(F25="Same",0.5,IF(OR(AND(F25="A",L25=N25),AND(F25="B",M25=N25)),1,0)))) | R25: =IF(I25<>"Include","",IF(G25="Not sure","",IF(G25="Same",0.5,IF(OR(AND(G25="A",L25=N25),AND(G25="B",M25=N25)),1,0))))
A26: V04 | B26: 2 | C26: 3 | D26: Images | E26: B | F26: A | G26: B | H26: =SUM(COUNTIF(E26:G26,"A"),COUNTIF(E26:G26,"B"),COUNTIF(E26:G26,"Same"),COUNTIF(E26:G26,"Not sure")) -> 3 | I26: =Participants!H10 -> Check cover answers | J26: images | K26: pr9q8buqrwe | L26: GPT-5.6 Sol | M26: Gemini 3.1 Flash Lite | N26: Gemini 3.1 Flash Lite | O26: GPT-5.6 Sol | P26: =IF(I26<>"Include","",IF(E26="Not sure","",IF(E26="Same",0.5,IF(OR(AND(E26="A",L26=N26),AND(E26="B",M26=N26)),1,0)))) | Q26: =IF(I26<>"Include","",IF(F26="Not sure","",IF(F26="Same",0.5,IF(OR(AND(F26="A",L26=N26),AND(F26="B",M26=N26)),1,0)))) | R26: =IF(I26<>"Include","",IF(G26="Not sure","",IF(G26="Same",0.5,IF(OR(AND(G26="A",L26=N26),AND(G26="B",M26=N26)),1,0))))
A27: V04 | B27: 3 | C27: 4 | D27: Structure | E27: Same | F27: Same | G27: B | H27: =SUM(COUNTIF(E27:G27,"A"),COUNTIF(E27:G27,"B"),COUNTIF(E27:G27,"Same"),COUNTIF(E27:G27,"Not sure")) -> 3 | I27: =Participants!H10 -> Check cover answers | J27: structure | K27: pshtgk9bhb8 | L27: Single-pass baseline | M27: Full Agora | N27: Full Agora | O27: Single-pass baseline | P27: =IF(I27<>"Include","",IF(E27="Not sure","",IF(E27="Same",0.5,IF(OR(AND(E27="A",L27=N27),AND(E27="B",M27=N27)),1,0)))) | Q27: =IF(I27<>"Include","",IF(F27="Not sure","",IF(F27="Same",0.5,IF(OR(AND(F27="A",L27=N27),AND(F27="B",M27=N27)),1,0)))) | R27: =IF(I27<>"Include","",IF(G27="Not sure","",IF(G27="Same",0.5,IF(OR(AND(G27="A",L27=N27),AND(G27="B",M27=N27)),1,0))))
A28: V04 | B28: 4 | C28: 5 | D28: Images | E28: B | F28: B | G28: B | H28: =SUM(COUNTIF(E28:G28,"A"),COUNTIF(E28:G28,"B"),COUNTIF(E28:G28,"Same"),COUNTIF(E28:G28,"Not sure")) -> 3 | I28: =Participants!H10 -> Check cover answers | J28: images | K28: p4n4wt973gs | L28: Gemini 3.1 Pro Preview | M28: Gemini 2.5 Flash | N28: Gemini 2.5 Flash | O28: Gemini 3.1 Pro Preview | P28: =IF(I28<>"Include","",IF(E28="Not sure","",IF(E28="Same",0.5,IF(OR(AND(E28="A",L28=N28),AND(E28="B",M28=N28)),1,0)))) | Q28: =IF(I28<>"Include","",IF(F28="Not sure","",IF(F28="Same",0.5,IF(OR(AND(F28="A",L28=N28),AND(F28="B",M28=N28)),1,0)))) | R28: =IF(I28<>"Include","",IF(G28="Not sure","",IF(G28="Same",0.5,IF(OR(AND(G28="A",L28=N28),AND(G28="B",M28=N28)),1,0))))
A29: V04 | B29: 5 | C29: 6 | D29: Images | E29: B | F29: B | G29: B | H29: =SUM(COUNTIF(E29:G29,"A"),COUNTIF(E29:G29,"B"),COUNTIF(E29:G29,"Same"),COUNTIF(E29:G29,"Not sure")) -> 3 | I29: =Participants!H10 -> Check cover answers | J29: images | K29: pfw7kwtz3xz | L29: Gemini 3.7 Flash | M29: Gemini 2.5 Flash | N29: Gemini 2.5 Flash | O29: Gemini 3.7 Flash | P29: =IF(I29<>"Include","",IF(E29="Not sure","",IF(E29="Same",0.5,IF(OR(AND(E29="A",L29=N29),AND(E29="B",M29=N29)),1,0)))) | Q29: =IF(I29<>"Include","",IF(F29="Not sure","",IF(F29="Same",0.5,IF(OR(AND(F29="A",L29=N29),AND(F29="B",M29=N29)),1,0)))) | R29: =IF(I29<>"Include","",IF(G29="Not sure","",IF(G29="Same",0.5,IF(OR(AND(G29="A",L29=N29),AND(G29="B",M29=N29)),1,0))))
A30: V04 | B30: 6 | C30: 7 | D30: Structure | E30: B | F30: A | G30: B | H30: =SUM(COUNTIF(E30:G30,"A"),COUNTIF(E30:G30,"B"),COUNTIF(E30:G30,"Same"),COUNTIF(E30:G30,"Not sure")) -> 3 | I30: =Participants!H10 -> Check cover answers | J30: structure | K30: pm36f3jqvfc | L30: Full Agora | M30: Single-pass baseline | N30: Full Agora | O30: Single-pass baseline | P30: =IF(I30<>"Include","",IF(E30="Not sure","",IF(E30="Same",0.5,IF(OR(AND(E30="A",L30=N30),AND(E30="B",M30=N30)),1,0)))) | Q30: =IF(I30<>"Include","",IF(F30="Not sure","",IF(F30="Same",0.5,IF(OR(AND(F30="A",L30=N30),AND(F30="B",M30=N30)),1,0)))) | R30: =IF(I30<>"Include","",IF(G30="Not sure","",IF(G30="Same",0.5,IF(OR(AND(G30="A",L30=N30),AND(G30="B",M30=N30)),1,0))))
A31: V05 | B31: 1 | C31: 2 | D31: Images | E31: B | F31: Same | G31: A | H31: =SUM(COUNTIF(E31:G31,"A"),COUNTIF(E31:G31,"B"),COUNTIF(E31:G31,"Same"),COUNTIF(E31:G31,"Not sure")) -> 3 | I31: =Participants!H11 -> Include | J31: images | K31: pktk4d47f6b | L31: Gemini 3.1 Flash Lite | M31: Gemini 3.1 Pro Preview | N31: Gemini 3.1 Flash Lite | O31: Gemini 3.1 Pro Preview | P31: =IF(I31<>"Include","",IF(E31="Not sure","",IF(E31="Same",0.5,IF(OR(AND(E31="A",L31=N31),AND(E31="B",M31=N31)),1,0)))) -> 0 | Q31: =IF(I31<>"Include","",IF(F31="Not sure","",IF(F31="Same",0.5,IF(OR(AND(F31="A",L31=N31),AND(F31="B",M31=N31)),1,0)))) -> 0.5 | R31: =IF(I31<>"Include","",IF(G31="Not sure","",IF(G31="Same",0.5,IF(OR(AND(G31="A",L31=N31),AND(G31="B",M31=N31)),1,0)))) -> 1
A32: V05 | B32: 2 | C32: 3 | D32: Structure | E32: B | F32: A | G32: B | H32: =SUM(COUNTIF(E32:G32,"A"),COUNTIF(E32:G32,"B"),COUNTIF(E32:G32,"Same"),COUNTIF(E32:G32,"Not sure")) -> 3 | I32: =Participants!H11 -> Include | J32: structure | K32: p99djg9fns3 | L32: Full Agora | M32: Single-pass baseline | N32: Full Agora | O32: Single-pass baseline | P32: =IF(I32<>"Include","",IF(E32="Not sure","",IF(E32="Same",0.5,IF(OR(AND(E32="A",L32=N32),AND(E32="B",M32=N32)),1,0)))) -> 0 | Q32: =IF(I32<>"Include","",IF(F32="Not sure","",IF(F32="Same",0.5,IF(OR(AND(F32="A",L32=N32),AND(F32="B",M32=N32)),1,0)))) -> 1 | R32: =IF(I32<>"Include","",IF(G32="Not sure","",IF(G32="Same",0.5,IF(OR(AND(G32="A",L32=N32),AND(G32="B",M32=N32)),1,0)))) -> 0
A33: V05 | B33: 3 | C33: 4 | D33: Images | E33: B | F33: B | G33: B | H33: =SUM(COUNTIF(E33:G33,"A"),COUNTIF(E33:G33,"B"),COUNTIF(E33:G33,"Same"),COUNTIF(E33:G33,"Not sure")) -> 3 | I33: =Participants!H11 -> Include | J33: images | K33: pyega4erk2n | L33: Gemini 3.1 Flash Lite | M33: GPT-5.6 Terra | N33: Gemini 3.1 Flash Lite | O33: GPT-5.6 Terra | P33: =IF(I33<>"Include","",IF(E33="Not sure","",IF(E33="Same",0.5,IF(OR(AND(E33="A",L33=N33),AND(E33="B",M33=N33)),1,0)))) -> 0 | Q33: =IF(I33<>"Include","",IF(F33="Not sure","",IF(F33="Same",0.5,IF(OR(AND(F33="A",L33=N33),AND(F33="B",M33=N33)),1,0)))) -> 0 | R33: =IF(I33<>"Include","",IF(G33="Not sure","",IF(G33="Same",0.5,IF(OR(AND(G33="A",L33=N33),AND(G33="B",M33=N33)),1,0)))) -> 0
A34: V05 | B34: 4 | C34: 5 | D34: Images | E34: A | F34: A | G34: A | H34: =SUM(COUNTIF(E34:G34,"A"),COUNTIF(E34:G34,"B"),COUNTIF(E34:G34,"Same"),COUNTIF(E34:G34,"Not sure")) -> 3 | I34: =Participants!H11 -> Include | J34: images | K34: pfw7kwtz3xz | L34: Gemini 2.5 Flash | M34: Gemini 3.7 Flash | N34: Gemini 2.5 Flash | O34: Gemini 3.7 Flash | P34: =IF(I34<>"Include","",IF(E34="Not sure","",IF(E34="Same",0.5,IF(OR(AND(E34="A",L34=N34),AND(E34="B",M34=N34)),1,0)))) -> 1 | Q34: =IF(I34<>"Include","",IF(F34="Not sure","",IF(F34="Same",0.5,IF(OR(AND(F34="A",L34=N34),AND(F34="B",M34=N34)),1,0)))) -> 1 | R34: =IF(I34<>"Include","",IF(G34="Not sure","",IF(G34="Same",0.5,IF(OR(AND(G34="A",L34=N34),AND(G34="B",M34=N34)),1,0)))) -> 1
A35: V05 | B35: 5 | C35: 6 | D35: Structure | E35: B | F35: Same | G35: B | H35: =SUM(COUNTIF(E35:G35,"A"),COUNTIF(E35:G35,"B"),COUNTIF(E35:G35,"Same"),COUNTIF(E35:G35,"Not sure")) -> 3 | I35: =Participants!H11 -> Include | J35: structure | K35: ppr7yrjpvsq | L35: Single-pass baseline | M35: Full Agora | N35: Full Agora | O35: Single-pass baseline | P35: =IF(I35<>"Include","",IF(E35="Not sure","",IF(E35="Same",0.5,IF(OR(AND(E35="A",L35=N35),AND(E35="B",M35=N35)),1,0)))) -> 1 | Q35: =IF(I35<>"Include","",IF(F35="Not sure","",IF(F35="Same",0.5,IF(OR(AND(F35="A",L35=N35),AND(F35="B",M35=N35)),1,0)))) -> 0.5 | R35: =IF(I35<>"Include","",IF(G35="Not sure","",IF(G35="Same",0.5,IF(OR(AND(G35="A",L35=N35),AND(G35="B",M35=N35)),1,0)))) -> 1
A36: V05 | B36: 6 | C36: 7 | D36: Images | E36: B | F36: B | G36: Same | H36: =SUM(COUNTIF(E36:G36,"A"),COUNTIF(E36:G36,"B"),COUNTIF(E36:G36,"Same"),COUNTIF(E36:G36,"Not sure")) -> 3 | I36: =Participants!H11 -> Include | J36: images | K36: pgu22spkfcc | L36: Gemini 3.5 Flash Lite | M36: Gemini 3.1 Pro Preview | N36: Gemini 3.1 Pro Preview | O36: Gemini 3.5 Flash Lite | P36: =IF(I36<>"Include","",IF(E36="Not sure","",IF(E36="Same",0.5,IF(OR(AND(E36="A",L36=N36),AND(E36="B",M36=N36)),1,0)))) -> 1 | Q36: =IF(I36<>"Include","",IF(F36="Not sure","",IF(F36="Same",0.5,IF(OR(AND(F36="A",L36=N36),AND(F36="B",M36=N36)),1,0)))) -> 1 | R36: =IF(I36<>"Include","",IF(G36="Not sure","",IF(G36="Same",0.5,IF(OR(AND(G36="A",L36=N36),AND(G36="B",M36=N36)),1,0)))) -> 0.5
A37: V06 | B37: 1 | C37: 2 | D37: Structure | E37: B | F37: A | G37: B | H37: =SUM(COUNTIF(E37:G37,"A"),COUNTIF(E37:G37,"B"),COUNTIF(E37:G37,"Same"),COUNTIF(E37:G37,"Not sure")) -> 3 | I37: =Participants!H12 -> Include | J37: structure | K37: p99djg9fns3 | L37: Full Agora | M37: Single-pass baseline | N37: Full Agora | O37: Single-pass baseline | P37: =IF(I37<>"Include","",IF(E37="Not sure","",IF(E37="Same",0.5,IF(OR(AND(E37="A",L37=N37),AND(E37="B",M37=N37)),1,0)))) -> 0 | Q37: =IF(I37<>"Include","",IF(F37="Not sure","",IF(F37="Same",0.5,IF(OR(AND(F37="A",L37=N37),AND(F37="B",M37=N37)),1,0)))) -> 1 | R37: =IF(I37<>"Include","",IF(G37="Not sure","",IF(G37="Same",0.5,IF(OR(AND(G37="A",L37=N37),AND(G37="B",M37=N37)),1,0)))) -> 0
A38: V06 | B38: 2 | C38: 3 | D38: Images | E38: B | F38: A | G38: A | H38: =SUM(COUNTIF(E38:G38,"A"),COUNTIF(E38:G38,"B"),COUNTIF(E38:G38,"Same"),COUNTIF(E38:G38,"Not sure")) -> 3 | I38: =Participants!H12 -> Include | J38: images | K38: pgu22spkfcc | L38: Gemini 3.1 Pro Preview | M38: Gemini 3.5 Flash Lite | N38: Gemini 3.1 Pro Preview | O38: Gemini 3.5 Flash Lite | P38: =IF(I38<>"Include","",IF(E38="Not sure","",IF(E38="Same",0.5,IF(OR(AND(E38="A",L38=N38),AND(E38="B",M38=N38)),1,0)))) -> 0 | Q38: =IF(I38<>"Include","",IF(F38="Not sure","",IF(F38="Same",0.5,IF(OR(AND(F38="A",L38=N38),AND(F38="B",M38=N38)),1,0)))) -> 1 | R38: =IF(I38<>"Include","",IF(G38="Not sure","",IF(G38="Same",0.5,IF(OR(AND(G38="A",L38=N38),AND(G38="B",M38=N38)),1,0)))) -> 1
A39: V06 | B39: 3 | C39: 4 | D39: Images | E39: A | F39: B | G39: B | H39: =SUM(COUNTIF(E39:G39,"A"),COUNTIF(E39:G39,"B"),COUNTIF(E39:G39,"Same"),COUNTIF(E39:G39,"Not sure")) -> 3 | I39: =Participants!H12 -> Include | J39: images | K39: pkvc5vp8bjb | L39: Gemini 3.1 Flash Lite | M39: Gemini 3.7 Flash | N39: Gemini 3.1 Flash Lite | O39: Gemini 3.7 Flash | P39: =IF(I39<>"Include","",IF(E39="Not sure","",IF(E39="Same",0.5,IF(OR(AND(E39="A",L39=N39),AND(E39="B",M39=N39)),1,0)))) -> 1 | Q39: =IF(I39<>"Include","",IF(F39="Not sure","",IF(F39="Same",0.5,IF(OR(AND(F39="A",L39=N39),AND(F39="B",M39=N39)),1,0)))) -> 0 | R39: =IF(I39<>"Include","",IF(G39="Not sure","",IF(G39="Same",0.5,IF(OR(AND(G39="A",L39=N39),AND(G39="B",M39=N39)),1,0)))) -> 0
A40: V06 | B40: 4 | C40: 5 | D40: Structure | E40: A | F40: B | G40: B | H40: =SUM(COUNTIF(E40:G40,"A"),COUNTIF(E40:G40,"B"),COUNTIF(E40:G40,"Same"),COUNTIF(E40:G40,"Not sure")) -> 3 | I40: =Participants!H12 -> Include | J40: structure | K40: p268pkt6x9s | L40: Single-pass baseline | M40: Full Agora | N40: Full Agora | O40: Single-pass baseline | P40: =IF(I40<>"Include","",IF(E40="Not sure","",IF(E40="Same",0.5,IF(OR(AND(E40="A",L40=N40),AND(E40="B",M40=N40)),1,0)))) -> 0 | Q40: =IF(I40<>"Include","",IF(F40="Not sure","",IF(F40="Same",0.5,IF(OR(AND(F40="A",L40=N40),AND(F40="B",M40=N40)),1,0)))) -> 1 | R40: =IF(I40<>"Include","",IF(G40="Not sure","",IF(G40="Same",0.5,IF(OR(AND(G40="A",L40=N40),AND(G40="B",M40=N40)),1,0)))) -> 1
A41: V06 | B41: 5 | C41: 6 | D41: Images | E41: B | F41: A | G41: A | H41: =SUM(COUNTIF(E41:G41,"A"),COUNTIF(E41:G41,"B"),COUNTIF(E41:G41,"Same"),COUNTIF(E41:G41,"Not sure")) -> 3 | I41: =Participants!H12 -> Include | J41: images | K41: pktk4d47f6b | L41: Gemini 3.1 Pro Preview | M41: Gemini 3.1 Flash Lite | N41: Gemini 3.1 Flash Lite | O41: Gemini 3.1 Pro Preview | P41: =IF(I41<>"Include","",IF(E41="Not sure","",IF(E41="Same",0.5,IF(OR(AND(E41="A",L41=N41),AND(E41="B",M41=N41)),1,0)))) -> 1 | Q41: =IF(I41<>"Include","",IF(F41="Not sure","",IF(F41="Same",0.5,IF(OR(AND(F41="A",L41=N41),AND(F41="B",M41=N41)),1,0)))) -> 0 | R41: =IF(I41<>"Include","",IF(G41="Not sure","",IF(G41="Same",0.5,IF(OR(AND(G41="A",L41=N41),AND(G41="B",M41=N41)),1,0)))) -> 0
A42: V06 | B42: 6 | C42: 7 | D42: Images | E42: A | F42: B | G42: A | H42: =SUM(COUNTIF(E42:G42,"A"),COUNTIF(E42:G42,"B"),COUNTIF(E42:G42,"Same"),COUNTIF(E42:G42,"Not sure")) -> 3 | I42: =Participants!H12 -> Include | J42: images | K42: pnez9yz55kd | L42: Gemini 3.5 Flash Lite | M42: GPT-5.6 Terra | N42: Gemini 3.5 Flash Lite | O42: GPT-5.6 Terra | P42: =IF(I42<>"Include","",IF(E42="Not sure","",IF(E42="Same",0.5,IF(OR(AND(E42="A",L42=N42),AND(E42="B",M42=N42)),1,0)))) -> 1 | Q42: =IF(I42<>"Include","",IF(F42="Not sure","",IF(F42="Same",0.5,IF(OR(AND(F42="A",L42=N42),AND(F42="B",M42=N42)),1,0)))) -> 0 | R42: =IF(I42<>"Include","",IF(G42="Not sure","",IF(G42="Same",0.5,IF(OR(AND(G42="A",L42=N42),AND(G42="B",M42=N42)),1,0)))) -> 1
A43: V07 | B43: 1 | C43: 2 | D43: Images | E43: B | F43: A | G43: B | H43: =SUM(COUNTIF(E43:G43,"A"),COUNTIF(E43:G43,"B"),COUNTIF(E43:G43,"Same"),COUNTIF(E43:G43,"Not sure")) -> 3 | I43: =Participants!H13 -> Include | J43: images | K43: pkvc5vp8bjb | L43: Gemini 3.7 Flash | M43: Gemini 3.1 Flash Lite | N43: Gemini 3.1 Flash Lite | O43: Gemini 3.7 Flash | P43: =IF(I43<>"Include","",IF(E43="Not sure","",IF(E43="Same",0.5,IF(OR(AND(E43="A",L43=N43),AND(E43="B",M43=N43)),1,0)))) -> 1 | Q43: =IF(I43<>"Include","",IF(F43="Not sure","",IF(F43="Same",0.5,IF(OR(AND(F43="A",L43=N43),AND(F43="B",M43=N43)),1,0)))) -> 0 | R43: =IF(I43<>"Include","",IF(G43="Not sure","",IF(G43="Same",0.5,IF(OR(AND(G43="A",L43=N43),AND(G43="B",M43=N43)),1,0)))) -> 1
...

Sheet Image results
A1: Image results | Source 1 preference
A2: Only included participants are counted. Same is a half vote; Not sure is outside the preference denominator. These are fixed-artifact exploratory judgments, not a general ranking.
A6: Pair / scene | B6: Source 1 | C6: Source 2 | D6: Question | E6: Planned | F6: Included | G6: Judgeable | H6: Source 1 wins | I6: Same | J6: Source 2 wins | K6: Not sure | L6: Source 1 preference
A7: Promise city | B7: Gemini 3.7 Flash | C7: GPT-5.6 Sol | D7: Explore preference | E7: 2 | F7: =IF(Responses!I64="Include",1,0)+IF(Responses!I70="Include",1,0) -> 2 | G7: =IF(ISNUMBER(Responses!P64),1,0)+IF(ISNUMBER(Responses!P70),1,0) -> 2 | H7: =IF(AND(ISNUMBER(Responses!P64),Responses!P64=1),1,0)+IF(AND(ISNUMBER(Responses!P70),Responses!P70=1),1,0) -> 2 | I7: =IF(AND(ISNUMBER(Responses!P64),Responses!P64=0.5),1,0)+IF(AND(ISNUMBER(Responses!P70),Responses!P70=0.5),1,0) -> 0 | J7: =IF(AND(ISNUMBER(Responses!P64),Responses!P64=0),1,0)+IF(AND(ISNUMBER(Responses!P70),Responses!P70=0),1,0) -> 0 | K7: =F7-G7 -> 0 | L7: =IF(G7=0,"",(H7+I7*0.5)/G7) -> 1
A8: Promise city | B8: Gemini 3.7 Flash | C8: GPT-5.6 Sol | D8: Map readability | E8: 2 | F8: =IF(Responses!I64="Include",1,0)+IF(Responses!I70="Include",1,0) -> 2 | G8: =IF(ISNUMBER(Responses!Q64),1,0)+IF(ISNUMBER(Responses!Q70),1,0) -> 2 | H8: =IF(AND(ISNUMBER(Responses!Q64),Responses!Q64=1),1,0)+IF(AND(ISNUMBER(Responses!Q70),Responses!Q70=1),1,0) -> 0 | I8: =IF(AND(ISNUMBER(Responses!Q64),Responses!Q64=0.5),1,0)+IF(AND(ISNUMBER(Responses!Q70),Responses!Q70=0.5),1,0) -> 0 | J8: =IF(AND(ISNUMBER(Responses!Q64),Responses!Q64=0),1,0)+IF(AND(ISNUMBER(Responses!Q70),Responses!Q70=0),1,0) -> 2 | K8: =F8-G8 -> 0 | L8: =IF(G8=0,"",(H8+I8*0.5)/G8) -> 0
A9: Promise city | B9: Gemini 3.7 Flash | C9: GPT-5.6 Sol | D9: Character-world fit | E9: 2 | F9: =IF(Responses!I64="Include",1,0)+IF(Responses!I70="Include",1,0) -> 2 | G9: =IF(ISNUMBER(Responses!R64),1,0)+IF(ISNUMBER(Responses!R70),1,0) -> 2 | H9: =IF(AND(ISNUMBER(Responses!R64),Responses!R64=1),1,0)+IF(AND(ISNUMBER(Responses!R70),Responses!R70=1),1,0) -> 2 | I9: =IF(AND(ISNUMBER(Responses!R64),Responses!R64=0.5),1,0)+IF(AND(ISNUMBER(Responses!R70),Responses!R70=0.5),1,0) -> 0 | J9: =IF(AND(ISNUMBER(Responses!R64),Responses!R64=0),1,0)+IF(AND(ISNUMBER(Responses!R70),Responses!R70=0),1,0) -> 0 | K9: =F9-G9 -> 0 | L9: =IF(G9=0,"",(H9+I9*0.5)/G9) -> 1
A10: Promise city | B10: Gemini 3.1 Pro Preview | C10: Gemini 3.7 Flash | D10: Explore preference | E10: 2 | F10: =IF(Responses!I46="Include",1,0)+IF(Responses!I52="Include",1,0) -> 2 | G10: =IF(ISNUMBER(Responses!P46),1,0)+IF(ISNUMBER(Responses!P52),1,0) -> 2 | H10: =IF(AND(ISNUMBER(Responses!P46),Responses!P46=1),1,0)+IF(AND(ISNUMBER(Responses!P52),Responses!P52=1),1,0) -> 0 | I10: =IF(AND(ISNUMBER(Responses!P46),Responses!P46=0.5),1,0)+IF(AND(ISNUMBER(Responses!P52),Responses!P52=0.5),1,0) -> 0 | J10: =IF(AND(ISNUMBER(Responses!P46),Responses!P46=0),1,0)+IF(AND(ISNUMBER(Responses!P52),Responses!P52=0),1,0) -> 2 | K10: =F10-G10 -> 0 | L10: =IF(G10=0,"",(H10+I10*0.5)/G10) -> 0
A11: Promise city | B11: Gemini 3.1 Pro Preview | C11: Gemini 3.7 Flash | D11: Map readability | E11: 2 | F11: =IF(Responses!I46="Include",1,0)+IF(Responses!I52="Include",1,0) -> 2 | G11: =IF(ISNUMBER(Responses!Q46),1,0)+IF(ISNUMBER(Responses!Q52),1,0) -> 2 | H11: =IF(AND(ISNUMBER(Responses!Q46),Responses!Q46=1),1,0)+IF(AND(ISNUMBER(Responses!Q52),Responses!Q52=1),1,0) -> 0 | I11: =IF(AND(ISNUMBER(Responses!Q46),Responses!Q46=0.5),1,0)+IF(AND(ISNUMBER(Responses!Q52),Responses!Q52=0.5),1,0) -> 0 | J11: =IF(AND(ISNUMBER(Responses!Q46),Responses!Q46=0),1,0)+IF(AND(ISNUMBER(Responses!Q52),Responses!Q52=0),1,0) -> 2 | K11: =F11-G11 -> 0 | L11: =IF(G11=0,"",(H11+I11*0.5)/G11) -> 0
A12: Promise city | B12: Gemini 3.1 Pro Preview | C12: Gemini 3.7 Flash | D12: Character-world fit | E12: 2 | F12: =IF(Responses!I46="Include",1,0)+IF(Responses!I52="Include",1,0) -> 2 | G12: =IF(ISNUMBER(Responses!R46),1,0)+IF(ISNUMBER(Responses!R52),1,0) -> 2 | H12: =IF(AND(ISNUMBER(Responses!R46),Responses!R46=1),1,0)+IF(AND(ISNUMBER(Responses!R52),Responses!R52=1),1,0) -> 1 | I12: =IF(AND(ISNUMBER(Responses!R46),Responses!R46=0.5),1,0)+IF(AND(ISNUMBER(Responses!R52),Responses!R52=0.5),1,0) -> 0 | J12: =IF(AND(ISNUMBER(Responses!R46),Responses!R46=0),1,0)+IF(AND(ISNUMBER(Responses!R52),Responses!R52=0),1,0) -> 1 | K12: =F12-G12 -> 0 | L12: =IF(G12=0,"",(H12+I12*0.5)/G12) -> 0.5
A13: Promise city | B13: Gemini 3.7 Flash | C13: GPT-5.6 Terra | D13: Explore preference | E13: 2 | F13: =IF(Responses!I57="Include",1,0)+IF(Responses!I65="Include",1,0) -> 2 | G13: =IF(ISNUMBER(Responses!P57),1,0)+IF(ISNUMBER(Responses!P65),1,0) -> 2 | H13: =IF(AND(ISNUMBER(Responses!P57),Responses!P57=1),1,0)+IF(AND(ISNUMBER(Responses!P65),Responses!P65=1),1,0) -> 0 | I13: =IF(AND(ISNUMBER(Responses!P57),Responses!P57=0.5),1,0)+IF(AND(ISNUMBER(Responses!P65),Responses!P65=0.5),1,0) -> 0 | J13: =IF(AND(ISNUMBER(Responses!P57),Responses!P57=0),1,0)+IF(AND(ISNUMBER(Responses!P65),Responses!P65=0),1,0) -> 2 | K13: =F13-G13 -> 0 | L13: =IF(G13=0,"",(H13+I13*0.5)/G13) -> 0
A14: Promise city | B14: Gemini 3.7 Flash | C14: GPT-5.6 Terra | D14: Map readability | E14: 2 | F14: =IF(Responses!I57="Include",1,0)+IF(Responses!I65="Include",1,0) -> 2 | G14: =IF(ISNUMBER(Responses!Q57),1,0)+IF(ISNUMBER(Responses!Q65),1,0) -> 2 | H14: =IF(AND(ISNUMBER(Responses!Q57),Responses!Q57=1),1,0)+IF(AND(ISNUMBER(Responses!Q65),Responses!Q65=1),1,0) -> 0 | I14: =IF(AND(ISNUMBER(Responses!Q57),Responses!Q57=0.5),1,0)+IF(AND(ISNUMBER(Responses!Q65),Responses!Q65=0.5),1,0) -> 0 | J14: =IF(AND(ISNUMBER(Responses!Q57),Responses!Q57=0),1,0)+IF(AND(ISNUMBER(Responses!Q65),Responses!Q65=0),1,0) -> 2 | K14: =F14-G14 -> 0 | L14: =IF(G14=0,"",(H14+I14*0.5)/G14) -> 0
A15: Promise city | B15: Gemini 3.7 Flash | C15: GPT-5.6 Terra | D15: Character-world fit | E15: 2 | F15: =IF(Responses!I57="Include",1,0)+IF(Responses!I65="Include",1,0) -> 2 | G15: =IF(ISNUMBER(Responses!R57),1,0)+IF(ISNUMBER(Responses!R65),1,0) -> 2 | H15: =IF(AND(ISNUMBER(Responses!R57),Responses!R57=1),1,0)+IF(AND(ISNUMBER(Responses!R65),Responses!R65=1),1,0) -> 0 | I15: =IF(AND(ISNUMBER(Responses!R57),Responses!R57=0.5),1,0)+IF(AND(ISNUMBER(Responses!R65),Responses!R65=0.5),1,0) -> 0 | J15: =IF(AND(ISNUMBER(Responses!R57),Responses!R57=0),1,0)+IF(AND(ISNUMBER(Responses!R65),Responses!R65=0),1,0) -> 2 | K15: =F15-G15 -> 0 | L15: =IF(G15=0,"",(H15+I15*0.5)/G15) -> 0
A16: Promise city | B16: Gemini 2.5 Flash | C16: Gemini 3.1 Pro Preview | D16: Explore preference | E16: 2 | F16: =IF(Responses!I21="Include",1,0)+IF(Responses!I28="Include",1,0) -> 1 | G16: =IF(ISNUMBER(Responses!P21),1,0)+IF(ISNUMBER(Responses!P28),1,0) -> 1 | H16: =IF(AND(ISNUMBER(Responses!P21),Responses!P21=1),1,0)+IF(AND(ISNUMBER(Responses!P28),Responses!P28=1),1,0) -> 1 | I16: =IF(AND(ISNUMBER(Responses!P21),Responses!P21=0.5),1,0)+IF(AND(ISNUMBER(Responses!P28),Responses!P28=0.5),1,0) -> 0 | J16: =IF(AND(ISNUMBER(Responses!P21),Responses!P21=0),1,0)+IF(AND(ISNUMBER(Responses!P28),Responses!P28=0),1,0) -> 0 | K16: =F16-G16 -> 0 | L16: =IF(G16=0,"",(H16+I16*0.5)/G16) -> 1
A17: Promise city | B17: Gemini 2.5 Flash | C17: Gemini 3.1 Pro Preview | D17: Map readability | E17: 2 | F17: =IF(Responses!I21="Include",1,0)+IF(Responses!I28="Include",1,0) -> 1 | G17: =IF(ISNUMBER(Responses!Q21),1,0)+IF(ISNUMBER(Responses!Q28),1,0) -> 1 | H17: =IF(AND(ISNUMBER(Responses!Q21),Responses!Q21=1),1,0)+IF(AND(ISNUMBER(Responses!Q28),Responses!Q28=1),1,0) -> 0 | I17: =IF(AND(ISNUMBER(Responses!Q21),Responses!Q21=0.5),1,0)+IF(AND(ISNUMBER(Responses!Q28),Responses!Q28=0.5),1,0) -> 0 | J17: =IF(AND(ISNUMBER(Responses!Q21),Responses!Q21=0),1,0)+IF(AND(ISNUMBER(Responses!Q28),Responses!Q28=0),1,0) -> 1 | K17: =F17-G17 -> 0 | L17: =IF(G17=0,"",(H17+I17*0.5)/G17) -> 0
A18: Promise city | B18: Gemini 2.5 Flash | C18: Gemini 3.1 Pro Preview | D18: Character-world fit | E18: 2 | F18: =IF(Responses!I21="Include",1,0)+IF(Responses!I28="Include",1,0) -> 1 | G18: =IF(ISNUMBER(Responses!R21),1,0)+IF(ISNUMBER(Responses!R28),1,0) -> 1 | H18: =IF(AND(ISNUMBER(Responses!R21),Responses!R21=1),1,0)+IF(AND(ISNUMBER(Responses!R28),Responses!R28=1),1,0) -> 1 | I18: =IF(AND(ISNUMBER(Responses!R21),Responses!R21=0.5),1,0)+IF(AND(ISNUMBER(Responses!R28),Responses!R28=0.5),1,0) -> 0 | J18: =IF(AND(ISNUMBER(Responses!R21),Responses!R21=0),1,0)+IF(AND(ISNUMBER(Responses!R28),Responses!R28=0),1,0) -> 0 | K18: =F18-G18 -> 0 | L18: =IF(G18=0,"",(H18+I18*0.5)/G18) -> 1
A19: Promise city | B19: Gemini 3.5 Flash Lite | C19: GPT-5.6 Sol | D19: Explore preference | E19: 2 | F19: =IF(Responses!I13="Include",1,0)+IF(Responses!I20="Include",1,0) -> 2 | G19: =IF(ISNUMBER(Responses!P13),1,0)+IF(ISNUMBER(Responses!P20),1,0) -> 2 | H19: =IF(AND(ISNUMBER(Responses!P13),Responses!P13=1),1,0)+IF(AND(ISNUMBER(Responses!P20),Responses!P20=1),1,0) -> 2 | I19: =IF(AND(ISNUMBER(Responses!P13),Responses!P13=0.5),1,0)+IF(AND(ISNUMBER(Responses!P20),Responses!P20=0.5),1,0) -> 0 | J19: =IF(AND(ISNUMBER(Responses!P13),Responses!P13=0),1,0)+IF(AND(ISNUMBER(Responses!P20),Responses!P20=0),1,0) -> 0 | K19: =F19-G19 -> 0 | L19: =IF(G19=0,"",(H19+I19*0.5)/G19) -> 1
A20: Promise city | B20: Gemini 3.5 Flash Lite | C20: GPT-5.6 Sol | D20: Map readability | E20: 2 | F20: =IF(Responses!I13="Include",1,0)+IF(Responses!I20="Include",1,0) -> 2 | G20: =IF(ISNUMBER(Responses!Q13),1,0)+IF(ISNUMBER(Responses!Q20),1,0) -> 2 | H20: =IF(AND(ISNUMBER(Responses!Q13),Responses!Q13=1),1,0)+IF(AND(ISNUMBER(Responses!Q20),Responses!Q20=1),1,0) -> 0 | I20: =IF(AND(ISNUMBER(Responses!Q13),Responses!Q13=0.5),1,0)+IF(AND(ISNUMBER(Responses!Q20),Responses!Q20=0.5),1,0) -> 0 | J20: =IF(AND(ISNUMBER(Responses!Q13),Responses!Q13=0),1,0)+IF(AND(ISNUMBER(Responses!Q20),Responses!Q20=0),1,0) -> 2 | K20: =F20-G20 -> 0 | L20: =IF(G20=0,"",(H20+I20*0.5)/G20) -> 0
A21: Promise city | B21: Gemini 3.5 Flash Lite | C21: GPT-5.6 Sol | D21: Character-world fit | E21: 2 | F21: =IF(Responses!I13="Include",1,0)+IF(Responses!I20="Include",1,0) -> 2 | G21: =IF(ISNUMBER(Responses!R13),1,0)+IF(ISNUMBER(Responses!R20),1,0) -> 2 | H21: =IF(AND(ISNUMBER(Responses!R13),Responses!R13=1),1,0)+IF(AND(ISNUMBER(Responses!R20),Responses!R20=1),1,0) -> 2 | I21: =IF(AND(ISNUMBER(Responses!R13),Responses!R13=0.5),1,0)+IF(AND(ISNUMBER(Responses!R20),Responses!R20=0.5),1,0) -> 0 | J21: =IF(AND(ISNUMBER(Responses!R13),Responses!R13=0),1,0)+IF(AND(ISNUMBER(Responses!R20),Responses!R20=0),1,0) -> 0 | K21: =F21-G21 -> 0 | L21: =IF(G21=0,"",(H21+I21*0.5)/G21) -> 1
A22: Promise city | B22: Gemini 3.5 Flash Lite | C22: Gemini 3.7 Flash | D22: Explore preference | E22: 2 | F22: =IF(Responses!I18="Include",1,0)+IF(Responses!I24="Include",1,0) -> 2 | G22: =IF(ISNUMBER(Responses!P18),1,0)+IF(ISNUMBER(Responses!P24),1,0) -> 2 | H22: =IF(AND(ISNUMBER(Responses!P18),Responses!P18=1),1,0)+IF(AND(ISNUMBER(Responses!P24),Responses!P24=1),1,0) -> 1 | I22: =IF(AND(ISNUMBER(Responses!P18),Responses!P18=0.5),1,0)+IF(AND(ISNUMBER(Responses!P24),Responses!P24=0.5),1,0) -> 0 | J22: =IF(AND(ISNUMBER(Responses!P18),Responses!P18=0),1,0)+IF(AND(ISNUMBER(Responses!P24),Responses!P24=0),1,0) -> 1 | K22: =F22-G22 -> 0 | L22: =IF(G22=0,"",(H22+I22*0.5)/G22) -> 0.5
A23: Promise city | B23: Gemini 3.5 Flash Lite | C23: Gemini 3.7 Flash | D23: Map readability | E23: 2 | F23: =IF(Responses!I18="Include",1,0)+IF(Responses!I24="Include",1,0) -> 2 | G23: =IF(ISNUMBER(Responses!Q18),1,0)+IF(ISNUMBER(Responses!Q24),1,0) -> 2 | H23: =IF(AND(ISNUMBER(Responses!Q18),Responses!Q18=1),1,0)+IF(AND(ISNUMBER(Responses!Q24),Responses!Q24=1),1,0) -> 0 | I23: =IF(AND(ISNUMBER(Responses!Q18),Responses!Q18=0.5),1,0)+IF(AND(ISNUMBER(Responses!Q24),Responses!Q24=0.5),1,0) -> 0 | J23: =IF(AND(ISNUMBER(Responses!Q18),Responses!Q18=0),1,0)+IF(AND(ISNUMBER(Responses!Q24),Responses!Q24=0),1,0) -> 2 | K23: =F23-G23 -> 0 | L23: =IF(G23=0,"",(H23+I23*0.5)/G23) -> 0
A24: Promise city | B24: Gemini 3.5 Flash Lite | C24: Gemini 3.7 Flash | D24: Character-world fit | E24: 2 | F24: =IF(Responses!I18="Include",1,0)+IF(Responses!I24="Include",1,0) -> 2 | G24: =IF(ISNUMBER(Responses!R18),1,0)+IF(ISNUMBER(Responses!R24),1,0) -> 2 | H24: =IF(AND(ISNUMBER(Responses!R18),Responses!R18=1),1,0)+IF(AND(ISNUMBER(Responses!R24),Responses!R24=1),1,0) -> 1 | I24: =IF(AND(ISNUMBER(Responses!R18),Responses!R18=0.5),1,0)+IF(AND(ISNUMBER(Responses!R24),Responses!R24=0.5),1,0) -> 0 | J24: =IF(AND(ISNUMBER(Responses!R18),Responses!R18=0),1,0)+IF(AND(ISNUMBER(Responses!R24),Responses!R24=0),1,0) -> 1 | K24: =F24-G24 -> 0 | L24: =IF(G24=0,"",(H24+I24*0.5)/G24) -> 0.5
A25: Promise city | B25: Gemini 2.5 Flash | C25: Gemini 3.7 Flash | D25: Explore preference | E25: 2 | F25: =IF(Responses!I29="Include",1,0)+IF(Responses!I34="Include",1,0) -> 1 | G25: =IF(ISNUMBER(Responses!P29),1,0)+IF(ISNUMBER(Responses!P34),1,0) -> 1 | H25: =IF(AND(ISNUMBER(Responses!P29),Responses!P29=1),1,0)+IF(AND(ISNUMBER(Responses!P34),Responses!P34=1),1,0) -> 1 | I25: =IF(AND(ISNUMBER(Responses!P29),Responses!P29=0.5),1,0)+IF(AND(ISNUMBER(Responses!P34),Responses!P34=0.5),1,0) -> 0 | J25: =IF(AND(ISNUMBER(Responses!P29),Responses!P29=0),1,0)+IF(AND(ISNUMBER(Responses!P34),Responses!P34=0),1,0) -> 0 | K25: =F25-G25 -> 0 | L25: =IF(G25=0,"",(H25+I25*0.5)/G25) -> 1
A26: Promise city | B26: Gemini 2.5 Flash | C26: Gemini 3.7 Flash | D26: Map readability | E26: 2 | F26: =IF(Responses!I29="Include",1,0)+IF(Responses!I34="Include",1,0) -> 1 | G26: =IF(ISNUMBER(Responses!Q29),1,0)+IF(ISNUMBER(Responses!Q34),1,0) -> 1 | H26: =IF(AND(ISNUMBER(Responses!Q29),Responses!Q29=1),1,0)+IF(AND(ISNUMBER(Responses!Q34),Responses!Q34=1),1,0) -> 1 | I26: =IF(AND(ISNUMBER(Responses!Q29),Responses!Q29=0.5),1,0)+IF(AND(ISNUMBER(Responses!Q34),Responses!Q34=0.5),1,0) -> 0 | J26: =IF(AND(ISNUMBER(Responses!Q29),Responses!Q29=0),1,0)+IF(AND(ISNUMBER(Responses!Q34),Responses!Q34=0),1,0) -> 0 | K26: =F26-G26 -> 0 | L26: =IF(G26=0,"",(H26+I26*0.5)/G26) -> 1
A27: Promise city | B27: Gemini 2.5 Flash | C27: Gemini 3.7 Flash | D27: Character-world fit | E27: 2 | F27: =IF(Responses!I29="Include",1,0)+IF(Responses!I34="Include",1,0) -> 1 | G27: =IF(ISNUMBER(Responses!R29),1,0)+IF(ISNUMBER(Responses!R34),1,0) -> 1 | H27: =IF(AND(ISNUMBER(Responses!R29),Responses!R29=1),1,0)+IF(AND(ISNUMBER(Responses!R34),Responses!R34=1),1,0) -> 1 | I27: =IF(AND(ISNUMBER(Responses!R29),Responses!R29=0.5),1,0)+IF(AND(ISNUMBER(Responses!R34),Responses!R34=0.5),1,0) -> 0 | J27: =IF(AND(ISNUMBER(Responses!R29),Responses!R29=0),1,0)+IF(AND(ISNUMBER(Responses!R34),Responses!R34=0),1,0) -> 0 | K27: =F27-G27 -> 0 | L27: =IF(G27=0,"",(H27+I27*0.5)/G27) -> 1
A28: Promise city | B28: Gemini 3.1 Pro Preview | C28: Gemini 3.5 Flash Lite | D28: Explore preference | E28: 2 | F28: =IF(Responses!I36="Include",1,0)+IF(Responses!I38="Include",1,0) -> 2 | G28: =IF(ISNUMBER(Responses!P36),1,0)+IF(ISNUMBER(Responses!P38),1,0) -> 2 | H28: =IF(AND(ISNUMBER(Responses!P36),Responses!P36=1),1,0)+IF(AND(ISNUMBER(Responses!P38),Responses!P38=1),1,0) -> 1 | I28: =IF(AND(ISNUMBER(Responses!P36),Responses!P36=0.5),1,0)+IF(AND(ISNUMBER(Responses!P38),Responses!P38=0.5),1,0) -> 0 | J28: =IF(AND(ISNUMBER(Responses!P36),Responses!P36=0),1,0)+IF(AND(ISNUMBER(Responses!P38),Responses!P38=0),1,0) -> 1 | K28: =F28-G28 -> 0 | L28: =IF(G28=0,"",(H28+I28*0.5)/G28) -> 0.5
A29: Promise city | B29: Gemini 3.1 Pro Preview | C29: Gemini 3.5 Flash Lite | D29: Map readability | E29: 2 | F29: =IF(Responses!I36="Include",1,0)+IF(Responses!I38="Include",1,0) -> 2 | G29: =IF(ISNUMBER(Responses!Q36),1,0)+IF(ISNUMBER(Responses!Q38),1,0) -> 2 | H29: =IF(AND(ISNUMBER(Responses!Q36),Responses!Q36=1),1,0)+IF(AND(ISNUMBER(Responses!Q38),Responses!Q38=1),1,0) -> 2 | I29: =IF(AND(ISNUMBER(Responses!Q36),Responses!Q36=0.5),1,0)+IF(AND(ISNUMBER(Responses!Q38),Responses!Q38=0.5),1,0) -> 0 | J29: =IF(AND(ISNUMBER(Responses!Q36),Responses!Q36=0),1,0)+IF(AND(ISNUMBER(Responses!Q38),Responses!Q38=0),1,0) -> 0 | K29: =F29-G29 -> 0 | L29: =IF(G29=0,"",(H29+I29*0.5)/G29) -> 1
A30: Promise city | B30: Gemini 3.1 Pro Preview | C30: Gemini 3.5 Flash Lite | D30: Character-world fit | E30: 2 | F30: =IF(Responses!I36="Include",1,0)+IF(Responses!I38="Include",1,0) -> 2 | G30: =IF(ISNUMBER(Responses!R36),1,0)+IF(ISNUMBER(Responses!R38),1,0) -> 2 | H30: =IF(AND(ISNUMBER(Responses!R36),Responses!R36=1),1,0)+IF(AND(ISNUMBER(Responses!R38),Responses!R38=1),1,0) -> 1 | I30: =IF(AND(ISNUMBER(Responses!R36),Responses!R36=0.5),1,0)+IF(AND(ISNUMBER(Responses!R38),Responses!R38=0.5),1,0) -> 1 | J30: =IF(AND(ISNUMBER(Responses!R36),Responses!R36=0),1,0)+IF(AND(ISNUMBER(Responses!R38),Responses!R38=0),1,0) -> 0 | K30: =F30-G30 -> 0 | L30: =IF(G30=0,"",(H30+I30*0.5)/G30) -> 0.75
A31: Promise city | B31: Gemini 2.5 Flash | C31: GPT-5.6 Sol | D31: Explore preference | E31: 2 | F31: =IF(Responses!I10="Include",1,0)+IF(Responses!I15="Include",1,0) -> 2 | G31: =IF(ISNUMBER(Responses!P10),1,0)+IF(ISNUMBER(Responses!P15),1,0) -> 2 | H31: =IF(AND(ISNUMBER(Responses!P10),Responses!P10=1),1,0)+IF(AND(ISNUMBER(Responses!P15),Responses!P15=1),1,0) -> 1 | I31: =IF(AND(ISNUMBER(Responses!P10),Responses!P10=0.5),1,0)+IF(AND(ISNUMBER(Responses!P15),Responses!P15=0.5),1,0) -> 0 | J31: =IF(AND(ISNUMBER(Responses!P10),Responses!P10=0),1,0)+IF(AND(ISNUMBER(Responses!P15),Responses!P15=0),1,0) -> 1 | K31: =F31-G31 -> 0 | L31: =IF(G31=0,"",(H31+I31*0.5)/G31) -> 0.5
A32: Promise city | B32: Gemini 2.5 Flash | C32: GPT-5.6 Sol | D32: Map readability | E32: 2 | F32: =IF(Responses!I10="Include",1,0)+IF(Responses!I15="Include",1,0) -> 2 | G32: =IF(ISNUMBER(Responses!Q10),1,0)+IF(ISNUMBER(Responses!Q15),1,0) -> 2 | H32: =IF(AND(ISNUMBER(Responses!Q10),Responses!Q10=1),1,0)+IF(AND(ISNUMBER(Responses!Q15),Responses!Q15=1),1,0) -> 1 | I32: =IF(AND(ISNUMBER(Responses!Q10),Responses!Q10=0.5),1,0)+IF(AND(ISNUMBER(Responses!Q15),Responses!Q15=0.5),1,0) -> 0 | J32: =IF(AND(ISNUMBER(Responses!Q10),Responses!Q10=0),1,0)+IF(AND(ISNUMBER(Responses!Q15),Responses!Q15=0),1,0) -> 1 | K32: =F32-G32 -> 0 | L32: =IF(G32=0,"",(H32+I32*0.5)/G32) -> 0.5
A33: Promise city | B33: Gemini 2.5 Flash | C33: GPT-5.6 Sol | D33: Character-world fit | E33: 2 | F33: =IF(Responses!I10="Include",1,0)+IF(Responses!I15="Include",1,0) -> 2 | G33: =IF(ISNUMBER(Responses!R10),1,0)+IF(ISNUMBER(Responses!R15),1,0) -> 2 | H33: =IF(AND(ISNUMBER(Responses!R10),Responses!R10=1),1,0)+IF(AND(ISNUMBER(Responses!R15),Responses!R15=1),1,0) -> 1 | I33: =IF(AND(ISNUMBER(Responses!R10),Responses!R10=0.5),1,0)+IF(AND(ISNUMBER(Responses!R15),Responses!R15=0.5),1,0) -> 0 | J33: =IF(AND(ISNUMBER(Responses!R10),Responses!R10=0),1,0)+IF(AND(ISNUMBER(Responses!R15),Responses!R15=0),1,0) -> 1 | K33: =F33-G33 -> 0 | L33: =IF(G33=0,"",(H33+I33*0.5)/G33) -> 0.5
A34: Promise city | B34: Gemini 3.1 Flash Lite | C34: Gemini 3.1 Pro Preview | D34: Explore preference | E34: 2 | F34: =IF(Responses!I31="Include",1,0)+IF(Responses!I41="Include",1,0) -> 2 | G34: =IF(ISNUMBER(Responses!P31),1,0)+IF(ISNUMBER(Responses!P41),1,0) -> 2 | H34: =IF(AND(ISNUMBER(Responses!P31),Responses!P31=1),1,0)+IF(AND(ISNUMBER(Responses!P41),Responses!P41=1),1,0) -> 1 | I34: =IF(AND(ISNUMBER(Responses!P31),Responses!P31=0.5),1,0)+IF(AND(ISNUMBER(Responses!P41),Responses!P41=0.5),1,0) -> 0 | J34: =IF(AND(ISNUMBER(Responses!P31),Responses!P31=0),1,0)+IF(AND(ISNUMBER(Responses!P41),Responses!P41=0),1,0) -> 1 | K34: =F34-G34 -> 0 | L34: =IF(G34=0,"",(H34+I34*0.5)/G34) -> 0.5
A35: Promise city | B35: Gemini 3.1 Flash Lite | C35: Gemini 3.1 Pro Preview | D35: Map readability | E35: 2 | F35: =IF(Responses!I31="Include",1,0)+IF(Responses!I41="Include",1,0) -> 2 | G35: =IF(ISNUMBER(Responses!Q31),1,0)+IF(ISNUMBER(Responses!Q41),1,0) -> 2 | H35: =IF(AND(ISNUMBER(Responses!Q31),Responses!Q31=1),1,0)+IF(AND(ISNUMBER(Responses!Q41),Responses!Q41=1),1,0) -> 0 | I35: =IF(AND(ISNUMBER(Responses!Q31),Responses!Q31=0.5),1,0)+IF(AND(ISNUMBER(Responses!Q41),Responses!Q41=0.5),1,0) -> 1 | J35: =IF(AND(ISNUMBER(Responses!Q31),Responses!Q31=0),1,0)+IF(AND(ISNUMBER(Responses!Q41),Responses!Q41=0),1,0) -> 1 | K35: =F35-G35 -> 0 | L35: =IF(G35=0,"",(H35+I35*0.5)/G35) -> 0.25
A36: Promise city | B36: Gemini 3.1 Flash Lite | C36: Gemini 3.1 Pro Preview | D36: Character-world fit | E36: 2 | F36: =IF(Responses!I31="Include",1,0)+IF(Responses!I41="Include",1,0) -> 2 | G36: =IF(ISNUMBER(Responses!R31),1,0)+IF(ISNUMBER(Responses!R41),1,0) -> 2 | H36: =IF(AND(ISNUMBER(Responses!R31),Responses!R31=1),1,0)+IF(AND(ISNUMBER(Responses!R41),Responses!R41=1),1,0) -> 1 | I36: =IF(AND(ISNUMBER(Responses!R31),Responses!R31=0.5),1,0)+IF(AND(ISNUMBER(Responses!R41),Responses!R41=0.5),1,0) -> 0 | J36: =IF(AND(ISNUMBER(Responses!R31),Responses!R31=0),1,0)+IF(AND(ISNUMBER(Responses!R41),Responses!R41=0),1,0) -> 1 | K36: =F36-G36 -> 0 | L36: =IF(G36=0,"",(H36+I36*0.5)/G36) -> 0.5
A37: Promise city | B37: Gemini 3.1 Flash Lite | C37: Gemini 3.7 Flash | D37: Explore preference | E37: 2 | F37: =IF(Responses!I39="Include",1,0)+IF(Responses!I43="Include",1,0) -> 2 | G37: =IF(ISNUMBER(Responses!P39),1,0)+IF(ISNUMBER(Responses!P43),1,0) -> 2 | H37: =IF(AND(ISNUMBER(Responses!P39),Responses!P39=1),1,0)+IF(AND(ISNUMBER(Responses!P43),Responses!P43=1),1,0) -> 2 | I37: =IF(AND(ISNUMBER(Responses!P39),Responses!P39=0.5),1,0)+IF(AND(ISNUMBER(Responses!P43),Responses!P43=0.5),1,0) -> 0 | J37: =IF(AND(ISNUMBER(Responses!P39),Responses!P39=0),1,0)+IF(AND(ISNUMBER(Responses!P43),Responses!P43=0),1,0) -> 0 | K37: =F37-G37 -> 0 | L37: =IF(G37=0,"",(H37+I37*0.5)/G37) -> 1
A38: Promise city | B38: Gemini 3.1 Flash Lite | C38: Gemini 3.7 Flash | D38: Map readability | E38: 2 | F38: =IF(Responses!I39="Include",1,0)+IF(Responses!I43="Include",1,0) -> 2 | G38: =IF(ISNUMBER(Responses!Q39),1,0)+IF(ISNUMBER(Responses!Q43),1,0) -> 2 | H38: =IF(AND(ISNUMBER(Responses!Q39),Responses!Q39=1),1,0)+IF(AND(ISNUMBER(Responses!Q43),Responses!Q43=1),1,0) -> 0 | I38: =IF(AND(ISNUMBER(Responses!Q39),Responses!Q39=0.5),1,0)+IF(AND(ISNUMBER(Responses!Q43),Responses!Q43=0.5),1,0) -> 0 | J38: =IF(AND(ISNUMBER(Responses!Q39),Responses!Q39=0),1,0)+IF(AND(ISNUMBER(Responses!Q43),Responses!Q43=0),1,0) -> 2 | K38: =F38-G38 -> 0 | L38: =IF(G38=0,"",(H38+I38*0.5)/G38) -> 0
A39: Promise city | B39: Gemini 3.1 Flash Lite | C39: Gemini 3.7 Flash | D39: Character-world fit | E39: 2 | F39: =IF(Responses!I39="Include",1,0)+IF(Responses!I43="Include",1,0) -> 2 | G39: =IF(ISNUMBER(Responses!R39),1,0)+IF(ISNUMBER(Responses!R43),1,0) -> 2 | H39: =IF(AND(ISNUMBER(Responses!R39),Responses!R39=1),1,0)+IF(AND(ISNUMBER(Responses!R43),Responses!R43=1),1,0) -> 1 | I39: =IF(AND(ISNUMBER(Responses!R39),Responses!R39=0.5),1,0)+IF(AND(ISNUMBER(Responses!R43),Responses!R43=0.5),1,0) -> 0 | J39: =IF(AND(ISNUMBER(Responses!R39),Responses!R39=0),1,0)+IF(AND(ISNUMBER(Responses!R43),Responses!R43=0),1,0) -> 1 | K39: =F39-G39 -> 0 | L39: =IF(G39=0,"",(H39+I39*0.5)/G39) -> 0.5
A40: Promise city | B40: Gemini 3.5 Flash Lite | C40: GPT-5.6 Terra | D40: Explore preference | E40: 4 | F40: =IF(Responses!I42="Include",1,0)+IF(Responses!I47="Include",1,0)+IF(Responses!I59="Include",1,0)+IF(Responses!I62="Include",1,0) -> 4 | G40: =IF(ISNUMBER(Responses!P42),1,0)+IF(ISNUMBER(Responses!P47),1,0)+IF(ISNUMBER(Responses!P59),1,0)+IF(ISNUMBER(Responses!P62),1,0) -> 4 | H40: =IF(AND(ISNUMBER(Responses!P42),Responses!P42=1),1,0)+IF(AND(ISNUMBER(Responses!P47),Responses!P47=1),1,0)+IF(AND(ISNUMBER(Responses!P59),Responses!P59=1),1,0)+IF(AND(ISNUMBER(Responses!P62),Responses!P62=1),1,0) -> 2 | I40: =IF(AND(ISNUMBER(Responses!P42),Responses!P42=0.5),1,0)+IF(AND(ISNUMBER(Responses!P47),Responses!P47=0.5),1,0)+IF(AND(ISNUMBER(Responses!P59),Responses!P59=0.5),1,0)+IF(AND(ISNUMBER(Responses!P62),Responses!P62=0.5),1,0) -> 0 | J40: =IF(AND(ISNUMBER(Responses!P42),Responses!P42=0),1,0)+IF(AND(ISNUMBER(Responses!P47),Responses!P47=0),1,0)+IF(AND(ISNUMBER(Responses!P59),Responses!P59=0),1,0)+IF(AND(ISNUMBER(Responses!P62),Responses!P62=0),1,0) -> 2 | K40: =F40-G40 -> 0 | L40: =IF(G40=0,"",(H40+I40*0.5)/G40) -> 0.5
A41: Promise city | B41: Gemini 3.5 Flash Lite | C41: GPT-5.6 Terra | D41: Map readability | E41: 4 | F41: =IF(Responses!I42="Include",1,0)+IF(Responses!I47="Include",1,0)+IF(Responses!I59="Include",1,0)+IF(Responses!I62="Include",1,0) -> 4 | G41: =IF(ISNUMBER(Responses!Q42),1,0)+IF(ISNUMBER(Responses!Q47),1,0)+IF(ISNUMBER(Responses!Q59),1,0)+IF(ISNUMBER(Responses!Q62),1,0) -> 4 | H41: =IF(AND(ISNUMBER(Responses!Q42),Responses!Q42=1),1,0)+IF(AND(ISNUMBER(Responses!Q47),Responses!Q47=1),1,0)+IF(AND(ISNUMBER(Responses!Q59),Responses!Q59=1),1,0)+IF(AND(ISNUMBER(Responses!Q62),Responses!Q62=1),1,0) -> 0 | I41: =IF(AND(ISNUMBER(Responses!Q42),Responses!Q42=0.5),1,0)+IF(AND(ISNUMBER(Responses!Q47),Responses!Q47=0.5),1,0)+IF(AND(ISNUMBER(Responses!Q59),Responses!Q59=0.5),1,0)+IF(AND(ISNUMBER(Responses!Q62),Responses!Q62=0.5),1,0) -> 0 | J41: =IF(AND(ISNUMBER(Responses!Q42),Responses!Q42=0),1,0)+IF(AND(ISNUMBER(Responses!Q47),Responses!Q47=0),1,0)+IF(AND(ISNUMBER(Responses!Q59),Responses!Q59=0),1,0)+IF(AND(ISNUMBER(Responses!Q62),Responses!Q62=0),1,0) -> 4 | K41: =F41-G41 -> 0 | L41: =IF(G41=0,"",(H41+I41*0.5)/G41) -> 0
